Workbook

Sheet Resumen-Mensual
B2: RESUMEN DE CURTAILMENTS ACUMULADO DE CENTRALES EÓLICAS Y SOLARES CORRESPONDIENTE AL AÑO 2022 (GWh)
C4: Resumen Anual / Mensual (GWh)
C6: Acumulado 2022
B7: Eólica | C7: =SUM(C12,F12,I12,L12,O12,R12,U12,X12,AA12,AD12,AG12,AJ12) -> 53.154253 | E7: =IF($C$9=0,"-",+C7/$C$9) -> 0.55027115
B8: Solar | C8: =SUM(C13,F13,I13,L13,O13,R13,U13,X13,AA13,AD13,AG13,AJ13) -> 43.442221 | E8: =IF($C$9=0,"-",+C8/$C$9) -> 0.44972885
B9: Total | C9: =SUM(C7:C8) -> 96.596475 | E9: =SUM(E7:E8) -> 1
C11: 44562 | F11: 44593 | I11: 44621 | L11: 44652 | O11: 44682 | R11: 44713 | U11: 44743 | X11: 44774 | AA11: 44805 | AD11: 44835 | AG11: 44866 | AJ11: 44896
B12: Eólica | C12: ='Acumulado-Anual-Eólico'!AJ10/1000 -> 53.154253 | E12: =IF($C$14=0,"-",+C12/$C$14) -> 0.55027115 | F12: =SUM(F133:U133)/1000 -> 0 | H12: =IF($C$14=0,"-",+F12/$C$14) -> 0 | I12: =SUM(I133:X133)/1000 -> 0 | K12: =IF($C$14=0,"-",+I12/$C$14) -> 0 | L12: =SUM(L133:AA133)/1000 -> 0 | N12: =IF($C$14=0,"-",+L12/$C$14) -> 0 | O12: =SUM(O133:AD133)/1000 -> 0 | Q12: =IF($C$14=0,"-",+O12/$C$14) -> 0 | R12: =SUM(R133:AG133)/1000 -> 0 | T12: =IF($C$14=0,"-",+R12/$C$14) -> 0 | U12: =SUM(U133:AJ133)/1000 -> 0 | W12: =IF($C$14=0,"-",+U12/$C$14) -> 0 | X12: =SUM(X133:AM133)/1000 -> 0 | Z12: =IF($C$14=0,"-",+X12/$C$14) -> 0 | AA12: =SUM(AA133:AP133)/1000 -> 0 | AC12: =IF($C$14=0,"-",+AA12/$C$14) -> 0 | AD12: =SUM(AD133:AS133)/1000 -> 0 | AF12: =IF($C$14=0,"-",+AD12/$C$14) -> 0 | AG12: =SUM(AG133:AV133)/1000 -> 0 | AI12: =IF($C$14=0,"-",+AG12/$C$14) -> 0 | AJ12: =SUM(AJ133:AY133)/1000 -> 0 | AL12: =IF($C$14=0,"-",+AJ12/$C$14) -> 0
B13: Solar | C13: ='Acumulado-Anual-Solar'!AJ10/1000 -> 43.442221 | E13: =IF($C$14=0,"-",+C13/$C$14) -> 0.44972885 | F13: =SUM(W133:AU133)/1000 -> 0 | H13: =IF($C$14=0,"-",+F13/$C$14) -> 0 | I13: =SUM(Z133:AX133)/1000 -> 0 | K13: =IF($C$14=0,"-",+I13/$C$14) -> 0 | L13: =SUM(AC133:BA133)/1000 -> 0 | N13: =IF($C$14=0,"-",+L13/$C$14) -> 0 | O13: =SUM(AF133:BD133)/1000 -> 0 | Q13: =IF($C$14=0,"-",+O13/$C$14) -> 0 | R13: =SUM(AI133:BG133)/1000 -> 0 | T13: =IF($C$14=0,"-",+R13/$C$14) -> 0 | U13: =SUM(AL133:BJ133)/1000 -> 0 | W13: =IF($C$14=0,"-",+U13/$C$14) -> 0 | X13: =SUM(AO133:BM133)/1000 -> 0 | Z13: =IF($C$14=0,"-",+X13/$C$14) -> 0 | AA13: =SUM(AR133:BP133)/1000 -> 0 | AC13: =IF($C$14=0,"-",+AA13/$C$14) -> 0 | AD13: =SUM(AU133:BS133)/1000 -> 0 | AF13: =IF($C$14=0,"-",+AD13/$C$14) -> 0 | AG13: =SUM(AX133:BV133)/1000 -> 0 | AI13: =IF($C$14=0,"-",+AG13/$C$14) -> 0 | AJ13: =SUM(BA133:BY133)/1000 -> 0 | AL13: =IF($C$14=0,"-",+AJ13/$C$14) -> 0
B14: Total | C14: =SUM(C12:C13) -> 96.596475 | E14: =SUM(E12:E13) -> 1 | F14: =SUM(F12:F13) -> 0 | H14: =SUM(H12:H13) -> 0 | I14: =SUM(I12:I13) -> 0 | K14: =SUM(K12:K13) -> 0 | L14: =SUM(L12:L13) -> 0 | N14: =SUM(N12:N13) -> 0 | O14: =SUM(O12:O13) -> 0 | Q14: =SUM(Q12:Q13) -> 0 | R14: =SUM(R12:R13) -> 0 | T14: =SUM(T12:T13) -> 0 | U14: =SUM(U12:U13) -> 0 | W14: =SUM(W12:W13) -> 0 | X14: =SUM(X12:X13) -> 0 | Z14: =SUM(Z12:Z13) -> 0 | AA14: =SUM(AA12:AA13) -> 0 | AC14: =SUM(AC12:AC13) -> 0 | AD14: =SUM(AD12:AD13) -> 0 | AF14: =SUM(AF12:AF13) -> 0 | AG14: =SUM(AG12:AG13) -> 0 | AI14: =SUM(AI12:AI13) -> 0 | AJ14: =SUM(AJ12:AJ13) -> 0 | AL14: =SUM(AL12:AL13) -> 0
B17: RESUMEN DE CURTAILMENTS CENTRALES EÓLICAS Y SOLARES CORRESPONDIENTE A ENERO 2022 (MWh)
B20: DESGLOSE DIARIO DE CURTAILMENTS DE ENERGÍA EÓLICA
B22: Central / Día | E22: 44562 | F22: =E22+1 -> 44563 | G22: =F22+1 -> 44564 | H22: =G22+1 -> 44565 | I22: =H22+1 -> 44566 | J22: =I22+1 -> 44567 | K22: =J22+1 -> 44568 | L22: =K22+1 -> 44569 | M22: =L22+1 -> 44570 | ... AI22: =AH22+1 -> 44592 | AJ22: Total
B23: Total | E23: =SUM(E24:E60) -> 5534.6365 | F23: =SUM(F24:F60) -> 5449.3832 | G23: =SUM(G24:G60) -> 582.06317 | H23: =SUM(H24:H60) -> 2478.4272 | I23: =SUM(I24:I60) -> 2233.1848 | J23: =SUM(J24:J60) -> 2271.0747 | K23: =SUM(K24:K60) -> 457.4755 | L23: =SUM(L24:L60) -> 99.093667 | ... AI23: =SUM(AI24:AI60) -> 72.604667 | AJ23: =SUM(AJ24:AK60) -> 53154.253
B24: PE-TCHAMMA | E24: ='Resumen-DiarioHorario-Eólico'!AC8 -> 40.035667 | F24: ='Resumen-DiarioHorario-Eólico'!AC51 -> 238.97183 | G24: ='Resumen-DiarioHorario-Eólico'!AC94 -> 44.0795 | H24: ='Resumen-DiarioHorario-Eólico'!AC137 -> 18.868333 | I24: ='Resumen-DiarioHorario-Eólico'!AC180 -> 92.931333 | J24: ='Resumen-DiarioHorario-Eólico'!AC223 -> 56.291833 | K24: ='Resumen-DiarioHorario-Eólico'!AC266 -> 1.7065 | L24: ='Resumen-DiarioHorario-Eólico'!AC309 -> 0 | M24: ='Resumen-DiarioHorario-Eólico'!AC352 -> 0.41183333 | N24: ='Resumen-DiarioHorario-Eólico'!AC395 -> 0 | O24: ='Resumen-DiarioHorario-Eólico'!AC438 -> 199.435 | P24: ='Resumen-DiarioHorario-Eólico'!AC481 -> 0 | Q24: ='Resumen-DiarioHorario-Eólico'!AC524 -> 0 | R24: ='Resumen-DiarioHorario-Eólico'!AC567 -> 0 | S24: ='Resumen-DiarioHorario-Eólico'!AC610 -> 0 | T24: ='Resumen-DiarioHorario-Eólico'!AC653 -> 98.387333 | U24: ='Resumen-DiarioHorario-Eólico'!AC696 -> 7.234 | V24: ='Resumen-DiarioHorario-Eólico'!AC739 -> 10.3115 | W24: ='Resumen-DiarioHorario-Eólico'!AC782 -> 30.728667 | X24: ='Resumen-DiarioHorario-Eólico'!AC825 -> 13.649833 | Y24: ='Resumen-DiarioHorario-Eólico'!AC868 -> 0 | Z24: ='Resumen-DiarioHorario-Eólico'!AC911 -> 3.8051667 | AA24: ='Resumen-DiarioHorario-Eólico'!AC954 -> 6.6075 | AB24: ='Resumen-DiarioHorario-Eólico'!AC997 -> 0 | AC24: ='Resumen-DiarioHorario-Eólico'!AC1040 -> 0 | AD24: ='Resumen-DiarioHorario-Eólico'!AC1083 -> 0 | AE24: ='Resumen-DiarioHorario-Eólico'!AC1126 -> 0 | AF24: ='Resumen-DiarioHorario-Eólico'!AC1168 -> 96.722167 | AG24: ='Resumen-DiarioHorario-Eólico'!AC1211 -> 45.759 | AH24: ='Resumen-DiarioHorario-Eólico'!AC1254 -> 197.9975 | AI24: ='Resumen-DiarioHorario-Eólico'!AC1297 -> 0 | AJ24: =SUM(E24:AI24) -> 1203.9345
B25: PE-SIERRAGORDA | E25: ='Resumen-DiarioHorario-Eólico'!AC9 -> 375.948 | F25: ='Resumen-DiarioHorario-Eólico'!AC52 -> 243.93717 | G25: ='Resumen-DiarioHorario-Eólico'!AC95 -> 90.725167 | H25: ='Resumen-DiarioHorario-Eólico'!AC138 -> 340.09767 | I25: ='Resumen-DiarioHorario-Eólico'!AC181 -> 397.41817 | J25: ='Resumen-DiarioHorario-Eólico'!AC224 -> 367.01133 | K25: ='Resumen-DiarioHorario-Eólico'!AC267 -> 141.34583 | L25: ='Resumen-DiarioHorario-Eólico'!AC310 -> 0 | M25: ='Resumen-DiarioHorario-Eólico'!AC353 -> 58.5055 | N25: ='Resumen-DiarioHorario-Eólico'!AC396 -> 0 | O25: ='Resumen-DiarioHorario-Eólico'!AC439 -> 137.362 | P25: ='Resumen-DiarioHorario-Eólico'!AC482 -> 211.9025 | Q25: ='Resumen-DiarioHorario-Eólico'!AC525 -> 262.27633 | R25: ='Resumen-DiarioHorario-Eólico'!AC568 -> 4.4561667 | S25: ='Resumen-DiarioHorario-Eólico'!AC611 -> 210.32917 | T25: ='Resumen-DiarioHorario-Eólico'!AC654 -> 192.63317 | U25: ='Resumen-DiarioHorario-Eólico'!AC697 -> 287.8905 | V25: ='Resumen-DiarioHorario-Eólico'!AC740 -> 177.4975 | W25: ='Resumen-DiarioHorario-Eólico'!AC783 -> 304.62783 | X25: ='Resumen-DiarioHorario-Eólico'!AC826 -> 382.69567 | Y25: ='Resumen-DiarioHorario-Eólico'!AC869 -> 344.20367 | Z25: ='Resumen-DiarioHorario-Eólico'!AC912 -> 70.681167 | AA25: ='Resumen-DiarioHorario-Eólico'!AC955 -> 209.16133 | AB25: ='Resumen-DiarioHorario-Eólico'!AC998 -> 0 | AC25: ='Resumen-DiarioHorario-Eólico'!AC1041 -> 0 | AD25: ='Resumen-DiarioHorario-Eólico'!AC1084 -> 167.22183 | AE25: ='Resumen-DiarioHorario-Eólico'!AC1127 -> 202.269 | AF25: ='Resumen-DiarioHorario-Eólico'!AC1169 -> 266.57583 | AG25: ='Resumen-DiarioHorario-Eólico'!AC1212 -> 305.3085 | AH25: ='Resumen-DiarioHorario-Eólico'!AC1255 -> 364.59283 | AI25: ='Resumen-DiarioHorario-Eólico'!AC1298 -> 0 | AJ25: =SUM(E25:AI25) -> 6116.6738
B26: PE-VALLEDELOSVIENTOS | E26: ='Resumen-DiarioHorario-Eólico'!AC10 -> 131.81 | F26: ='Resumen-DiarioHorario-Eólico'!AC53 -> 87.025167 | G26: ='Resumen-DiarioHorario-Eólico'!AC96 -> 82.388667 | H26: ='Resumen-DiarioHorario-Eólico'!AC139 -> 35.1175 | I26: ='Resumen-DiarioHorario-Eólico'!AC182 -> 51.385667 | J26: ='Resumen-DiarioHorario-Eólico'!AC225 -> 40.4655 | K26: ='Resumen-DiarioHorario-Eólico'!AC268 -> 96.599333 | L26: ='Resumen-DiarioHorario-Eólico'!AC311 -> 69.482167 | M26: ='Resumen-DiarioHorario-Eólico'!AC354 -> 100.3095 | N26: ='Resumen-DiarioHorario-Eólico'!AC397 -> 2.112 | O26: ='Resumen-DiarioHorario-Eólico'!AC440 -> 43.519333 | P26: ='Resumen-DiarioHorario-Eólico'!AC483 -> 0.088166667 | Q26: ='Resumen-DiarioHorario-Eólico'!AC526 -> 40.813833 | R26: ='Resumen-DiarioHorario-Eólico'!AC569 -> 28.809833 | S26: ='Resumen-DiarioHorario-Eólico'!AC612 -> 70.495833 | T26: ='Resumen-DiarioHorario-Eólico'!AC655 -> 46.288333 | U26: ='Resumen-DiarioHorario-Eólico'!AC698 -> 113.36117 | V26: ='Resumen-DiarioHorario-Eólico'!AC741 -> 50.753667 | W26: ='Resumen-DiarioHorario-Eólico'!AC784 -> 90.77 | X26: ='Resumen-DiarioHorario-Eólico'!AC827 -> 42.303833 | Y26: ='Resumen-DiarioHorario-Eólico'!AC870 -> 44.485833 | Z26: ='Resumen-DiarioHorario-Eólico'!AC913 -> 23.359 | AA26: ='Resumen-DiarioHorario-Eólico'!AC956 -> 65.468 | AB26: ='Resumen-DiarioHorario-Eólico'!AC999 -> 56.177333 | AC26: ='Resumen-DiarioHorario-Eólico'!AC1042 -> 69.392833 | AD26: ='Resumen-DiarioHorario-Eólico'!AC1085 -> 51.367833 | AE26: ='Resumen-DiarioHorario-Eólico'!AC1128 -> 46.691167 | AF26: ='Resumen-DiarioHorario-Eólico'!AC1170 -> 27.381667 | AG26: ='Resumen-DiarioHorario-Eólico'!AC1213 -> 34.549333 | AH26: ='Resumen-DiarioHorario-Eólico'!AC1256 -> 78.553667 | AI26: ='Resumen-DiarioHorario-Eólico'!AC1299 -> 66.0875 | AJ26: =SUM(E26:AI26) -> 1787.4137
B27: PE-CERROTIGRE * | E27: ='Resumen-DiarioHorario-Eólico'!AC11 -> 0 | F27: ='Resumen-DiarioHorario-Eólico'!AC54 -> 0 | G27: ='Resumen-DiarioHorario-Eólico'!AC97 -> 0 | H27: ='Resumen-DiarioHorario-Eólico'!AC140 -> 0 | I27: ='Resumen-DiarioHorario-Eólico'!AC183 -> 0 | J27: ='Resumen-DiarioHorario-Eólico'!AC226 -> 0 | K27: ='Resumen-DiarioHorario-Eólico'!AC269 -> 0 | L27: ='Resumen-DiarioHorario-Eólico'!AC312 -> 0 | M27: ='Resumen-DiarioHorario-Eólico'!AC355 -> 0 | N27: ='Resumen-DiarioHorario-Eólico'!AC398 -> 0 | O27: ='Resumen-DiarioHorario-Eólico'!AC441 -> 0 | P27: ='Resumen-DiarioHorario-Eólico'!AC484 -> 0 | Q27: ='Resumen-DiarioHorario-Eólico'!AC527 -> 0 | R27: ='Resumen-DiarioHorario-Eólico'!AC570 -> 0 | S27: ='Resumen-DiarioHorario-Eólico'!AC613 -> 0 | T27: ='Resumen-DiarioHorario-Eólico'!AC656 -> 0 | U27: ='Resumen-DiarioHorario-Eólico'!AC699 -> 0 | V27: ='Resumen-DiarioHorario-Eólico'!AC742 -> 0 | W27: ='Resumen-DiarioHorario-Eólico'!AC785 -> 0 | X27: ='Resumen-DiarioHorario-Eólico'!AC828 -> 0 | Y27: ='Resumen-DiarioHorario-Eólico'!AC871 -> 0 | Z27: ='Resumen-DiarioHorario-Eólico'!AC914 -> 0 | AA27: ='Resumen-DiarioHorario-Eólico'!AC957 -> 0 | AB27: ='Resumen-DiarioHorario-Eólico'!AC1000 -> 0 | AC27: ='Resumen-DiarioHorario-Eólico'!AC1043 -> 0 | AD27: ='Resumen-DiarioHorario-Eólico'!AC1086 -> 0 | AE27: ='Resumen-DiarioHorario-Eólico'!AC1129 -> 0 | AF27: ='Resumen-DiarioHorario-Eólico'!AC1171 -> 0 | AG27: ='Resumen-DiarioHorario-Eólico'!AC1214 -> 0 | AH27: ='Resumen-DiarioHorario-Eólico'!AC1257 -> 0 | AI27: ='Resumen-DiarioHorario-Eólico'!AC1300 -> 0 | AJ27: =SUM(E27:AI27) -> 0
B28: PE-CALAMA | E28: ='Resumen-DiarioHorario-Eólico'!AC12 -> 70.6495 | F28: ='Resumen-DiarioHorario-Eólico'!AC55 -> 20.817833 | G28: ='Resumen-DiarioHorario-Eólico'!AC98 -> 15.963 | H28: ='Resumen-DiarioHorario-Eólico'!AC141 -> 2.0201667 | I28: ='Resumen-DiarioHorario-Eólico'!AC184 -> 22.887 | J28: ='Resumen-DiarioHorario-Eólico'!AC227 -> 45.043333 | K28: ='Resumen-DiarioHorario-Eólico'!AC270 -> 11.348333 | L28: ='Resumen-DiarioHorario-Eólico'!AC313 -> 29.603 | M28: ='Resumen-DiarioHorario-Eólico'!AC356 -> 22.87 | N28: ='Resumen-DiarioHorario-Eólico'!AC399 -> 10.672167 | O28: ='Resumen-DiarioHorario-Eólico'!AC442 -> 100.96017 | P28: ='Resumen-DiarioHorario-Eólico'!AC485 -> 199.60167 | Q28: ='Resumen-DiarioHorario-Eólico'!AC528 -> 59.336833 | R28: ='Resumen-DiarioHorario-Eólico'!AC571 -> 16.512833 | S28: ='Resumen-DiarioHorario-Eólico'!AC614 -> 57.215833 | T28: ='Resumen-DiarioHorario-Eólico'!AC657 -> 81.5255 | U28: ='Resumen-DiarioHorario-Eólico'!AC700 -> 131.01317 | V28: ='Resumen-DiarioHorario-Eólico'!AC743 -> 9.5638333 | W28: ='Resumen-DiarioHorario-Eólico'!AC786 -> 1.2778333 | X28: ='Resumen-DiarioHorario-Eólico'!AC829 -> 139.30817 | Y28: ='Resumen-DiarioHorario-Eólico'!AC872 -> 56.418333 | Z28: ='Resumen-DiarioHorario-Eólico'!AC915 -> 0 | AA28: ='Resumen-DiarioHorario-Eólico'!AC958 -> 1.8776667 | AB28: ='Resumen-DiarioHorario-Eólico'!AC1001 -> 30.701333 | AC28: ='Resumen-DiarioHorario-Eólico'!AC1044 -> 18.668 | AD28: ='Resumen-DiarioHorario-Eólico'!AC1087 -> 8.4916667 | AE28: ='Resumen-DiarioHorario-Eólico'!AC1130 -> 2.4348333 | AF28: ='Resumen-DiarioHorario-Eólico'!AC1172 -> 184.80717 | AG28: ='Resumen-DiarioHorario-Eólico'!AC1215 -> 212.745 | AH28: ='Resumen-DiarioHorario-Eólico'!AC1258 -> 31.3865 | AI28: ='Resumen-DiarioHorario-Eólico'!AC1301 -> 2.6051667 | AJ28: =SUM(E28:AI28) -> 1598.3258
B29: PE-TALTAL | E29: ='Resumen-DiarioHorario-Eólico'!AC13 -> 0 | F29: ='Resumen-DiarioHorario-Eólico'!AC56 -> 43.195167 | G29: ='Resumen-DiarioHorario-Eólico'!AC99 -> 66.6805 | H29: ='Resumen-DiarioHorario-Eólico'!AC142 -> 123.75133 | I29: ='Resumen-DiarioHorario-Eólico'!AC185 -> 181.06833 | J29: ='Resumen-DiarioHorario-Eólico'!AC228 -> 88.691333 | K29: ='Resumen-DiarioHorario-Eólico'!AC271 -> 24.324833 | L29: ='Resumen-DiarioHorario-Eólico'!AC314 -> 0.0085 | M29: ='Resumen-DiarioHorario-Eólico'!AC357 -> 3.4371667 | N29: ='Resumen-DiarioHorario-Eólico'!AC400 -> 7.3858333 | O29: ='Resumen-DiarioHorario-Eólico'!AC443 -> 32.481667 | P29: ='Resumen-DiarioHorario-Eólico'!AC486 -> 122.97517 | Q29: ='Resumen-DiarioHorario-Eólico'!AC529 -> 96.214833 | R29: ='Resumen-DiarioHorario-Eólico'!AC572 -> 0.47916667 | S29: ='Resumen-DiarioHorario-Eólico'!AC615 -> 11.572833 | T29: ='Resumen-DiarioHorario-Eólico'!AC658 -> 0 | U29: ='Resumen-DiarioHorario-Eólico'!AC701 -> 58.354667 | V29: ='Resumen-DiarioHorario-Eólico'!AC744 -> 30.989667 | W29: ='Resumen-DiarioHorario-Eólico'!AC787 -> 15.637333 | X29: ='Resumen-DiarioHorario-Eólico'!AC830 -> 170.95383 | Y29: ='Resumen-DiarioHorario-Eólico'!AC873 -> 240.14933 | Z29: ='Resumen-DiarioHorario-Eólico'!AC916 -> 113.98367 | AA29: ='Resumen-DiarioHorario-Eólico'!AC959 -> 115.09317 | AB29: ='Resumen-DiarioHorario-Eólico'!AC1002 -> 0 | AC29: ='Resumen-DiarioHorario-Eólico'!AC1045 -> 16.096 | AD29: ='Resumen-DiarioHorario-Eólico'!AC1088 -> 48.376667 | AE29: ='Resumen-DiarioHorario-Eólico'!AC1131 -> 50.386333 | AF29: ='Resumen-DiarioHorario-Eólico'!AC1173 -> 113.70933 | AG29: ='Resumen-DiarioHorario-Eólico'!AC1216 -> 13.944667 | AH29: ='Resumen-DiarioHorario-Eólico'!AC1259 -> 32.6615 | AI29: ='Resumen-DiarioHorario-Eólico'!AC1302 -> 3.912 | AJ29: =SUM(E29:AI29) -> 1826.5148
B30: PE-SARCO | E30: ='Resumen-DiarioHorario-Eólico'!AC14 -> 496.5445 | F30: ='Resumen-DiarioHorario-Eólico'!AC57 -> 373.91633 | G30: ='Resumen-DiarioHorario-Eólico'!AC100 -> 5.3935 | H30: ='Resumen-DiarioHorario-Eólico'!AC143 -> 47.887333 | I30: ='Resumen-DiarioHorario-Eólico'!AC186 -> 217.99767 | J30: ='Resumen-DiarioHorario-Eólico'!AC229 -> 245.04833 | K30: ='Resumen-DiarioHorario-Eólico'!AC272 -> 0 | L30: ='Resumen-DiarioHorario-Eólico'!AC315 -> 0 | M30: ='Resumen-DiarioHorario-Eólico'!AC358 -> 2.4915 | N30: ='Resumen-DiarioHorario-Eólico'!AC401 -> 0 | O30: ='Resumen-DiarioHorario-Eólico'!AC444 -> 147.16833 | P30: ='Resumen-DiarioHorario-Eólico'!AC487 -> 397.95833 | Q30: ='Resumen-DiarioHorario-Eólico'!AC530 -> 639.96 | R30: ='Resumen-DiarioHorario-Eólico'!AC573 -> 0 | S30: ='Resumen-DiarioHorario-Eólico'!AC616 -> 0 | T30: ='Resumen-DiarioHorario-Eólico'!AC659 -> 195.24167 | U30: ='Resumen-DiarioHorario-Eólico'!AC702 -> 181.63667 | V30: ='Resumen-DiarioHorario-Eólico'!AC745 -> 7.2618333 | W30: ='Resumen-DiarioHorario-Eólico'!AC788 -> 248.56217 | X30: ='Resumen-DiarioHorario-Eólico'!AC831 -> 186.42933 | Y30: ='Resumen-DiarioHorario-Eólico'!AC874 -> 24.848 | Z30: ='Resumen-DiarioHorario-Eólico'!AC917 -> 55.175167 | AA30: ='Resumen-DiarioHorario-Eólico'!AC960 -> 77.1005 | AB30: ='Resumen-DiarioHorario-Eólico'!AC1003 -> 0 | AC30: ='Resumen-DiarioHorario-Eólico'!AC1046 -> 0 | AD30: ='Resumen-DiarioHorario-Eólico'!AC1089 -> 88.676167 | AE30: ='Resumen-DiarioHorario-Eólico'!AC1132 -> 27.773 | AF30: ='Resumen-DiarioHorario-Eólico'!AC1174 -> 17.172333 | AG30: ='Resumen-DiarioHorario-Eólico'!AC1217 -> 259.92667 | AH30: ='Resumen-DiarioHorario-Eólico'!AC1260 -> 233.47783 | AI30: ='Resumen-DiarioHorario-Eólico'!AC1303 -> 0 | AJ30: =SUM(E30:AI30) -> 4177.6472
B31: PE-CABOLEONES-1 | E31: ='Resumen-DiarioHorario-Eólico'!AC15 -> 290.31783 | F31: ='Resumen-DiarioHorario-Eólico'!AC58 -> 408.905 | G31: ='Resumen-DiarioHorario-Eólico'!AC101 -> 2.5895 | H31: ='Resumen-DiarioHorario-Eólico'!AC144 -> 202.36883 | I31: ='Resumen-DiarioHorario-Eólico'!AC187 -> 215.2715 | J31: ='Resumen-DiarioHorario-Eólico'!AC230 -> 195.493 | K31: ='Resumen-DiarioHorario-Eólico'!AC273 -> 10.502667 | L31: ='Resumen-DiarioHorario-Eólico'!AC316 -> 0 | M31: ='Resumen-DiarioHorario-Eólico'!AC359 -> 5.4266667 | N31: ='Resumen-DiarioHorario-Eólico'!AC402 -> 0 | O31: ='Resumen-DiarioHorario-Eólico'!AC445 -> 7.8396667 | P31: ='Resumen-DiarioHorario-Eólico'!AC488 -> 4.1816667 | Q31: ='Resumen-DiarioHorario-Eólico'!AC531 -> 225.81833 | R31: ='Resumen-DiarioHorario-Eólico'!AC574 -> 0 | S31: ='Resumen-DiarioHorario-Eólico'!AC617 -> 65.135 | T31: ='Resumen-DiarioHorario-Eólico'!AC660 -> 196.21317 | U31: ='Resumen-DiarioHorario-Eólico'!AC703 -> 99.672167 | V31: ='Resumen-DiarioHorario-Eólico'!AC746 -> 0 | W31: ='Resumen-DiarioHorario-Eólico'!AC789 -> 118.21667 | X31: ='Resumen-DiarioHorario-Eólico'!AC832 -> 189.73517 | Y31: ='Resumen-DiarioHorario-Eólico'!AC875 -> 109.20433 | Z31: ='Resumen-DiarioHorario-Eólico'!AC918 -> 115.606 | AA31: ='Resumen-DiarioHorario-Eólico'!AC961 -> 88.962167 | AB31: ='Resumen-DiarioHorario-Eólico'!AC1004 -> 0 | AC31: ='Resumen-DiarioHorario-Eólico'!AC1047 -> 0 | AD31: ='Resumen-DiarioHorario-Eólico'!AC1090 -> 52.345 | AE31: ='Resumen-DiarioHorario-Eólico'!AC1133 -> 62.1355 | AF31: ='Resumen-DiarioHorario-Eólico'!AC1175 -> 12.317833 | AG31: ='Resumen-DiarioHorario-Eólico'!AC1218 -> 226.15367 | AH31: ='Resumen-DiarioHorario-Eólico'!AC1261 -> 44.2625 | AI31: ='Resumen-DiarioHorario-Eólico'!AC1304 -> 0 | AJ31: =SUM(E31:AI31) -> 2948.6738
B32: PE-CABOLEONES-2 | E32: ='Resumen-DiarioHorario-Eólico'!AC16 -> 460.74117 | F32: ='Resumen-DiarioHorario-Eólico'!AC59 -> 528.59033 | G32: ='Resumen-DiarioHorario-Eólico'!AC102 -> 71.992667 | H32: ='Resumen-DiarioHorario-Eólico'!AC145 -> 255.079 | I32: ='Resumen-DiarioHorario-Eólico'!AC188 -> 205.59167 | J32: ='Resumen-DiarioHorario-Eólico'!AC231 -> 306.03883 | K32: ='Resumen-DiarioHorario-Eólico'!AC274 -> 20.150667 | L32: ='Resumen-DiarioHorario-Eólico'!AC317 -> 0 | M32: ='Resumen-DiarioHorario-Eólico'!AC360 -> 0.55483333 | N32: ='Resumen-DiarioHorario-Eólico'!AC403 -> 0 | O32: ='Resumen-DiarioHorario-Eólico'!AC446 -> 17.580833 | P32: ='Resumen-DiarioHorario-Eólico'!AC489 -> 28.493667 | Q32: ='Resumen-DiarioHorario-Eólico'!AC532 -> 354.31833 | R32: ='Resumen-DiarioHorario-Eólico'!AC575 -> 0 | S32: ='Resumen-DiarioHorario-Eólico'!AC618 -> 140.24717 | T32: ='Resumen-DiarioHorario-Eólico'!AC661 -> 286.60783 | U32: ='Resumen-DiarioHorario-Eólico'!AC704 -> 484.24733 | V32: ='Resumen-DiarioHorario-Eólico'!AC747 -> 0 | W32: ='Resumen-DiarioHorario-Eólico'!AC790 -> 344.87517 | X32: ='Resumen-DiarioHorario-Eólico'!AC833 -> 719.07317 | Y32: ='Resumen-DiarioHorario-Eólico'!AC876 -> 173.55517 | Z32: ='Resumen-DiarioHorario-Eólico'!AC919 -> 100.26183 | AA32: ='Resumen-DiarioHorario-Eólico'!AC962 -> 177.6045 | AB32: ='Resumen-DiarioHorario-Eólico'!AC1005 -> 0 | AC32: ='Resumen-DiarioHorario-Eólico'!AC1048 -> 0 | AD32: ='Resumen-DiarioHorario-Eólico'!AC1091 -> 69.4375 | AE32: ='Resumen-DiarioHorario-Eólico'!AC1134 -> 75.662333 | AF32: ='Resumen-DiarioHorario-Eólico'!AC1176 -> 93.159833 | AG32: ='Resumen-DiarioHorario-Eólico'!AC1219 -> 258.42667 | AH32: ='Resumen-DiarioHorario-Eólico'!AC1262 -> 134.9545 | AI32: ='Resumen-DiarioHorario-Eólico'!AC1305 -> 0 | AJ32: =SUM(E32:AI32) -> 5307.245
B33: PE-CABOLEONES-3 | E33: ='Resumen-DiarioHorario-Eólico'!AC17 -> 729.52833 | F33: ='Resumen-DiarioHorario-Eólico'!AC60 -> 621.62717 | G33: ='Resumen-DiarioHorario-Eólico'!AC103 -> 87.560333 | H33: ='Resumen-DiarioHorario-Eólico'!AC146 -> 385.92467 | I33: ='Resumen-DiarioHorario-Eólico'!AC189 -> 330.81217 | J33: ='Resumen-DiarioHorario-Eólico'!AC232 -> 405.0295 | K33: ='Resumen-DiarioHorario-Eólico'!AC275 -> 104.94183 | L33: ='Resumen-DiarioHorario-Eólico'!AC318 -> 0 | M33: ='Resumen-DiarioHorario-Eólico'!AC361 -> 12.820667 | N33: ='Resumen-DiarioHorario-Eólico'!AC404 -> 0 | O33: ='Resumen-DiarioHorario-Eólico'!AC447 -> 91.9075 | P33: ='Resumen-DiarioHorario-Eólico'!AC490 -> 89.5795 | Q33: ='Resumen-DiarioHorario-Eólico'!AC533 -> 443.3745 | R33: ='Resumen-DiarioHorario-Eólico'!AC576 -> 24.539667 | S33: ='Resumen-DiarioHorario-Eólico'!AC619 -> 233.32833 | T33: ='Resumen-DiarioHorario-Eólico'!AC662 -> 349.04183 | U33: ='Resumen-DiarioHorario-Eólico'!AC705 -> 271.312 | V33: ='Resumen-DiarioHorario-Eólico'!AC748 -> 8.2663333 | W33: ='Resumen-DiarioHorario-Eólico'!AC791 -> 301.0975 | X33: ='Resumen-DiarioHorario-Eólico'!AC834 -> 419.72217 | Y33: ='Resumen-DiarioHorario-Eólico'!AC877 -> 164.05017 | Z33: ='Resumen-DiarioHorario-Eólico'!AC920 -> 284.9085 | AA33: ='Resumen-DiarioHorario-Eólico'!AC963 -> 421.679 | AB33: ='Resumen-DiarioHorario-Eólico'!AC1006 -> 0 | AC33: ='Resumen-DiarioHorario-Eólico'!AC1049 -> 0 | AD33: ='Resumen-DiarioHorario-Eólico'!AC1092 -> 144.30967 | AE33: ='Resumen-DiarioHorario-Eólico'!AC1135 -> 222.4305 | AF33: ='Resumen-DiarioHorario-Eólico'!AC1177 -> 290.94233 | AG33: ='Resumen-DiarioHorario-Eólico'!AC1220 -> 464.91667 | AH33: ='Resumen-DiarioHorario-Eólico'!AC1263 -> 441.128 | AI33: ='Resumen-DiarioHorario-Eólico'!AC1306 -> 0 | AJ33: =SUM(E33:AI33) -> 7344.7788
B34: PE-SANJUAN | E34: ='Resumen-DiarioHorario-Eólico'!AC18 -> 691.9525 | F34: ='Resumen-DiarioHorario-Eólico'!AC61 -> 474.511 | G34: ='Resumen-DiarioHorario-Eólico'!AC104 -> 1.012 | H34: ='Resumen-DiarioHorario-Eólico'!AC147 -> 93.547333 | I34: ='Resumen-DiarioHorario-Eólico'!AC190 -> 87.821833 | J34: ='Resumen-DiarioHorario-Eólico'!AC233 -> 62.3855 | K34: ='Resumen-DiarioHorario-Eólico'!AC276 -> 0 | L34: ='Resumen-DiarioHorario-Eólico'!AC319 -> 0 | M34: ='Resumen-DiarioHorario-Eólico'!AC362 -> 15.0355 | N34: ='Resumen-DiarioHorario-Eólico'!AC405 -> 0 | O34: ='Resumen-DiarioHorario-Eólico'!AC448 -> 0 | P34: ='Resumen-DiarioHorario-Eólico'!AC491 -> 0 | Q34: ='Resumen-DiarioHorario-Eólico'!AC534 -> 24.5395 | R34: ='Resumen-DiarioHorario-Eólico'!AC577 -> 0 | S34: ='Resumen-DiarioHorario-Eólico'!AC620 -> 99.821833 | T34: ='Resumen-DiarioHorario-Eólico'!AC663 -> 431.03217 | U34: ='Resumen-DiarioHorario-Eólico'!AC706 -> 169.87783 | V34: ='Resumen-DiarioHorario-Eólico'!AC749 -> 0 | W34: ='Resumen-DiarioHorario-Eólico'!AC792 -> 127.27383 | X34: ='Resumen-DiarioHorario-Eólico'!AC835 -> 211.62483 | Y34: ='Resumen-DiarioHorario-Eólico'!AC878 -> 147.27183 | Z34: ='Resumen-DiarioHorario-Eólico'!AC921 -> 58.9085 | AA34: ='Resumen-DiarioHorario-Eólico'!AC964 -> 25.734833 | AB34: ='Resumen-DiarioHorario-Eólico'!AC1007 -> 0 | AC34: ='Resumen-DiarioHorario-Eólico'!AC1050 -> 0 | AD34: ='Resumen-DiarioHorario-Eólico'!AC1093 -> 110.15867 | AE34: ='Resumen-DiarioHorario-Eólico'!AC1136 -> 54.096333 | AF34: ='Resumen-DiarioHorario-Eólico'!AC1178 -> 24.483333 | AG34: ='Resumen-DiarioHorario-Eólico'!AC1221 -> 318.58233 | AH34: ='Resumen-DiarioHorario-Eólico'!AC1264 -> 202.51867 | AI34: ='Resumen-DiarioHorario-Eólico'!AC1307 -> 0 | AJ34: =SUM(E34:AI34) -> 3432.1902
B35: PE-PUNTACOLORADA | E35: ='Resumen-DiarioHorario-Eólico'!AC19 -> 42.212167 | F35: ='Resumen-DiarioHorario-Eólico'!AC62 -> 40.655167 | G35: ='Resumen-DiarioHorario-Eólico'!AC105 -> 0 | H35: ='Resumen-DiarioHorario-Eólico'!AC148 -> 30.16 | I35: ='Resumen-DiarioHorario-Eólico'!AC191 -> 32.492167 | J35: ='Resumen-DiarioHorario-Eólico'!AC234 -> 25.644167 | K35: ='Resumen-DiarioHorario-Eólico'!AC277 -> 9.1128333 | L35: ='Resumen-DiarioHorario-Eólico'!AC320 -> 0 | M35: ='Resumen-DiarioHorario-Eólico'!AC363 -> 9.2695 | N35: ='Resumen-DiarioHorario-Eólico'!AC406 -> 0 | O35: ='Resumen-DiarioHorario-Eólico'!AC449 -> 8.7263333 | P35: ='Resumen-DiarioHorario-Eólico'!AC492 -> 20.115 | Q35: ='Resumen-DiarioHorario-Eólico'!AC535 -> 25.0035 | R35: ='Resumen-DiarioHorario-Eólico'!AC578 -> 2.4516667 | S35: ='Resumen-DiarioHorario-Eólico'!AC621 -> 10.516667 | T35: ='Resumen-DiarioHorario-Eólico'!AC664 -> 9.3833333 | U35: ='Resumen-DiarioHorario-Eólico'!AC707 -> 10.060833 | V35: ='Resumen-DiarioHorario-Eólico'!AC750 -> 6.3933333 | W35: ='Resumen-DiarioHorario-Eólico'!AC793 -> 8.2075 | X35: ='Resumen-DiarioHorario-Eólico'!AC836 -> 6.5158333 | Y35: ='Resumen-DiarioHorario-Eólico'!AC879 -> 7.3475 | Z35: ='Resumen-DiarioHorario-Eólico'!AC922 -> 15.286167 | AA35: ='Resumen-DiarioHorario-Eólico'!AC965 -> 7.8675 | AB35: ='Resumen-DiarioHorario-Eólico'!AC1008 -> 0 | AC35: ='Resumen-DiarioHorario-Eólico'!AC1051 -> 0 | AD35: ='Resumen-DiarioHorario-Eólico'!AC1094 -> 10.080667 | AE35: ='Resumen-DiarioHorario-Eólico'!AC1137 -> 4.0606667 | AF35: ='Resumen-DiarioHorario-Eólico'!AC1179 -> 17.107167 | AG35: ='Resumen-DiarioHorario-Eólico'!AC1222 -> 17.454833 | AH35: ='Resumen-DiarioHorario-Eólico'!AC1265 -> 23.018833 | AI35: ='Resumen-DiarioHorario-Eólico'!AC1308 -> 0 | AJ35: =SUM(E35:AI35) -> 399.14333
... B60: PE-ALENA | E60: ='Resumen-DiarioHorario-Eólico'!AC44 -> 231.824 | F60: ='Resumen-DiarioHorario-Eólico'!AC87 -> 261.65733 | G60: ='Resumen-DiarioHorario-Eólico'!AC130 -> 0 | H60: ='Resumen-DiarioHorario-Eólico'!AC173 -> 0 | I60: ='Resumen-DiarioHorario-Eólico'!AC216 -> 0 | J60: ='Resumen-DiarioHorario-Eólico'!AC259 -> 0 | K60: ='Resumen-DiarioHorario-Eólico'!AC302 -> 0 | L60: ='Resumen-DiarioHorario-Eólico'!AC345 -> 0 | M60: ='Resumen-DiarioHorario-Eólico'!AC388 -> 0 | N60: ='Resumen-DiarioHorario-Eólico'!AC431 -> 0 | O60: ='Resumen-DiarioHorario-Eólico'!AC474 -> 0 | P60: ='Resumen-DiarioHorario-Eólico'!AC517 -> 0 | Q60: ='Resumen-DiarioHorario-Eólico'!AC560 -> 0 | R60: ='Resumen-DiarioHorario-Eólico'!AC603 -> 0 | S60: ='Resumen-DiarioHorario-Eólico'!AC646 -> 53.079333 | T60: ='Resumen-DiarioHorario-Eólico'!AC689 -> 0 | U60: ='Resumen-DiarioHorario-Eólico'!AC732 -> 4.7955 | V60: ='Resumen-DiarioHorario-Eólico'!AC775 -> 0 | W60: ='Resumen-DiarioHorario-Eólico'!AC818 -> 0 | X60: ='Resumen-DiarioHorario-Eólico'!AC861 -> 1.2688333 | Y60: ='Resumen-DiarioHorario-Eólico'!AC904 -> 0 | Z60: ='Resumen-DiarioHorario-Eólico'!AC947 -> 0 | AA60: ='Resumen-DiarioHorario-Eólico'!AC990 -> 0 | AB60: ='Resumen-DiarioHorario-Eólico'!AC1033 -> 0 | AC60: ='Resumen-DiarioHorario-Eólico'!AC1076 -> 0 | AD60: ='Resumen-DiarioHorario-Eólico'!AC1119 -> 0 | AE60: ='Resumen-DiarioHorario-Eólico'!AC1162 -> 0 | AF60: ='Resumen-DiarioHorario-Eólico'!AC1204 -> 0 | AG60: ='Resumen-DiarioHorario-Eólico'!AC1247 -> 0 | AH60: ='Resumen-DiarioHorario-Eólico'!AC1290 -> 14.089 | AI60: ='Resumen-DiarioHorario-Eólico'!AC1333 -> 0 | AJ60: =SUM(E60:AI60) -> 566.714
B64: DESGLOSE DIARIO DE CURTAILMENTS DE ENERGÍA SOLAR
B66: Central / Día | E66: =E22 -> 44562 | F66: =F22 -> 44563 | G66: =G22 -> 44564 | H66: =H22 -> 44565 | I66: =I22 -> 44566 | J66: =J22 -> 44567 | K66: =K22 -> 44568 | L66: =L22 -> 44569 | ... AI66: =AI22 -> 44592 | AJ66: Total
B67: Total | E67: =SUM(E68:E116) -> 5637.6028 | F67: =SUM(F68:F116) -> 4370.6822 | G67: =SUM(G68:G116) -> 483.3605 | H67: =SUM(H68:H116) -> 2516.4855 | I67: =SUM(I68:I116) -> 2837.8305 | J67: =SUM(J68:J116) -> 1484.8965 | K67: =SUM(K68:K116) -> 453.25483 | L67: =SUM(L68:L116) -> 355.5485 | ... AI67: =SUM(AI68:AI116) -> 482.02283 | AJ67: =SUM(AJ68:AK116) -> 43442.221
B68: PFV-POZOALMONTE-2 | E68: ='Resumen-DiarioHorario-Solar'!AC8 -> 6.4098333 | F68: ='Resumen-DiarioHorario-Solar'!AC63 -> 6.0046667 | G68: ='Resumen-DiarioHorario-Solar'!AC118 -> 0.97666667 | H68: ='Resumen-DiarioHorario-Solar'!AC173 -> 5.5136667 | I68: ='Resumen-DiarioHorario-Solar'!AC228 -> 7.4816667 | J68: ='Resumen-DiarioHorario-Solar'!AC283 -> 0.48916667 | K68: ='Resumen-DiarioHorario-Solar'!AC338 -> 0.0745 | L68: ='Resumen-DiarioHorario-Solar'!AC393 -> 0 | M68: ='Resumen-DiarioHorario-Solar'!AC448 -> 0.2995 | N68: ='Resumen-DiarioHorario-Solar'!AC503 -> 0 | O68: ='Resumen-DiarioHorario-Solar'!AC558 -> 0 | P68: ='Resumen-DiarioHorario-Solar'!AC613 -> 0.64983333 | Q68: ='Resumen-DiarioHorario-Solar'!AC668 -> 2.3038333 | R68: ='Resumen-DiarioHorario-Solar'!AC723 -> 0 | S68: ='Resumen-DiarioHorario-Solar'!AC778 -> 0 | T68: ='Resumen-DiarioHorario-Solar'!AC833 -> 1.0166667 | U68: ='Resumen-DiarioHorario-Solar'!AC888 -> 0.026166667 | V68: ='Resumen-DiarioHorario-Solar'!AC943 -> 0.5725 | W68: ='Resumen-DiarioHorario-Solar'!AC998 -> 0.44566667 | X68: ='Resumen-DiarioHorario-Solar'!AC1053 -> 0 | Y68: ='Resumen-DiarioHorario-Solar'!AC1108 -> 0 | Z68: ='Resumen-DiarioHorario-Solar'!AC1163 -> 2.3913333 | AA68: ='Resumen-DiarioHorario-Solar'!AC1218 -> 0.20516667 | AB68: ='Resumen-DiarioHorario-Solar'!AC1273 -> 0 | AC68: ='Resumen-DiarioHorario-Solar'!AC1328 -> 0 | AD68: ='Resumen-DiarioHorario-Solar'!AC1383 -> 0.022 | AE68: ='Resumen-DiarioHorario-Solar'!AC1438 -> 1.2658333 | AF68: ='Resumen-DiarioHorario-Solar'!AC1493 -> 0.087333333 | AG68: ='Resumen-DiarioHorario-Solar'!AC1548 -> 7.3616667 | AH68: ='Resumen-DiarioHorario-Solar'!AC1603 -> 4.2343333 | AI68: ='Resumen-DiarioHorario-Solar'!AC1658 -> 0 | AJ68: =SUM(E68:AI68) -> 47.832
B69: PFV-POZOALMONTE-3 | E69: ='Resumen-DiarioHorario-Solar'!AC9 -> 7.9505 | F69: ='Resumen-DiarioHorario-Solar'!AC64 -> 5.0803333 | G69: ='Resumen-DiarioHorario-Solar'!AC119 -> 0.179 | H69: ='Resumen-DiarioHorario-Solar'!AC174 -> 8.9066667 | I69: ='Resumen-DiarioHorario-Solar'!AC229 -> 19.514667 | J69: ='Resumen-DiarioHorario-Solar'!AC284 -> 0.71433333 | K69: ='Resumen-DiarioHorario-Solar'!AC339 -> 0.7055 | L69: ='Resumen-DiarioHorario-Solar'!AC394 -> 0 | M69: ='Resumen-DiarioHorario-Solar'!AC449 -> 0.20266667 | N69: ='Resumen-DiarioHorario-Solar'!AC504 -> 0 | O69: ='Resumen-DiarioHorario-Solar'!AC559 -> 0.51216667 | P69: ='Resumen-DiarioHorario-Solar'!AC614 -> 2.062 | Q69: ='Resumen-DiarioHorario-Solar'!AC669 -> 4.9898333 | R69: ='Resumen-DiarioHorario-Solar'!AC724 -> 1.0831667 | S69: ='Resumen-DiarioHorario-Solar'!AC779 -> 1.3455 | T69: ='Resumen-DiarioHorario-Solar'!AC834 -> 0.16716667 | U69: ='Resumen-DiarioHorario-Solar'!AC889 -> 0 | V69: ='Resumen-DiarioHorario-Solar'!AC944 -> 0 | W69: ='Resumen-DiarioHorario-Solar'!AC999 -> 0 | X69: ='Resumen-DiarioHorario-Solar'!AC1054 -> 0 | Y69: ='Resumen-DiarioHorario-Solar'!AC1109 -> 0 | Z69: ='Resumen-DiarioHorario-Solar'!AC1164 -> 0 | AA69: ='Resumen-DiarioHorario-Solar'!AC1219 -> 3.3101667 | AB69: ='Resumen-DiarioHorario-Solar'!AC1274 -> 0 | AC69: ='Resumen-DiarioHorario-Solar'!AC1329 -> 0 | AD69: ='Resumen-DiarioHorario-Solar'!AC1384 -> 0.19466667 | AE69: ='Resumen-DiarioHorario-Solar'!AC1439 -> 3.3141667 | AF69: ='Resumen-DiarioHorario-Solar'!AC1494 -> 6.6795 | AG69: ='Resumen-DiarioHorario-Solar'!AC1549 -> 5.1121667 | AH69: ='Resumen-DiarioHorario-Solar'!AC1604 -> 7.0381667 | AI69: ='Resumen-DiarioHorario-Solar'!AC1659 -> 0 | AJ69: =SUM(E69:AI69) -> 79.062333
B70: PFV-LAHUAYCA-2 | E70: ='Resumen-DiarioHorario-Solar'!AC10 -> 33.761833 | F70: ='Resumen-DiarioHorario-Solar'!AC65 -> 32.543 | G70: ='Resumen-DiarioHorario-Solar'!AC120 -> 0.5705 | H70: ='Resumen-DiarioHorario-Solar'!AC175 -> 16.7035 | I70: ='Resumen-DiarioHorario-Solar'!AC230 -> 19.068 | J70: ='Resumen-DiarioHorario-Solar'!AC285 -> 0.80266667 | K70: ='Resumen-DiarioHorario-Solar'!AC340 -> 0.27 | L70: ='Resumen-DiarioHorario-Solar'!AC395 -> 0 | M70: ='Resumen-DiarioHorario-Solar'!AC450 -> 0.017 | N70: ='Resumen-DiarioHorario-Solar'!AC505 -> 0 | O70: ='Resumen-DiarioHorario-Solar'!AC560 -> 5.3516667 | P70: ='Resumen-DiarioHorario-Solar'!AC615 -> 25.206167 | Q70: ='Resumen-DiarioHorario-Solar'!AC670 -> 12.7305 | R70: ='Resumen-DiarioHorario-Solar'!AC725 -> 1.717 | S70: ='Resumen-DiarioHorario-Solar'!AC780 -> 0.7455 | T70: ='Resumen-DiarioHorario-Solar'!AC835 -> 3.077 | U70: ='Resumen-DiarioHorario-Solar'!AC890 -> 0.86883333 | V70: ='Resumen-DiarioHorario-Solar'!AC945 -> 0 | W70: ='Resumen-DiarioHorario-Solar'!AC1000 -> 19.86 | X70: ='Resumen-DiarioHorario-Solar'!AC1055 -> 26.492833 | Y70: ='Resumen-DiarioHorario-Solar'!AC1110 -> 0 | Z70: ='Resumen-DiarioHorario-Solar'!AC1165 -> 0.57016667 | AA70: ='Resumen-DiarioHorario-Solar'!AC1220 -> 9.5323333 | AB70: ='Resumen-DiarioHorario-Solar'!AC1275 -> 0 | AC70: ='Resumen-DiarioHorario-Solar'!AC1330 -> 0 | AD70: ='Resumen-DiarioHorario-Solar'!AC1385 -> 0 | AE70: ='Resumen-DiarioHorario-Solar'!AC1440 -> 5.4583333 | AF70: ='Resumen-DiarioHorario-Solar'!AC1495 -> 1.9133333 | AG70: ='Resumen-DiarioHorario-Solar'!AC1550 -> 2.3501667 | AH70: ='Resumen-DiarioHorario-Solar'!AC1605 -> 54.038167 | AI70: ='Resumen-DiarioHorario-Solar'!AC1660 -> 0 | AJ70: =SUM(E70:AI70) -> 273.6485
B71: PFV-SANTAISABEL | E71: ='Resumen-DiarioHorario-Solar'!AC11 -> 637.85033 | F71: ='Resumen-DiarioHorario-Solar'!AC66 -> 130.4355 | G71: ='Resumen-DiarioHorario-Solar'!AC121 -> 0 | H71: ='Resumen-DiarioHorario-Solar'!AC176 -> 48.374667 | I71: ='Resumen-DiarioHorario-Solar'!AC231 -> 93.350833 | J71: ='Resumen-DiarioHorario-Solar'!AC286 -> 20.537833 | K71: ='Resumen-DiarioHorario-Solar'!AC341 -> 0 | L71: ='Resumen-DiarioHorario-Solar'!AC396 -> 0 | M71: ='Resumen-DiarioHorario-Solar'!AC451 -> 0.028333333 | N71: ='Resumen-DiarioHorario-Solar'!AC506 -> 0 | O71: ='Resumen-DiarioHorario-Solar'!AC561 -> 21.919 | P71: ='Resumen-DiarioHorario-Solar'!AC616 -> 3.3483333 | Q71: ='Resumen-DiarioHorario-Solar'!AC671 -> 15.184333 | R71: ='Resumen-DiarioHorario-Solar'!AC726 -> 0 | S71: ='Resumen-DiarioHorario-Solar'!AC781 -> 1.488 | T71: ='Resumen-DiarioHorario-Solar'!AC836 -> 4.6251667 | U71: ='Resumen-DiarioHorario-Solar'!AC891 -> 6.378 | V71: ='Resumen-DiarioHorario-Solar'!AC946 -> 0.3155 | W71: ='Resumen-DiarioHorario-Solar'!AC1001 -> 0.025833333 | X71: ='Resumen-DiarioHorario-Solar'!AC1056 -> 9.2688333 | Y71: ='Resumen-DiarioHorario-Solar'!AC1111 -> 0 | Z71: ='Resumen-DiarioHorario-Solar'!AC1166 -> 0 | AA71: ='Resumen-DiarioHorario-Solar'!AC1221 -> 358.992 | AB71: ='Resumen-DiarioHorario-Solar'!AC1276 -> 0 | AC71: ='Resumen-DiarioHorario-Solar'!AC1331 -> 0 | AD71: ='Resumen-DiarioHorario-Solar'!AC1386 -> 0 | AE71: ='Resumen-DiarioHorario-Solar'!AC1441 -> 2.58 | AF71: ='Resumen-DiarioHorario-Solar'!AC1496 -> 1.7925 | AG71: ='Resumen-DiarioHorario-Solar'!AC1551 -> 0.17016667 | AH71: ='Resumen-DiarioHorario-Solar'!AC1606 -> 35.794333 | AI71: ='Resumen-DiarioHorario-Solar'!AC1661 -> 0 | AJ71: =SUM(E71:AI71) -> 1392.4595
B72: PFV-HUATACONDO | E72: ='Resumen-DiarioHorario-Solar'!AC12 -> 90.176 | F72: ='Resumen-DiarioHorario-Solar'!AC67 -> 36.588 | G72: ='Resumen-DiarioHorario-Solar'!AC122 -> 3.3573333 | H72: ='Resumen-DiarioHorario-Solar'!AC177 -> 54.7005 | I72: ='Resumen-DiarioHorario-Solar'!AC232 -> 78.878833 | J72: ='Resumen-DiarioHorario-Solar'!AC287 -> 13.0155 | K72: ='Resumen-DiarioHorario-Solar'!AC342 -> 54.052167 | L72: ='Resumen-DiarioHorario-Solar'!AC397 -> 2.2356667 | M72: ='Resumen-DiarioHorario-Solar'!AC452 -> 15.131667 | N72: ='Resumen-DiarioHorario-Solar'!AC507 -> 45.353833 | O72: ='Resumen-DiarioHorario-Solar'!AC562 -> 121.268 | P72: ='Resumen-DiarioHorario-Solar'!AC617 -> 22.125833 | Q72: ='Resumen-DiarioHorario-Solar'!AC672 -> 81.832167 | R72: ='Resumen-DiarioHorario-Solar'!AC727 -> 0 | S72: ='Resumen-DiarioHorario-Solar'!AC782 -> 0.221 | T72: ='Resumen-DiarioHorario-Solar'!AC837 -> 31.618667 | U72: ='Resumen-DiarioHorario-Solar'!AC892 -> 32.6585 | V72: ='Resumen-DiarioHorario-Solar'!AC947 -> 14.874833 | W72: ='Resumen-DiarioHorario-Solar'!AC1002 -> 42.9385 | X72: ='Resumen-DiarioHorario-Solar'!AC1057 -> 3.6 | Y72: ='Resumen-DiarioHorario-Solar'!AC1112 -> 56.0025 | Z72: ='Resumen-DiarioHorario-Solar'!AC1167 -> 0 | AA72: ='Resumen-DiarioHorario-Solar'!AC1222 -> 25.285 | AB72: ='Resumen-DiarioHorario-Solar'!AC1277 -> 0.46533333 | AC72: ='Resumen-DiarioHorario-Solar'!AC1332 -> 0 | AD72: ='Resumen-DiarioHorario-Solar'!AC1387 -> 31.162 | AE72: ='Resumen-DiarioHorario-Solar'!AC1442 -> 42.586333 | AF72: ='Resumen-DiarioHorario-Solar'!AC1497 -> 0.073333333 | AG72: ='Resumen-DiarioHorario-Solar'!AC1552 -> 66.583 | AH72: ='Resumen-DiarioHorario-Solar'!AC1607 -> 8.446 | AI72: ='Resumen-DiarioHorario-Solar'!AC1662 -> 0 | AJ72: =SUM(E72:AI72) -> 975.2305
B73: PFV-ATACAMASOLAR-2 | E73: ='Resumen-DiarioHorario-Solar'!AC13 -> 75.845333 | F73: ='Resumen-DiarioHorario-Solar'!AC68 -> 10.090833 | G73: ='Resumen-DiarioHorario-Solar'!AC123 -> 0 | H73: ='Resumen-DiarioHorario-Solar'!AC178 -> 7.9671667 | I73: ='Resumen-DiarioHorario-Solar'!AC233 -> 19.190667 | J73: ='Resumen-DiarioHorario-Solar'!AC288 -> 0 | K73: ='Resumen-DiarioHorario-Solar'!AC343 -> 21.997833 | L73: ='Resumen-DiarioHorario-Solar'!AC398 -> 0 | M73: ='Resumen-DiarioHorario-Solar'!AC453 -> 0 | N73: ='Resumen-DiarioHorario-Solar'!AC508 -> 0 | O73: ='Resumen-DiarioHorario-Solar'!AC563 -> 3.7576667 | P73: ='Resumen-DiarioHorario-Solar'!AC618 -> 27.141667 | Q73: ='Resumen-DiarioHorario-Solar'!AC673 -> 102.85933 | R73: ='Resumen-DiarioHorario-Solar'!AC728 -> 2.1695 | S73: ='Resumen-DiarioHorario-Solar'!AC783 -> 0 | T73: ='Resumen-DiarioHorario-Solar'!AC838 -> 0.52716667 | U73: ='Resumen-DiarioHorario-Solar'!AC893 -> 2.1545 | V73: ='Resumen-DiarioHorario-Solar'!AC948 -> 0 | W73: ='Resumen-DiarioHorario-Solar'!AC1003 -> 0 | X73: ='Resumen-DiarioHorario-Solar'!AC1058 -> 2.0243333 | Y73: ='Resumen-DiarioHorario-Solar'!AC1113 -> 0.034166667 | Z73: ='Resumen-DiarioHorario-Solar'!AC1168 -> 0 | AA73: ='Resumen-DiarioHorario-Solar'!AC1223 -> 6.7291667 | AB73: ='Resumen-DiarioHorario-Solar'!AC1278 -> 0 | AC73: ='Resumen-DiarioHorario-Solar'!AC1333 -> 0 | AD73: ='Resumen-DiarioHorario-Solar'!AC1388 -> 0.028166667 | AE73: ='Resumen-DiarioHorario-Solar'!AC1443 -> 42.126 | AF73: ='Resumen-DiarioHorario-Solar'!AC1498 -> 18.498 | AG73: ='Resumen-DiarioHorario-Solar'!AC1553 -> 0 | AH73: ='Resumen-DiarioHorario-Solar'!AC1608 -> 0 | AI73: ='Resumen-DiarioHorario-Solar'!AC1663 -> 0 | AJ73: =SUM(E73:AI73) -> 343.1415
B74: PFV-NUEVOQUILLAGUA | E74: ='Resumen-DiarioHorario-Solar'!AC14 -> 275.15017 | F74: ='Resumen-DiarioHorario-Solar'!AC69 -> 202.304 | G74: ='Resumen-DiarioHorario-Solar'!AC124 -> 6.084 | H74: ='Resumen-DiarioHorario-Solar'!AC179 -> 58.896833 | I74: ='Resumen-DiarioHorario-Solar'!AC234 -> 81.192833 | J74: ='Resumen-DiarioHorario-Solar'!AC289 -> 50.307833 | K74: ='Resumen-DiarioHorario-Solar'!AC344 -> 54.652833 | L74: ='Resumen-DiarioHorario-Solar'!AC399 -> 45.7735 | M74: ='Resumen-DiarioHorario-Solar'!AC454 -> 23.054333 | N74: ='Resumen-DiarioHorario-Solar'!AC509 -> 0.1455 | O74: ='Resumen-DiarioHorario-Solar'!AC564 -> 116.03533 | P74: ='Resumen-DiarioHorario-Solar'!AC619 -> 39.385833 | Q74: ='Resumen-DiarioHorario-Solar'!AC674 -> 2.7796667 | R74: ='Resumen-DiarioHorario-Solar'!AC729 -> 13.005833 | S74: ='Resumen-DiarioHorario-Solar'!AC784 -> 0.56616667 | T74: ='Resumen-DiarioHorario-Solar'!AC839 -> 45.0905 | U74: ='Resumen-DiarioHorario-Solar'!AC894 -> 15.523833 | V74: ='Resumen-DiarioHorario-Solar'!AC949 -> 11.162167 | W74: ='Resumen-DiarioHorario-Solar'!AC1004 -> 8.795 | X74: ='Resumen-DiarioHorario-Solar'!AC1059 -> 0.0048333333 | Y74: ='Resumen-DiarioHorario-Solar'!AC1114 -> 67.718833 | Z74: ='Resumen-DiarioHorario-Solar'!AC1169 -> 111.32633 | AA74: ='Resumen-DiarioHorario-Solar'!AC1224 -> 119.312 | AB74: ='Resumen-DiarioHorario-Solar'!AC1279 -> 0.41133333 | AC74: ='Resumen-DiarioHorario-Solar'!AC1334 -> 0.42733333 | AD74: ='Resumen-DiarioHorario-Solar'!AC1389 -> 26.536333 | AE74: ='Resumen-DiarioHorario-Solar'!AC1444 -> 48.6005 | AF74: ='Resumen-DiarioHorario-Solar'!AC1499 -> 61.264167 | AG74: ='Resumen-DiarioHorario-Solar'!AC1554 -> 92.104333 | AH74: ='Resumen-DiarioHorario-Solar'!AC1609 -> 63.8145 | AI74: ='Resumen-DiarioHorario-Solar'!AC1664 -> 14.481167 | AJ74: =SUM(E74:AI74) -> 1655.9078
B75: PFV-GRANJA | E75: ='Resumen-DiarioHorario-Solar'!AC15 -> 72.896333 | F75: ='Resumen-DiarioHorario-Solar'!AC70 -> 44.234 | G75: ='Resumen-DiarioHorario-Solar'!AC125 -> 0 | H75: ='Resumen-DiarioHorario-Solar'!AC180 -> 33.3755 | I75: ='Resumen-DiarioHorario-Solar'!AC235 -> 60.0965 | J75: ='Resumen-DiarioHorario-Solar'!AC290 -> 0 | K75: ='Resumen-DiarioHorario-Solar'!AC345 -> 2.6935 | L75: ='Resumen-DiarioHorario-Solar'!AC400 -> 0 | M75: ='Resumen-DiarioHorario-Solar'!AC455 -> 0 | N75: ='Resumen-DiarioHorario-Solar'!AC510 -> 0 | O75: ='Resumen-DiarioHorario-Solar'!AC565 -> 13.237333 | P75: ='Resumen-DiarioHorario-Solar'!AC620 -> 54.544667 | Q75: ='Resumen-DiarioHorario-Solar'!AC675 -> 135.55533 | R75: ='Resumen-DiarioHorario-Solar'!AC730 -> 0.72883333 | S75: ='Resumen-DiarioHorario-Solar'!AC785 -> 0 | T75: ='Resumen-DiarioHorario-Solar'!AC840 -> 0 | U75: ='Resumen-DiarioHorario-Solar'!AC895 -> 0.020666667 | V75: ='Resumen-DiarioHorario-Solar'!AC950 -> 1.8473333 | W75: ='Resumen-DiarioHorario-Solar'!AC1005 -> 0 | X75: ='Resumen-DiarioHorario-Solar'!AC1060 -> 7.2875 | Y75: ='Resumen-DiarioHorario-Solar'!AC1115 -> 0 | Z75: ='Resumen-DiarioHorario-Solar'!AC1170 -> 0.034666667 | AA75: ='Resumen-DiarioHorario-Solar'!AC1225 -> 32.744667 | AB75: ='Resumen-DiarioHorario-Solar'!AC1280 -> 0 | AC75: ='Resumen-DiarioHorario-Solar'!AC1335 -> 0 | AD75: ='Resumen-DiarioHorario-Solar'!AC1390 -> 3.2745 | AE75: ='Resumen-DiarioHorario-Solar'!AC1445 -> 12.188833 | AF75: ='Resumen-DiarioHorario-Solar'!AC1500 -> 8.0225 | AG75: ='Resumen-DiarioHorario-Solar'!AC1555 -> 1.3175 | AH75: ='Resumen-DiarioHorario-Solar'!AC1610 -> 45.874 | AI75: ='Resumen-DiarioHorario-Solar'!AC1665 -> 0 | AJ75: =SUM(E75:AI75) -> 529.97417
B76: PFV-USYA | E76: ='Resumen-DiarioHorario-Solar'!AC16 -> 120.39 | F76: ='Resumen-DiarioHorario-Solar'!AC71 -> 64.603833 | G76: ='Resumen-DiarioHorario-Solar'!AC126 -> 70.936667 | H76: ='Resumen-DiarioHorario-Solar'!AC181 -> 105.713 | I76: ='Resumen-DiarioHorario-Solar'!AC236 -> 79.2085 | J76: ='Resumen-DiarioHorario-Solar'!AC291 -> 47.313167 | K76: ='Resumen-DiarioHorario-Solar'!AC346 -> 96.404667 | L76: ='Resumen-DiarioHorario-Solar'!AC401 -> 78.159 | M76: ='Resumen-DiarioHorario-Solar'!AC456 -> 43.289 | N76: ='Resumen-DiarioHorario-Solar'!AC511 -> 78.276833 | O76: ='Resumen-DiarioHorario-Solar'!AC566 -> 99.849667 | P76: ='Resumen-DiarioHorario-Solar'!AC621 -> 30.3985 | Q76: ='Resumen-DiarioHorario-Solar'!AC676 -> 37.3545 | R76: ='Resumen-DiarioHorario-Solar'!AC731 -> 62.285833 | S76: ='Resumen-DiarioHorario-Solar'!AC786 -> 78.7175 | T76: ='Resumen-DiarioHorario-Solar'!AC841 -> 77.759167 | U76: ='Resumen-DiarioHorario-Solar'!AC896 -> 60.681333 | V76: ='Resumen-DiarioHorario-Solar'!AC951 -> 120.89517 | W76: ='Resumen-DiarioHorario-Solar'!AC1006 -> 33.880667 | X76: ='Resumen-DiarioHorario-Solar'!AC1061 -> 13.145833 | Y76: ='Resumen-DiarioHorario-Solar'!AC1116 -> 25.633667 | Z76: ='Resumen-DiarioHorario-Solar'!AC1171 -> 48.655167 | AA76: ='Resumen-DiarioHorario-Solar'!AC1226 -> 28.4545 | AB76: ='Resumen-DiarioHorario-Solar'!AC1281 -> 55.062333 | AC76: ='Resumen-DiarioHorario-Solar'!AC1336 -> 59.8805 | AD76: ='Resumen-DiarioHorario-Solar'!AC1391 -> 44.862667 | AE76: ='Resumen-DiarioHorario-Solar'!AC1446 -> 8.7906667 | AF76: ='Resumen-DiarioHorario-Solar'!AC1501 -> 31.473 | AG76: ='Resumen-DiarioHorario-Solar'!AC1556 -> 46.997833 | AH76: ='Resumen-DiarioHorario-Solar'!AC1611 -> 77.736667 | AI76: ='Resumen-DiarioHorario-Solar'!AC1666 -> 85.873667 | AJ76: =SUM(E76:AI76) -> 1912.6835
B77: PFV-SANPEDRO-GPG | E77: ='Resumen-DiarioHorario-Solar'!AC17 -> 134.54617 | F77: ='Resumen-DiarioHorario-Solar'!AC72 -> 212.428 | G77: ='Resumen-DiarioHorario-Solar'!AC127 -> 67.772 | H77: ='Resumen-DiarioHorario-Solar'!AC182 -> 142.22517 | I77: ='Resumen-DiarioHorario-Solar'!AC237 -> 117.4485 | J77: ='Resumen-DiarioHorario-Solar'!AC292 -> 55.668167 | K77: ='Resumen-DiarioHorario-Solar'!AC347 -> 48.343667 | L77: ='Resumen-DiarioHorario-Solar'!AC402 -> 114.31183 | M77: ='Resumen-DiarioHorario-Solar'!AC457 -> 94.6445 | N77: ='Resumen-DiarioHorario-Solar'!AC512 -> 234.5245 | O77: ='Resumen-DiarioHorario-Solar'!AC567 -> 7.8305 | P77: ='Resumen-DiarioHorario-Solar'!AC622 -> 78.643 | Q77: ='Resumen-DiarioHorario-Solar'!AC677 -> 137.10317 | R77: ='Resumen-DiarioHorario-Solar'!AC732 -> 75.624833 | S77: ='Resumen-DiarioHorario-Solar'!AC787 -> 174.639 | T77: ='Resumen-DiarioHorario-Solar'!AC842 -> 79.991 | U77: ='Resumen-DiarioHorario-Solar'!AC897 -> 4.8996667 | V77: ='Resumen-DiarioHorario-Solar'!AC952 -> 127.13383 | W77: ='Resumen-DiarioHorario-Solar'!AC1007 -> 52.67 | X77: ='Resumen-DiarioHorario-Solar'!AC1062 -> 86.266667 | Y77: ='Resumen-DiarioHorario-Solar'!AC1117 -> 74.924667 | Z77: ='Resumen-DiarioHorario-Solar'!AC1172 -> 107.77633 | AA77: ='Resumen-DiarioHorario-Solar'!AC1227 -> 121.34583 | AB77: ='Resumen-DiarioHorario-Solar'!AC1282 -> 64.6565 | AC77: ='Resumen-DiarioHorario-Solar'!AC1337 -> 21.404 | AD77: ='Resumen-DiarioHorario-Solar'!AC1392 -> 65.704 | AE77: ='Resumen-DiarioHorario-Solar'!AC1447 -> 132.52333 | AF77: ='Resumen-DiarioHorario-Solar'!AC1502 -> 0.033333333 | AG77: ='Resumen-DiarioHorario-Solar'!AC1557 -> 64.122833 | AH77: ='Resumen-DiarioHorario-Solar'!AC1612 -> 68.991333 | AI77: ='Resumen-DiarioHorario-Solar'!AC1667 -> 119.192 | AJ77: =SUM(E77:AI77) -> 2887.3883
...

Sheet Resumen-DiarioHorario-Eólico
B2: CURTAILMENTS EÓLICAS POR CENTRALES EN FORMA DIARIA/HORARIA
B5: ='Resumen-Mensual'!$E$22 -> 44562
B7: Central/Hora | E7: 1 | F7: 2 | G7: 3 | H7: 4 | I7: 5 | J7: 6 | K7: 7 | L7: 8 | M7: 9 | N7: 10 | O7: 11 | P7: 12 | Q7: 13 | R7: 14 | S7: 15 | T7: 16 | U7: 17 | V7: 18 | W7: 19 | X7: 20 | Y7: 21 | Z7: 22 | AA7: 23 | AB7: 24 | AC7: Total
B8: PE-TCHAMMA | E8: 0 | F8: 0 | G8: 0 | H8: 0 | I8: 0 | J8: 0 | K8: 0 | L8: 0 | M8: 0 | N8: 0 | O8: 4.8538333 | P8: 11.198667 | Q8: 1.0118333 | R8: 0 | S8: 0.32183333 | T8: 0 | U8: 0 | V8: 0 | W8: 9.893 | X8: 12.7565 | Y8: 0 | Z8: 0 | AA8: 0 | AB8: 0 | AC8: =SUM(E8:AB8) -> 40.035667
B9: PE-SIERRAGORDA | E9: 0 | F9: 0 | G9: 0 | H9: 0 | I9: 0 | J9: 0 | K9: 0 | L9: 0 | M9: 0 | N9: 0 | O9: 0 | P9: 1.717 | Q9: 18.222833 | R9: 31.246167 | S9: 44.260833 | T9: 58.359333 | U9: 68.076 | V9: 65.919667 | W9: 67.0925 | X9: 21.053667 | Y9: 0 | Z9: 0 | AA9: 0 | AB9: 0 | AC9: =SUM(E9:AB9) -> 375.948
B10: PE-VALLEDELOSVIENTOS | E10: 0 | F10: 0 | G10: 0 | H10: 0 | I10: 0 | J10: 0 | K10: 0 | L10: 0 | M10: 0 | N10: 0 | O10: 0 | P10: 1.1998333 | Q10: 13.1035 | R10: 20.3525 | S10: 7.8423333 | T10: 0 | U10: 28.6775 | V10: 11.487167 | W10: 27.0945 | X10: 22.052667 | Y10: 0 | Z10: 0 | AA10: 0 | AB10: 0 | AC10: =SUM(E10:AB10) -> 131.81
B11: PE-CERROTIGRE * | E11: 0 | F11: 0 | G11: 0 | H11: 0 | I11: 0 | J11: 0 | K11: 0 | L11: 0 | M11: 0 | N11: 0 | O11: 0 | P11: 0 | Q11: 0 | R11: 0 | S11: 0 | T11: 0 | U11: 0 | V11: 0 | W11: 0 | X11: 0 | Y11: 0 | Z11: 0 | AA11: 0 | AB11: 0 | AC11: =SUM(E11:AB11) -> 0
B12: PE-CALAMA | E12: 0 | F12: 0 | G12: 0 | H12: 0 | I12: 0 | J12: 0 | K12: 0 | L12: 0 | M12: 6.409 | N12: 3.5953333 | O12: 0.15533333 | P12: 11.230833 | Q12: 5.446 | R12: 31.667167 | S12: 0 | T12: 0.0016666667 | U12: 0 | V12: 0.17433333 | W12: 0.0023333333 | X12: 11.9675 | Y12: 0 | Z12: 0 | AA12: 0 | AB12: 0 | AC12: =SUM(E12:AB12) -> 70.6495
B13: PE-TALTAL | E13: 0 | F13: 0 | G13: 0 | H13: 0 | I13: 0 | J13: 0 | K13: 0 | L13: 0 | M13: 0 | N13: 0 | O13: 0 | P13: 0 | Q13: 0 | R13: 0 | S13: 0 | T13: 0 | U13: 0 | V13: 0 | W13: 0 | X13: 0 | Y13: 0 | Z13: 0 | AA13: 0 | AB13: 0 | AC13: =SUM(E13:AB13) -> 0
B14: PE-SARCO | E14: 0 | F14: 0 | G14: 0 | H14: 0 | I14: 0 | J14: 0 | K14: 0 | L14: 0 | M14: 1.4563333 | N14: 2.6985 | O14: 5.0588333 | P14: 10.983167 | Q14: 16.426333 | R14: 25.166333 | S14: 37.801667 | T14: 63.856 | U14: 94.180333 | V14: 99.478667 | W14: 103.8345 | X14: 35.603833 | Y14: 0 | Z14: 0 | AA14: 0 | AB14: 0 | AC14: =SUM(E14:AB14) -> 496.5445
B15: PE-CABOLEONES-1 | E15: 0 | F15: 0 | G15: 0 | H15: 0 | I15: 0 | J15: 0 | K15: 0 | L15: 0 | M15: 0.33983333 | N15: 1.786 | O15: 5.5665 | P15: 11.641833 | Q15: 19.9815 | R15: 17.277333 | S15: 18.46 | T15: 39.502 | U15: 58.686667 | V15: 63.329167 | W15: 50.479333 | X15: 3.2676667 | Y15: 0 | Z15: 0 | AA15: 0 | AB15: 0 | AC15: =SUM(E15:AB15) -> 290.31783
B16: PE-CABOLEONES-2 | E16: 0 | F16: 0 | G16: 0 | H16: 0 | I16: 0 | J16: 0 | K16: 0 | L16: 0 | M16: 1.3101667 | N16: 2.82 | O16: 3.52 | P16: 6.7595 | Q16: 14.734167 | R16: 29.065833 | S16: 49.842333 | T16: 70.680833 | U16: 88.881667 | V16: 86.727 | W16: 83.968833 | X16: 22.430833 | Y16: 0 | Z16: 0 | AA16: 0 | AB16: 0 | AC16: =SUM(E16:AB16) -> 460.74117
B17: PE-CABOLEONES-3 | E17: 0 | F17: 0 | G17: 0 | H17: 0 | I17: 0 | J17: 0 | K17: 0 | L17: 0 | M17: 4.0558333 | N17: 6.0173333 | O17: 10.1455 | P17: 22.4085 | Q17: 43.294833 | R17: 65.253167 | S17: 92.7055 | T17: 116.67617 | U17: 130.97733 | V17: 114.1235 | W17: 98.133 | X17: 25.737667 | Y17: 0 | Z17: 0 | AA17: 0 | AB17: 0 | AC17: =SUM(E17:AB17) -> 729.52833
B18: PE-SANJUAN | E18: 0 | F18: 0 | G18: 0 | H18: 0 | I18: 0 | J18: 0 | K18: 0 | L18: 0 | M18: 3.6725 | N18: 3.3281667 | O18: 8.9013333 | P18: 15.738667 | Q18: 31.228667 | R18: 52.9015 | S18: 75.967667 | T18: 102.2995 | U18: 131.336 | V18: 115.20417 | W18: 120.21883 | X18: 31.1555 | Y18: 0 | Z18: 0 | AA18: 0 | AB18: 0 | AC18: =SUM(E18:AB18) -> 691.9525
B19: PE-PUNTACOLORADA | E19: 0 | F19: 0 | G19: 0 | H19: 0 | I19: 0 | J19: 0 | K19: 0 | L19: 0 | M19: 0.0175 | N19: 0.13 | O19: 0.43 | P19: 1.83 | Q19: 4.13 | R19: 5.63 | S19: 6.03 | T19: 5.7361667 | U19: 5.54 | V19: 4.84 | W19: 5.14 | X19: 2.7585 | Y19: 0 | Z19: 0 | AA19: 0 | AB19: 0 | AC19: =SUM(E19:AB19) -> 42.212167
... B44: PE-ALENA | E44: 0 | F44: 0 | G44: 0 | H44: 0 | I44: 0 | J44: 0 | K44: 0 | L44: 0 | M44: 0 | N44: 0 | O44: 1.8273333 | P44: 9.8256667 | Q44: 20.122833 | R44: 24.946167 | S44: 31.460833 | T44: 38.859333 | U44: 42.976 | V44: 32.319667 | W44: 25.7925 | X44: 3.6936667 | Y44: 0 | Z44: 0 | AA44: 0 | AB44: 0 | AC44: =SUM(E44:AB44) -> 231.824
B45: Total | E45: =SUM(E8:E44) -> 0 | F45: =SUM(F8:F44) -> 0 | G45: =SUM(G8:G44) -> 0 | H45: =SUM(H8:H44) -> 0 | I45: =SUM(I8:I44) -> 0 | J45: =SUM(J8:J44) -> 0 | K45: =SUM(K8:K44) -> 0 | L45: =SUM(L8:L44) -> 0 | ... AB45: =SUM(AB8:AB44) -> 0 | AC45: =SUM(AC8:AE44) -> 5534.6365
B48: ='Resumen-Mensual'!$F$22 -> 44563
B50: Central/Hora | E50: 1 | F50: 2 | G50: 3 | H50: 4 | I50: 5 | J50: 6 | K50: 7 | L50: 8 | M50: 9 | N50: 10 | O50: 11 | P50: 12 | Q50: 13 | R50: 14 | S50: 15 | T50: 16 | U50: 17 | V50: 18 | W50: 19 | X50: 20 | Y50: 21 | Z50: 22 | AA50: 23 | AB50: 24 | AC50: Total
B51: PE-TCHAMMA | E51: 0 | F51: 0 | G51: 0 | H51: 0 | I51: 0 | J51: 0 | K51: 0 | L51: 0 | M51: 11.8015 | N51: 23.830167 | O51: 7.9038333 | P51: 5.1316667 | Q51: 3.8305 | R51: 0.90133333 | S51: 3.049 | T51: 11.57 | U51: 49.819333 | V51: 75.9625 | W51: 45.172 | X51: 0 | Y51: 0 | Z51: 0 | AA51: 0 | AB51: 0 | AC51: =SUM(E51:AB51) -> 238.97183
B52: PE-SIERRAGORDA | E52: 0 | F52: 0 | G52: 0 | H52: 0 | I52: 0 | J52: 0 | K52: 0 | L52: 0 | M52: 0 | N52: 0 | O52: 0 | P52: 0.133 | Q52: 3.686 | R52: 16.127667 | S52: 28.795 | T52: 34.1195 | U52: 43.150333 | V52: 57.223 | W52: 54.395 | X52: 6.3076667 | Y52: 0 | Z52: 0 | AA52: 0 | AB52: 0 | AC52: =SUM(E52:AB52) -> 243.93717
B53: PE-VALLEDELOSVIENTOS | E53: 0 | F53: 0 | G53: 0 | H53: 0 | I53: 0 | J53: 0 | K53: 0 | L53: 0 | M53: 0 | N53: 0 | O53: 0 | P53: 0.19366667 | Q53: 1.2981667 | R53: 0 | S53: 0 | T53: 0 | U53: 21.3015 | V53: 14.494833 | W53: 40.707167 | X53: 9.0298333 | Y53: 0 | Z53: 0 | AA53: 0 | AB53: 0 | AC53: =SUM(E53:AB53) -> 87.025167
B54: PE-CERROTIGRE * | E54: 0 | F54: 0 | G54: 0 | H54: 0 | I54: 0 | J54: 0 | K54: 0 | L54: 0 | M54: 0 | N54: 0 | O54: 0 | P54: 0 | Q54: 0 | R54: 0 | S54: 0 | T54: 0 | U54: 0 | V54: 0 | W54: 0 | X54: 0 | Y54: 0 | Z54: 0 | AA54: 0 | AB54: 0 | AC54: =SUM(E54:AB54) -> 0
B55: PE-CALAMA | E55: 0 | F55: 0 | G55: 0 | H55: 0 | I55: 0 | J55: 0 | K55: 0 | L55: 0 | M55: 0 | N55: 0.25133333 | O55: 0.027166667 | P55: 0 | Q55: 0.037333333 | R55: 2.0765 | S55: 0 | T55: 0 | U55: 0.038333333 | V55: 0 | W55: 0 | X55: 18.387167 | Y55: 0 | Z55: 0 | AA55: 0 | AB55: 0 | AC55: =SUM(E55:AB55) -> 20.817833
B56: PE-TALTAL | E56: 0 | F56: 0 | G56: 0 | H56: 0 | I56: 0 | J56: 0 | K56: 0 | L56: 0 | M56: 0 | N56: 0 | O56: 0 | P56: 0 | Q56: 0 | R56: 2.5506667 | S56: 0 | T56: 5.1705 | U56: 20.904167 | V56: 14.298667 | W56: 0.27116667 | X56: 0 | Y56: 0 | Z56: 0 | AA56: 0 | AB56: 0 | AC56: =SUM(E56:AB56) -> 43.195167
B57: PE-SARCO | E57: 0 | F57: 0 | G57: 0 | H57: 0 | I57: 0 | J57: 0 | K57: 0 | L57: 0 | M57: 0.75933333 | N57: 3.4988333 | O57: 3.8236667 | P57: 11.694 | Q57: 18.480833 | R57: 32.083167 | S57: 42.340667 | T57: 56.983667 | U57: 65.957333 | V57: 60.216667 | W57: 66.141833 | X57: 11.936333 | Y57: 0 | Z57: 0 | AA57: 0 | AB57: 0 | AC57: =SUM(E57:AB57) -> 373.91633
B58: PE-CABOLEONES-1 | E58: 0 | F58: 0 | G58: 0 | H58: 0 | I58: 0 | J58: 0 | K58: 0 | L58: 0 | M58: 0.56533333 | N58: 2.5993333 | O58: 6.4873333 | P58: 13.672 | Q58: 21.916167 | R58: 30.316 | S58: 29.410333 | T58: 45.646333 | U58: 68.156167 | V58: 88.424333 | W58: 88.445167 | X58: 13.2665 | Y58: 0 | Z58: 0 | AA58: 0 | AB58: 0 | AC58: =SUM(E58:AB58) -> 408.905
B59: PE-CABOLEONES-2 | E59: 0 | F59: 0 | G59: 0 | H59: 0 | I59: 0 | J59: 0 | K59: 0 | L59: 0 | M59: 1.0553333 | N59: 2.2503333 | O59: 2.0471667 | P59: 9.967 | Q59: 19.651833 | R59: 34.010833 | S59: 40.5515 | T59: 60.9755 | U59: 84.972333 | V59: 116.62167 | W59: 134.38817 | X59: 22.098667 | Y59: 0 | Z59: 0 | AA59: 0 | AB59: 0 | AC59: =SUM(E59:AB59) -> 528.59033
B60: PE-CABOLEONES-3 | E60: 0 | F60: 0 | G60: 0 | H60: 0 | I60: 0 | J60: 0 | K60: 0 | L60: 0 | M60: 2.7596667 | N60: 5.4588333 | O60: 10.629167 | P60: 19.226333 | Q60: 30.753 | R60: 44.076167 | S60: 52.131333 | T60: 76.986333 | U60: 102.09667 | V60: 121.61817 | W60: 134.433 | X60: 21.4585 | Y60: 0 | Z60: 0 | AA60: 0 | AB60: 0 | AC60: =SUM(E60:AB60) -> 621.62717
B61: PE-SANJUAN | E61: 0 | F61: 0 | G61: 0 | H61: 0 | I61: 0 | J61: 0 | K61: 0 | L61: 0 | M61: 4.5431667 | N61: 11.225833 | O61: 15.702833 | P61: 21.312833 | Q61: 30.213167 | R61: 44.074667 | S61: 49.459 | T61: 56.565 | U61: 79.769667 | V61: 67.876 | W61: 82.125667 | X61: 11.643167 | Y61: 0 | Z61: 0 | AA61: 0 | AB61: 0 | AC61: =SUM(E61:AB61) -> 474.511
B62: PE-PUNTACOLORADA | E62: 0 | F62: 0 | G62: 0 | H62: 0 | I62: 0 | J62: 0 | K62: 0 | L62: 0 | M62: 0.052 | N62: 0.13 | O62: 0.53 | P62: 2.13 | Q62: 4.03 | R62: 5.63 | S62: 6.0435 | T62: 5.7578333 | U62: 5.4741667 | V62: 4.8888333 | W62: 5.1953333 | X62: 0.7935 | Y62: 0 | Z62: 0 | AA62: 0 | AB62: 0 | AC62: =SUM(E62:AB62) -> 40.655167
... B87: PE-ALENA | E87: 0 | F87: 0 | G87: 0 | H87: 0 | I87: 0 | J87: 0 | K87: 0 | L87: 0 | M87: 15.315667 | N87: 43.402667 | O87: 44.7415 | P87: 42.573167 | Q87: 33.031167 | R87: 24.527667 | S87: 14.295 | T87: 10.8195 | U87: 10.550333 | V87: 11.623 | W87: 9.795 | X87: 0.98266667 | Y87: 0 | Z87: 0 | AA87: 0 | AB87: 0 | AC87: =SUM(E87:AB87) -> 261.65733
B88: Total | E88: =SUM(E51:E87) -> 0 | F88: =SUM(F51:F87) -> 0 | G88: =SUM(G51:G87) -> 0 | H88: =SUM(H51:H87) -> 0 | I88: =SUM(I51:I87) -> 0 | J88: =SUM(J51:J87) -> 0 | K88: =SUM(K51:K87) -> 0 | L88: =SUM(L51:L87) -> 0 | ... AB88: =SUM(AB51:AB87) -> 0 | AC88: =SUM(AC51:AE87) -> 5449.3832
B91: ='Resumen-Mensual'!$G$22 -> 44564
B93: Central/Hora | E93: 1 | F93: 2 | G93: 3 | H93: 4 | I93: 5 | J93: 6 | K93: 7 | L93: 8 | M93: 9 | N93: 10 | O93: 11 | P93: 12 | Q93: 13 | R93: 14 | S93: 15 | T93: 16 | U93: 17 | V93: 18 | W93: 19 | X93: 20 | Y93: 21 | Z93: 22 | AA93: 23 | AB93: 24 | AC93: Total
B94: PE-TCHAMMA | E94: 0 | F94: 0 | G94: 0 | H94: 0 | I94: 0 | J94: 0 | K94: 0 | L94: 0 | M94: 0 | N94: 0 | O94: 0 | P94: 0 | Q94: 0 | R94: 0 | S94: 0 | T94: 0 | U94: 0.40283333 | V94: 31.593833 | W94: 12.082833 | X94: 0 | Y94: 0 | Z94: 0 | AA94: 0 | AB94: 0 | AC94: =SUM(E94:AB94) -> 44.0795
B95: PE-SIERRAGORDA | E95: 0 | F95: 0 | G95: 0 | H95: 0 | I95: 0 | J95: 0 | K95: 0 | L95: 0 | M95: 0 | N95: 0 | O95: 0 | P95: 0 | Q95: 0 | R95: 0 | S95: 0 | T95: 0 | U95: 9.5136667 | V95: 58.414167 | W95: 22.797333 | X95: 0 | Y95: 0 | Z95: 0 | AA95: 0 | AB95: 0 | AC95: =SUM(E95:AB95) -> 90.725167
B96: PE-VALLEDELOSVIENTOS | E96: 0 | F96: 0 | G96: 0 | H96: 0 | I96: 0 | J96: 0 | K96: 0 | L96: 0 | M96: 0 | N96: 0 | O96: 0 | P96: 0 | Q96: 0 | R96: 0 | S96: 0 | T96: 14.290167 | U96: 13.880833 | V96: 14.870333 | W96: 31.679333 | X96: 7.668 | Y96: 0 | Z96: 0 | AA96: 0 | AB96: 0 | AC96: =SUM(E96:AB96) -> 82.388667
B97: PE-CERROTIGRE * | E97: 0 | F97: 0 | G97: 0 | H97: 0 | I97: 0 | J97: 0 | K97: 0 | L97: 0 | M97: 0 | N97: 0 | O97: 0 | P97: 0 | Q97: 0 | R97: 0 | S97: 0 | T97: 0 | U97: 0 | V97: 0 | W97: 0 | X97: 0 | Y97: 0 | Z97: 0 | AA97: 0 | AB97: 0 | AC97: =SUM(E97:AB97) -> 0
B98: PE-CALAMA | E98: 0 | F98: 0 | G98: 0 | H98: 0 | I98: 0 | J98: 0 | K98: 0 | L98: 0 | M98: 0 | N98: 0 | O98: 0 | P98: 0 | Q98: 0 | R98: 11.273333 | S98: 0 | T98: 0.023833333 | U98: 0 | V98: 0.089166667 | W98: 0 | X98: 4.5766667 | Y98: 0 | Z98: 0 | AA98: 0 | AB98: 0 | AC98: =SUM(E98:AB98) -> 15.963
...

Sheet Resumen-DiarioHorario-Solar
B2: CURTAILMENTS SOLAR POR CENTRALES EN FORMA DIARIA/HORARIA
B5: ='Resumen-Mensual'!$E$22 -> 44562
B7: Central/Hora | E7: 1 | F7: 2 | G7: 3 | H7: 4 | I7: 5 | J7: 6 | K7: 7 | L7: 8 | M7: 9 | N7: 10 | O7: 11 | P7: 12 | Q7: 13 | R7: 14 | S7: 15 | T7: 16 | U7: 17 | V7: 18 | W7: 19 | X7: 20 | Y7: 21 | Z7: 22 | AA7: 23 | AB7: 24 | AC7: Total
B8: PFV-POZOALMONTE-2 | E8: 0 | F8: 0 | G8: 0 | H8: 0 | I8: 0 | J8: 0 | K8: 0 | L8: 0 | M8: 0.18266667 | N8: 0.99216667 | O8: 0.9175 | P8: 0.7605 | Q8: 0 | R8: 0 | S8: 0.52583333 | T8: 0.49216667 | U8: 0 | V8: 1.5218333 | W8: 1.0171667 | X8: 0 | Y8: 0 | Z8: 0 | AA8: 0 | AB8: 0 | AC8: =SUM(E8:AB8) -> 6.4098333
B9: PFV-POZOALMONTE-3 | E9: 0 | F9: 0 | G9: 0 | H9: 0 | I9: 0 | J9: 0 | K9: 0 | L9: 0 | M9: 0.22566667 | N9: 0.11966667 | O9: 0.5115 | P9: 1.0226667 | Q9: 0 | R9: 0 | S9: 0.6775 | T9: 0.79983333 | U9: 0 | V9: 2.161 | W9: 2.4326667 | X9: 0 | Y9: 0 | Z9: 0 | AA9: 0 | AB9: 0 | AC9: =SUM(E9:AB9) -> 7.9505
B10: PFV-LAHUAYCA-2 | E10: 0 | F10: 0 | G10: 0 | H10: 0 | I10: 0 | J10: 0 | K10: 0 | L10: 0 | M10: 2.625 | N10: 9.9 | O10: 1.5711667 | P10: 3.9466667 | Q10: 0 | R10: 0 | S10: 7.257 | T10: 5.7216667 | U10: 0 | V10: 0.9515 | W10: 1.1211667 | X10: 0.66766667 | Y10: 0 | Z10: 0 | AA10: 0 | AB10: 0 | AC10: =SUM(E10:AB10) -> 33.761833
B11: PFV-SANTAISABEL | E11: 0 | F11: 0 | G11: 0 | H11: 0 | I11: 0 | J11: 0 | K11: 0 | L11: 0 | M11: 29.009167 | N11: 88.43 | O11: 94.23 | P11: 97.43 | Q11: 98.63 | R11: 99.83 | S11: 98.33 | T11: 0 | U11: 0 | V11: 0 | W11: 31.961167 | X11: 0 | Y11: 0 | Z11: 0 | AA11: 0 | AB11: 0 | AC11: =SUM(E11:AB11) -> 637.85033
B12: PFV-HUATACONDO | E12: 0 | F12: 0 | G12: 0 | H12: 0 | I12: 0 | J12: 0 | K12: 0 | L12: 0 | M12: 2.6411667 | N12: 18.938 | O12: 18.752667 | P12: 0 | Q12: 19.580667 | R12: 21.791167 | S12: 0 | T12: 0 | U12: 0 | V12: 0 | W12: 8.4258333 | X12: 0.0465 | Y12: 0 | Z12: 0 | AA12: 0 | AB12: 0 | AC12: =SUM(E12:AB12) -> 90.176
B13: PFV-ATACAMASOLAR-2 | E13: 0 | F13: 0 | G13: 0 | H13: 0 | I13: 0 | J13: 0 | K13: 0 | L13: 0 | M13: 0 | N13: 0 | O13: 0 | P13: 16.974833 | Q13: 0 | R13: 0 | S13: 32.921333 | T13: 25.949167 | U13: 0 | V13: 0 | W13: 0 | X13: 0 | Y13: 0 | Z13: 0 | AA13: 0 | AB13: 0 | AC13: =SUM(E13:AB13) -> 75.845333
B14: PFV-NUEVOQUILLAGUA | E14: 0 | F14: 0 | G14: 0 | H14: 0 | I14: 0 | J14: 0 | K14: 0 | L14: 0 | M14: 13.129 | N14: 30.949667 | O14: 24.088333 | P14: 15.435 | Q14: 17.655 | R14: 15.804833 | S14: 18.3505 | T14: 19.676333 | U14: 35.975 | V14: 47.441667 | W14: 36.598333 | X14: 0.0465 | Y14: 0 | Z14: 0 | AA14: 0 | AB14: 0 | AC14: =SUM(E14:AB14) -> 275.15017
B15: PFV-GRANJA | E15: 0 | F15: 0 | G15: 0 | H15: 0 | I15: 0 | J15: 0 | K15: 0 | L15: 0 | M15: 0 | N15: 0 | O15: 0 | P15: 0 | Q15: 18.860833 | R15: 27.058 | S15: 0 | T15: 0 | U15: 0 | V15: 0 | W15: 26.9775 | X15: 0 | Y15: 0 | Z15: 0 | AA15: 0 | AB15: 0 | AC15: =SUM(E15:AB15) -> 72.896333
