Workbook

Sheet Resumen-Mensual
B2: RESUMEN DE CURTAILMENTS ACUMULADO DE CENTRALES EÓLICAS, SOLARES HIDRÁULICAS DE PASADA, EMBALSES Y SERIES HÍDRICAS AÑO 2025
C4: Resumen Anual / Mensual (GWh)
C6: Acumulado 2025
B7: Eólica | C7: =SUM(C14,F14,I14,L14,O14,R14,U14,X14,AA14,AD14,AG14,AJ14) -> 433.60088 | E7: =IF($C$11=0,"-",+C7/$C$11) -> 0.22103504
B8: Solar | C8: =SUM(C15,F15,I15,L15,O15,R15,U15,X15,AA15,AD15,AG15,AJ15) -> 1487.8473 | E8: =IF($C$11=0,"-",+C8/$C$11) -> 0.75845419 | Y8: =+AJ84/1000-X15 -> 266.28583
B9: Hidro Pasada | C9: =SUM(C16,F16,I16,L16,O16,R16,U16,X16,AA16,AD16,AG16,AJ16) -> 38.244804 | E9: =IF($C$11=0,"-",+C9/$C$11) -> 0.019495906
B10: Hidro Embalse | C10: =SUM(C17,F17,I17,L17,O17,R17,U17,X17,AA17,AD17,AG17,AJ17) -> 1.9908386 | E10: =IF($C$11=0,"-",+C10/$C$11) -> 0.0010148621
B11: Total | C11: =SUM(C7:C10) -> 1961.6839 | E11: =SUM(E7:E10) -> 1
C13: 45658 | F13: 45689 | I13: 45717 | L13: 45748 | O13: 45778 | R13: 45809 | U13: 45839 | X13: 45870 | AA13: 45901 | AD13: 45931 | AG13: 45962 | AJ13: 45992
B14: Eólica | C14: ='Acumulado-Anual-Eólico'!AJ10/1000 -> 147.02888 | E14: =IF($C$18=0,"-",+C14/$C$18) -> 0.22184096 | F14: ='Acumulado-Anual-Eólico'!AJ65/1000 -> 100.28563 | H14: =IF($F$18=0,"-",+F14/$F$18) -> 0.23812007 | I14: ='Acumulado-Anual-Eólico'!$AJ$120/1000 -> 121.00713 | K14: =IF($I$18=0,"-",+I14/$I$18) -> 0.2223667 | L14: ='Acumulado-Anual-Eólico'!AJ175/1000 -> 65.27924 | N14: =IF($L$18=0,"-",+L14/$L$18) -> 0.19569124 | O14: 0 | Q14: =IF($O$18=0,"-",+O14/$O$18) -> - | R14: 0 | T14: =IF($R$18=0,"-",+R14/$R$18) -> - | U14: 0 | W14: =IF($U$18=0,"-",+U14/$U$18) -> - | X14: 0 | Z14: =IF($X$18=0,"-",+X14/$X$18) -> - | AA14: 0 | AC14: =IF($AA$18=0,"-",+AA14/$AA$18) -> - | AD14: 0 | AF14: =IF($AD$18=0,"-",+AD14/$AD$18) -> - | AG14: 0 | AI14: =IF($AG$18=0,"-",+AG14/$AG$18) -> - | AJ14: 0 | AL14: =IF($AJ$18=0,"-",+AJ14/$AJ$18) -> -
B15: Solar | C15: ='Acumulado-Anual-Solar'!AJ10/1000 -> 494.3341 | E15: =IF($C$18=0,"-",+C15/$C$18) -> 0.74586401 | F15: ='Acumulado-Anual-Solar'!AJ84/1000 -> 311.23959 | H15: =IF($F$18=0,"-",+F15/$F$18) -> 0.73901313 | I15: ='Acumulado-Anual-Solar'!$AJ$158/1000 -> 415.98783 | K15: =IF($I$18=0,"-",+I15/$I$18) -> 0.76443301 | L15: ='Acumulado-Anual-Solar'!AJ232/1000 -> 266.28583 | N15: =IF($L$18=0,"-",+L15/$L$18) -> 0.79825998 | O15: 0 | Q15: =IF($O$18=0,"-",+O15/$O$18) -> - | R15: 0 | T15: =IF($R$18=0,"-",+R15/$R$18) -> - | U15: 0 | W15: =IF($U$18=0,"-",+U15/$U$18) -> - | X15: 0 | Z15: =IF($X$18=0,"-",+X15/$X$18) -> - | AA15: 0 | AC15: =IF($AA$18=0,"-",+AA15/$AA$18) -> - | AD15: 0 | AF15: =IF($AD$18=0,"-",+AD15/$AD$18) -> - | AG15: 0 | AI15: =IF($AG$18=0,"-",+AG15/$AG$18) -> - | AJ15: 0 | AL15: =IF($AJ$18=0,"-",+AJ15/$AJ$18) -> -
B16: Hidro Pasada | C16: =+'Acumulado-Anual-HP'!AJ11/1000 -> 20.43018 | E16: =IF($C$18=0,"-",+C16/$C$18) -> 0.030825581 | F16: =+'Acumulado-Anual-HP'!AJ152/1000 -> 8.6135453 | H16: =IF($F$18=0,"-",+F16/$F$18) -> 0.020452164 | I16: ='Acumulado-Anual-HP'!AJ293/1000 -> 7.18331 | K16: =IF($I$18=0,"-",+I16/$I$18) -> 0.013200288 | L16: ='Acumulado-Anual-HP'!AJ434/1000 -> 2.0177691 | N16: =IF($L$18=0,"-",+L16/$L$18) -> 0.0060487797 | O16: 0 | Q16: =IF($O$18=0,"-",+O16/$O$18) -> - | R16: 0 | T16: =IF($R$18=0,"-",+R16/$R$18) -> - | U16: 0 | W16: =IF($U$18=0,"-",+U16/$U$18) -> - | X16: 0 | Z16: =IF($X$18=0,"-",+X16/$X$18) -> - | AA16: 0 | AC16: =IF($AA$18=0,"-",+AA16/$AA$18) -> - | AD16: 0 | AF16: =IF($AD$18=0,"-",+AD16/$AD$18) -> - | AG16: 0 | AI16: =IF($AG$18=0,"-",+AG16/$AG$18) -> - | AJ16: 0 | AL16: =IF($AJ$18=0,"-",+AJ16/$AJ$18) -> -
B17: Hidro Embalse | C17: ='Acumulado-Anual-HE'!AJ10/1000 -> 0.97390005 | E17: =IF($C$18=0,"-",+C17/$C$18) -> 0.0014694455 | F17: =+'Acumulado-Anual-HE'!AJ44/1000 -> 1.0169386 | H17: =IF($F$18=0,"-",+F17/$F$18) -> 0.0024146381 | I17: ='Acumulado-Anual-HE'!AJ78 -> 0 | K17: =IF($I$18=0,"-",+I17/$I$18) -> 0 | L17: ='Acumulado-Anual-HE'!AJ112 -> 0 | N17: =IF($L$18=0,"-",+L17/$L$18) -> 0 | O17: 0 | Q17: =IF($O$18=0,"-",+O17/$O$18) -> - | R17: 0 | T17: =IF($R$18=0,"-",+R17/$R$18) -> - | U17: 0 | W17: =IF($U$18=0,"-",+U17/$U$18) -> - | X17: 0 | Z17: =IF($X$18=0,"-",+X17/$X$18) -> - | AA17: 0 | AC17: =IF($AA$18=0,"-",+AA17/$AA$18) -> - | AD17: 0 | AF17: =IF($AD$18=0,"-",+AD17/$AD$18) -> - | AG17: 0 | AI17: =IF($AG$18=0,"-",+AG17/$AG$18) -> - | AJ17: 0 | AL17: =IF($AJ$18=0,"-",+AJ17/$AJ$18) -> -
B18: Total | C18: =SUM(C14:D17) -> 662.76706 | E18: =SUM(E14:E17) -> 1 | F18: =SUM(F14:G17) -> 421.1557 | H18: =SUM(H14:H17) -> 1 | I18: =SUM(I14:I17) -> 544.17827 | K18: =SUM(K14:K17) -> 1 | L18: =SUM(L14:L17) -> 333.58284 | N18: =SUM(N14:N17) -> 1 | O18: =SUM(O14:O17) -> 0 | Q18: =SUM(Q14:Q17) -> 0 | R18: =SUM(R14:R17) -> 0 | T18: =SUM(T14:T17) -> 0 | U18: =SUM(U14:U17) -> 0 | W18: =SUM(W14:W17) -> 0 | X18: =SUM(X14:X17) -> 0 | Z18: =SUM(Z14:Z17) -> 0 | AA18: =SUM(AA14:AA17) -> 0 | AC18: =SUM(AC14:AC17) -> 0 | AD18: =SUM(AD14:AD17) -> 0 | AF18: =SUM(AF14:AF17) -> 0 | AG18: =SUM(AG14:AG17) -> 0 | AI18: =SUM(AI14:AI17) -> 0 | AJ18: =SUM(AJ14:AJ17) -> 0 | AL18: =SUM(AL14:AL17) -> 0
B21: RESUMEN DE CURTAILMENTS CENTRALES EÓLICAS, SOLARES, HIDRÁULICAS DE PASADA, EMBALSES Y SERIES HÍDRICAS CORRESPONDIENTE A ABRIL 2025 (MWh)
B24: DESGLOSE DIARIO DE CURTAILMENTS DE ENERGÍA EÓLICA
B26: Central / Día | E26: 45748 | F26: =+E26+1 -> 45749 | G26: =+F26+1 -> 45750 | H26: =+G26+1 -> 45751 | I26: =+H26+1 -> 45752 | J26: =+I26+1 -> 45753 | K26: =+J26+1 -> 45754 | L26: =+K26+1 -> 45755 | M26: =+L26+1 -> 45756 | ... AH26: =+AG26+1 -> 45777 | AI26: - | AJ26: Total
B27: Total | E27: =SUM(E28:E78) -> 4559.9606 | F27: =SUM(F28:F78) -> 3733.3025 | G27: =SUM(G28:G78) -> 3422.1843 | H27: =SUM(H28:H78) -> 1223.5436 | I27: =SUM(I28:I78) -> 985.61083 | J27: =SUM(J28:J78) -> 3851.9686 | K27: =SUM(K28:K78) -> 2237.9692 | L27: =SUM(L28:L78) -> 1698.9895 | ... AI27: =SUM(AI28:AI78) -> 0 | AK27: =SUM(AK28:AK78) -> 65279.24
B28: PE-TCHAMMA | E28: ='Resumen-DiarioHorario-Eólico'!AD8 -> 154.709 | F28: ='Resumen-DiarioHorario-Eólico'!AD65 -> 65.511 | G28: ='Resumen-DiarioHorario-Eólico'!AD122 -> 29.539 | H28: ='Resumen-DiarioHorario-Eólico'!AD179 -> 5.1506667 | I28: ='Resumen-DiarioHorario-Eólico'!AD236 -> 10.182833 | J28: ='Resumen-DiarioHorario-Eólico'!AD293 -> 129.50583 | K28: ='Resumen-DiarioHorario-Eólico'!AD350 -> 40.404167 | L28: ='Resumen-DiarioHorario-Eólico'!AD407 -> 0 | M28: ='Resumen-DiarioHorario-Eólico'!AD464 -> 232.28833 | N28: ='Resumen-DiarioHorario-Eólico'!AD521 -> 127.01617 | O28: ='Resumen-DiarioHorario-Eólico'!AD578 -> 251.509 | P28: ='Resumen-DiarioHorario-Eólico'!AD635 -> 177.12733 | Q28: ='Resumen-DiarioHorario-Eólico'!AD692 -> 78.247167 | R28: ='Resumen-DiarioHorario-Eólico'!AD749 -> 25.427833 | S28: ='Resumen-DiarioHorario-Eólico'!AD806 -> 91.206333 | T28: ='Resumen-DiarioHorario-Eólico'!AD863 -> 145.596 | U28: ='Resumen-DiarioHorario-Eólico'!AD920 -> 88.414 | V28: ='Resumen-DiarioHorario-Eólico'!AD977 -> 288.72633 | W28: ='Resumen-DiarioHorario-Eólico'!AD1034 -> 186.09083 | X28: ='Resumen-DiarioHorario-Eólico'!AD1091 -> 88.182833 | Y28: ='Resumen-DiarioHorario-Eólico'!AD1148 -> 0 | Z28: ='Resumen-DiarioHorario-Eólico'!AD1205 -> 1.3083333 | AA28: ='Resumen-DiarioHorario-Eólico'!AD1262 -> 57.607167 | AB28: ='Resumen-DiarioHorario-Eólico'!AD1319 -> 81.473333 | AC28: ='Resumen-DiarioHorario-Eólico'!AD1376 -> 248.09733 | AD28: ='Resumen-DiarioHorario-Eólico'!AD1433 -> 201.00567 | AE28: ='Resumen-DiarioHorario-Eólico'!AD1490 -> 92.187833 | AF28: ='Resumen-DiarioHorario-Eólico'!AD1546 -> 40.4545 | AG28: ='Resumen-DiarioHorario-Eólico'!AD1602 -> 0 | AH28: =+'Resumen-DiarioHorario-Eólico'!AD1658 -> 18.3405 | AI28: =+'Resumen-DiarioHorario-Eólico'!AD1714 -> 0 | AK28: =SUM(E28:AI28) -> 2955.3093
B29: PE-SIERRAGORDA | E29: ='Resumen-DiarioHorario-Eólico'!AD9 -> 199.57983 | F29: ='Resumen-DiarioHorario-Eólico'!AD66 -> 182.16683 | G29: ='Resumen-DiarioHorario-Eólico'!AD123 -> 110.32467 | H29: ='Resumen-DiarioHorario-Eólico'!AD180 -> 88.4695 | I29: ='Resumen-DiarioHorario-Eólico'!AD237 -> 72.916667 | J29: ='Resumen-DiarioHorario-Eólico'!AD294 -> 140.70333 | K29: ='Resumen-DiarioHorario-Eólico'!AD351 -> 169.46983 | L29: ='Resumen-DiarioHorario-Eólico'!AD408 -> 181.03233 | M29: ='Resumen-DiarioHorario-Eólico'!AD465 -> 185.227 | N29: ='Resumen-DiarioHorario-Eólico'!AD522 -> 0 | O29: ='Resumen-DiarioHorario-Eólico'!AD579 -> 0 | P29: ='Resumen-DiarioHorario-Eólico'!AD636 -> 0 | Q29: ='Resumen-DiarioHorario-Eólico'!AD693 -> 148.03367 | R29: ='Resumen-DiarioHorario-Eólico'!AD750 -> 16.0125 | S29: ='Resumen-DiarioHorario-Eólico'!AD807 -> 40.265333 | T29: ='Resumen-DiarioHorario-Eólico'!AD864 -> 69.614833 | U29: ='Resumen-DiarioHorario-Eólico'!AD921 -> 89.960167 | V29: ='Resumen-DiarioHorario-Eólico'!AD978 -> 149.75633 | W29: ='Resumen-DiarioHorario-Eólico'!AD1035 -> 74.0005 | X29: ='Resumen-DiarioHorario-Eólico'!AD1092 -> 85.0355 | Y29: ='Resumen-DiarioHorario-Eólico'!AD1149 -> 0 | Z29: ='Resumen-DiarioHorario-Eólico'!AD1206 -> 0 | AA29: ='Resumen-DiarioHorario-Eólico'!AD1263 -> 37.6745 | AB29: ='Resumen-DiarioHorario-Eólico'!AD1320 -> 94.693333 | AC29: ='Resumen-DiarioHorario-Eólico'!AD1377 -> 174.56283 | AD29: ='Resumen-DiarioHorario-Eólico'!AD1434 -> 143.553 | AE29: ='Resumen-DiarioHorario-Eólico'!AD1491 -> 122.59167 | AF29: ='Resumen-DiarioHorario-Eólico'!AD1547 -> 27.156833 | AG29: ='Resumen-DiarioHorario-Eólico'!AD1603 -> 0 | AH29: =+'Resumen-DiarioHorario-Eólico'!AD1659 -> 6.8088333 | AI29: =+'Resumen-DiarioHorario-Eólico'!AD1715 -> 0 | AK29: =SUM(E29:AI29) -> 2609.6098
B30: PE-VALLEDELOSVIENTOS | E30: ='Resumen-DiarioHorario-Eólico'!AD10 -> 207.679 | F30: ='Resumen-DiarioHorario-Eólico'!AD67 -> 162.5635 | G30: ='Resumen-DiarioHorario-Eólico'!AD124 -> 84.127833 | H30: ='Resumen-DiarioHorario-Eólico'!AD181 -> 131.09683 | I30: ='Resumen-DiarioHorario-Eólico'!AD238 -> 121.8695 | J30: ='Resumen-DiarioHorario-Eólico'!AD295 -> 143.14733 | K30: ='Resumen-DiarioHorario-Eólico'!AD352 -> 229.332 | L30: ='Resumen-DiarioHorario-Eólico'!AD409 -> 188.31883 | M30: ='Resumen-DiarioHorario-Eólico'!AD466 -> 118.33533 | N30: ='Resumen-DiarioHorario-Eólico'!AD523 -> 82.848833 | O30: ='Resumen-DiarioHorario-Eólico'!AD580 -> 241.37833 | P30: ='Resumen-DiarioHorario-Eólico'!AD637 -> 129.97383 | Q30: ='Resumen-DiarioHorario-Eólico'!AD694 -> 160.734 | R30: ='Resumen-DiarioHorario-Eólico'!AD751 -> 78.968 | S30: ='Resumen-DiarioHorario-Eólico'!AD808 -> 51.945833 | T30: ='Resumen-DiarioHorario-Eólico'!AD865 -> 88.692167 | U30: ='Resumen-DiarioHorario-Eólico'!AD922 -> 46.133833 | V30: ='Resumen-DiarioHorario-Eólico'!AD979 -> 150.45767 | W30: ='Resumen-DiarioHorario-Eólico'!AD1036 -> 127.767 | X30: ='Resumen-DiarioHorario-Eólico'!AD1093 -> 122.39867 | Y30: ='Resumen-DiarioHorario-Eólico'!AD1150 -> 0 | Z30: ='Resumen-DiarioHorario-Eólico'!AD1207 -> 3.2685 | AA30: ='Resumen-DiarioHorario-Eólico'!AD1264 -> 39.588167 | AB30: ='Resumen-DiarioHorario-Eólico'!AD1321 -> 80.028833 | AC30: ='Resumen-DiarioHorario-Eólico'!AD1378 -> 220.98017 | AD30: ='Resumen-DiarioHorario-Eólico'!AD1435 -> 256.277 | AE30: ='Resumen-DiarioHorario-Eólico'!AD1492 -> 172.116 | AF30: ='Resumen-DiarioHorario-Eólico'!AD1548 -> 26.581 | AG30: ='Resumen-DiarioHorario-Eólico'!AD1604 -> 58.462667 | AH30: =+'Resumen-DiarioHorario-Eólico'!AD1660 -> 53.078667 | AI30: =+'Resumen-DiarioHorario-Eólico'!AD1716 -> 0 | AK30: =SUM(E30:AI30) -> 3578.1493
B31: PE-CERROTIGRE | E31: ='Resumen-DiarioHorario-Eólico'!AD11 -> 553.56783 | F31: ='Resumen-DiarioHorario-Eólico'!AD68 -> 542.1 | G31: ='Resumen-DiarioHorario-Eólico'!AD125 -> 576.663 | H31: ='Resumen-DiarioHorario-Eólico'!AD182 -> 325.51667 | I31: ='Resumen-DiarioHorario-Eólico'!AD239 -> 244.25233 | J31: ='Resumen-DiarioHorario-Eólico'!AD296 -> 485.0595 | K31: ='Resumen-DiarioHorario-Eólico'!AD353 -> 527.09333 | L31: ='Resumen-DiarioHorario-Eólico'!AD410 -> 545.30933 | M31: ='Resumen-DiarioHorario-Eólico'!AD467 -> 0 | N31: ='Resumen-DiarioHorario-Eólico'!AD524 -> 169.753 | O31: ='Resumen-DiarioHorario-Eólico'!AD581 -> 392.0175 | P31: ='Resumen-DiarioHorario-Eólico'!AD638 -> 379.1335 | Q31: ='Resumen-DiarioHorario-Eólico'!AD695 -> 498.4 | R31: ='Resumen-DiarioHorario-Eólico'!AD752 -> 61.0855 | S31: ='Resumen-DiarioHorario-Eólico'!AD809 -> 108.008 | T31: ='Resumen-DiarioHorario-Eólico'!AD866 -> 186.91833 | U31: ='Resumen-DiarioHorario-Eólico'!AD923 -> 278.46783 | V31: ='Resumen-DiarioHorario-Eólico'!AD980 -> 458.18033 | W31: ='Resumen-DiarioHorario-Eólico'!AD1037 -> 438.07117 | X31: ='Resumen-DiarioHorario-Eólico'!AD1094 -> 183.253 | Y31: ='Resumen-DiarioHorario-Eólico'!AD1151 -> 0 | Z31: ='Resumen-DiarioHorario-Eólico'!AD1208 -> 0.132 | AA31: ='Resumen-DiarioHorario-Eólico'!AD1265 -> 11.109 | AB31: ='Resumen-DiarioHorario-Eólico'!AD1322 -> 269.75717 | AC31: ='Resumen-DiarioHorario-Eólico'!AD1379 -> 488.40817 | AD31: ='Resumen-DiarioHorario-Eólico'!AD1436 -> 568.36683 | AE31: ='Resumen-DiarioHorario-Eólico'!AD1493 -> 597.79783 | AF31: ='Resumen-DiarioHorario-Eólico'!AD1549 -> 58.360333 | AG31: ='Resumen-DiarioHorario-Eólico'!AD1605 -> 0 | AH31: =+'Resumen-DiarioHorario-Eólico'!AD1661 -> 19.087 | AI31: =+'Resumen-DiarioHorario-Eólico'!AD1717 -> 0 | AK31: =SUM(E31:AI31) -> 8965.8685
B32: PE-CALAMA | E32: ='Resumen-DiarioHorario-Eólico'!AD12 -> 252.9735 | F32: ='Resumen-DiarioHorario-Eólico'!AD69 -> 245.32917 | G32: ='Resumen-DiarioHorario-Eólico'!AD126 -> 197.98467 | H32: ='Resumen-DiarioHorario-Eólico'!AD183 -> 261.64433 | I32: ='Resumen-DiarioHorario-Eólico'!AD240 -> 79.299 | J32: ='Resumen-DiarioHorario-Eólico'!AD297 -> 85.574167 | K32: ='Resumen-DiarioHorario-Eólico'!AD354 -> 296.1755 | L32: ='Resumen-DiarioHorario-Eólico'!AD411 -> 263.242 | M32: ='Resumen-DiarioHorario-Eólico'!AD468 -> 217.39583 | N32: ='Resumen-DiarioHorario-Eólico'!AD525 -> 209.601 | O32: ='Resumen-DiarioHorario-Eólico'!AD582 -> 390.88883 | P32: ='Resumen-DiarioHorario-Eólico'!AD639 -> 252.70733 | Q32: ='Resumen-DiarioHorario-Eólico'!AD696 -> 223.22817 | R32: ='Resumen-DiarioHorario-Eólico'!AD753 -> 31.9985 | S32: ='Resumen-DiarioHorario-Eólico'!AD810 -> 90.413 | T32: ='Resumen-DiarioHorario-Eólico'!AD867 -> 232.27417 | U32: ='Resumen-DiarioHorario-Eólico'!AD924 -> 160.32483 | V32: ='Resumen-DiarioHorario-Eólico'!AD981 -> 253.84567 | W32: ='Resumen-DiarioHorario-Eólico'!AD1038 -> 314.4285 | X32: ='Resumen-DiarioHorario-Eólico'!AD1095 -> 195.8715 | Y32: ='Resumen-DiarioHorario-Eólico'!AD1152 -> 0 | Z32: ='Resumen-DiarioHorario-Eólico'!AD1209 -> 9.4925 | AA32: ='Resumen-DiarioHorario-Eólico'!AD1266 -> 44.401333 | AB32: ='Resumen-DiarioHorario-Eólico'!AD1323 -> 333.2295 | AC32: ='Resumen-DiarioHorario-Eólico'!AD1380 -> 388.45517 | AD32: ='Resumen-DiarioHorario-Eólico'!AD1437 -> 332.808 | AE32: ='Resumen-DiarioHorario-Eólico'!AD1494 -> 264.59083 | AF32: ='Resumen-DiarioHorario-Eólico'!AD1550 -> 71.529 | AG32: ='Resumen-DiarioHorario-Eólico'!AD1606 -> 0 | AH32: =+'Resumen-DiarioHorario-Eólico'!AD1662 -> 12.230167 | AI32: =+'Resumen-DiarioHorario-Eólico'!AD1718 -> 0 | AK32: =SUM(E32:AI32) -> 5711.9362
B33: PE-TALTAL | E33: ='Resumen-DiarioHorario-Eólico'!AD13 -> 65.283667 | F33: ='Resumen-DiarioHorario-Eólico'!AD70 -> 51.455167 | G33: ='Resumen-DiarioHorario-Eólico'!AD127 -> 50.229333 | H33: ='Resumen-DiarioHorario-Eólico'!AD184 -> 37.755833 | I33: ='Resumen-DiarioHorario-Eólico'!AD241 -> 35.107333 | J33: ='Resumen-DiarioHorario-Eólico'!AD298 -> 91.791 | K33: ='Resumen-DiarioHorario-Eólico'!AD355 -> 168.28583 | L33: ='Resumen-DiarioHorario-Eólico'!AD412 -> 51.683333 | M33: ='Resumen-DiarioHorario-Eólico'!AD469 -> 213.91783 | N33: ='Resumen-DiarioHorario-Eólico'!AD526 -> 1.859 | O33: ='Resumen-DiarioHorario-Eólico'!AD583 -> 83.989667 | P33: ='Resumen-DiarioHorario-Eólico'!AD640 -> 272.05867 | Q33: ='Resumen-DiarioHorario-Eólico'!AD697 -> 105.29367 | R33: ='Resumen-DiarioHorario-Eólico'!AD754 -> 50.968333 | S33: ='Resumen-DiarioHorario-Eólico'!AD811 -> 118.0755 | T33: ='Resumen-DiarioHorario-Eólico'!AD868 -> 60.319667 | U33: ='Resumen-DiarioHorario-Eólico'!AD925 -> 61.954 | V33: ='Resumen-DiarioHorario-Eólico'!AD982 -> 123.61 | W33: ='Resumen-DiarioHorario-Eólico'!AD1039 -> 307.665 | X33: ='Resumen-DiarioHorario-Eólico'!AD1096 -> 284.57367 | Y33: ='Resumen-DiarioHorario-Eólico'!AD1153 -> 0 | Z33: ='Resumen-DiarioHorario-Eólico'!AD1210 -> 0.0093333333 | AA33: ='Resumen-DiarioHorario-Eólico'!AD1267 -> 10.0615 | AB33: ='Resumen-DiarioHorario-Eólico'!AD1324 -> 40.676833 | AC33: ='Resumen-DiarioHorario-Eólico'!AD1381 -> 29.757667 | AD33: ='Resumen-DiarioHorario-Eólico'!AD1438 -> 54.293167 | AE33: ='Resumen-DiarioHorario-Eólico'!AD1495 -> 71.565 | AF33: ='Resumen-DiarioHorario-Eólico'!AD1551 -> 4.424 | AG33: ='Resumen-DiarioHorario-Eólico'!AD1607 -> 0 | AH33: =+'Resumen-DiarioHorario-Eólico'!AD1663 -> 19.725333 | AI33: =+'Resumen-DiarioHorario-Eólico'!AD1719 -> 0 | AK33: =SUM(E33:AI33) -> 2466.3893
B34: PE-SARCO | E34: ='Resumen-DiarioHorario-Eólico'!AD14 -> 136.67017 | F34: ='Resumen-DiarioHorario-Eólico'!AD71 -> 192.71367 | G34: ='Resumen-DiarioHorario-Eólico'!AD128 -> 35.123333 | H34: ='Resumen-DiarioHorario-Eólico'!AD185 -> 4.053 | I34: ='Resumen-DiarioHorario-Eólico'!AD242 -> 21.105833 | J34: ='Resumen-DiarioHorario-Eólico'!AD299 -> 314.52817 | K34: ='Resumen-DiarioHorario-Eólico'!AD356 -> 0 | L34: ='Resumen-DiarioHorario-Eólico'!AD413 -> 38.978 | M34: ='Resumen-DiarioHorario-Eólico'!AD470 -> 26.714 | N34: ='Resumen-DiarioHorario-Eólico'!AD527 -> 83.878333 | O34: ='Resumen-DiarioHorario-Eólico'!AD584 -> 381.09083 | P34: ='Resumen-DiarioHorario-Eólico'!AD641 -> 61.938833 | Q34: ='Resumen-DiarioHorario-Eólico'!AD698 -> 17.343 | R34: ='Resumen-DiarioHorario-Eólico'!AD755 -> 12.581667 | S34: ='Resumen-DiarioHorario-Eólico'!AD812 -> 16.970333 | T34: ='Resumen-DiarioHorario-Eólico'!AD869 -> 125.5535 | U34: ='Resumen-DiarioHorario-Eólico'!AD926 -> 100.3135 | V34: ='Resumen-DiarioHorario-Eólico'!AD983 -> 17.692333 | W34: ='Resumen-DiarioHorario-Eólico'!AD1040 -> 40.160167 | X34: ='Resumen-DiarioHorario-Eólico'!AD1097 -> 32.224167 | Y34: ='Resumen-DiarioHorario-Eólico'!AD1154 -> 0 | Z34: ='Resumen-DiarioHorario-Eólico'!AD1211 -> 0.43916667 | AA34: ='Resumen-DiarioHorario-Eólico'!AD1268 -> 0 | AB34: ='Resumen-DiarioHorario-Eólico'!AD1325 -> 149.977 | AC34: ='Resumen-DiarioHorario-Eólico'!AD1382 -> 587.8945 | AD34: ='Resumen-DiarioHorario-Eólico'!AD1439 -> 315.75233 | AE34: ='Resumen-DiarioHorario-Eólico'!AD1496 -> 125.05583 | AF34: ='Resumen-DiarioHorario-Eólico'!AD1552 -> 4.9506667 | AG34: ='Resumen-DiarioHorario-Eólico'!AD1608 -> 0 | AH34: =+'Resumen-DiarioHorario-Eólico'!AD1664 -> 0.937 | AI34: =+'Resumen-DiarioHorario-Eólico'!AD1720 -> 0 | AK34: =SUM(E34:AI34) -> 2844.6393
B35: PE-CABOLEONES-1 | E35: ='Resumen-DiarioHorario-Eólico'!AD15 -> 92.704667 | F35: ='Resumen-DiarioHorario-Eólico'!AD72 -> 121.3995 | G35: ='Resumen-DiarioHorario-Eólico'!AD129 -> 44.571167 | H35: ='Resumen-DiarioHorario-Eólico'!AD186 -> 2.651 | I35: ='Resumen-DiarioHorario-Eólico'!AD243 -> 3.2465 | J35: ='Resumen-DiarioHorario-Eólico'!AD300 -> 7.1403333 | K35: ='Resumen-DiarioHorario-Eólico'!AD357 -> 18.4255 | L35: ='Resumen-DiarioHorario-Eólico'!AD414 -> 38.636333 | M35: ='Resumen-DiarioHorario-Eólico'!AD471 -> 36.587667 | N35: ='Resumen-DiarioHorario-Eólico'!AD528 -> 41.912667 | O35: ='Resumen-DiarioHorario-Eólico'!AD585 -> 184.264 | P35: ='Resumen-DiarioHorario-Eólico'!AD642 -> 42.050333 | Q35: ='Resumen-DiarioHorario-Eólico'!AD699 -> 32.618167 | R35: ='Resumen-DiarioHorario-Eólico'!AD756 -> 2.5513333 | S35: ='Resumen-DiarioHorario-Eólico'!AD813 -> 36.027167 | T35: ='Resumen-DiarioHorario-Eólico'!AD870 -> 21.687667 | U35: ='Resumen-DiarioHorario-Eólico'!AD927 -> 0 | V35: ='Resumen-DiarioHorario-Eólico'!AD984 -> 10.332167 | W35: ='Resumen-DiarioHorario-Eólico'!AD1041 -> 37.102167 | X35: ='Resumen-DiarioHorario-Eólico'!AD1098 -> 20.088833 | Y35: ='Resumen-DiarioHorario-Eólico'!AD1155 -> 0 | Z35: ='Resumen-DiarioHorario-Eólico'!AD1212 -> 0.54566667 | AA35: ='Resumen-DiarioHorario-Eólico'!AD1269 -> 0.0043333333 | AB35: ='Resumen-DiarioHorario-Eólico'!AD1326 -> 8.1135 | AC35: ='Resumen-DiarioHorario-Eólico'!AD1383 -> 402.56267 | AD35: ='Resumen-DiarioHorario-Eólico'!AD1440 -> 177.55883 | AE35: ='Resumen-DiarioHorario-Eólico'!AD1497 -> 93.2745 | AF35: ='Resumen-DiarioHorario-Eólico'!AD1553 -> 0 | AG35: ='Resumen-DiarioHorario-Eólico'!AD1609 -> 0 | AH35: =+'Resumen-DiarioHorario-Eólico'!AD1665 -> 0 | AI35: =+'Resumen-DiarioHorario-Eólico'!AD1721 -> 0 | AK35: =SUM(E35:AI35) -> 1476.0567
B36: PE-CABOLEONES-2 | E36: ='Resumen-DiarioHorario-Eólico'!AD16 -> 99.691833 | F36: ='Resumen-DiarioHorario-Eólico'!AD73 -> 102.13917 | G36: ='Resumen-DiarioHorario-Eólico'!AD130 -> 44.895 | H36: ='Resumen-DiarioHorario-Eólico'!AD187 -> 3.835 | I36: ='Resumen-DiarioHorario-Eólico'!AD244 -> 2.786 | J36: ='Resumen-DiarioHorario-Eólico'!AD301 -> 54.807667 | K36: ='Resumen-DiarioHorario-Eólico'!AD358 -> 30.829833 | L36: ='Resumen-DiarioHorario-Eólico'!AD415 -> 61.533 | M36: ='Resumen-DiarioHorario-Eólico'!AD472 -> 68.995333 | N36: ='Resumen-DiarioHorario-Eólico'!AD529 -> 35.283333 | O36: ='Resumen-DiarioHorario-Eólico'!AD586 -> 54.135 | P36: ='Resumen-DiarioHorario-Eólico'!AD643 -> 38.7385 | Q36: ='Resumen-DiarioHorario-Eólico'!AD700 -> 31.099667 | R36: ='Resumen-DiarioHorario-Eólico'!AD757 -> 2.3291667 | S36: ='Resumen-DiarioHorario-Eólico'!AD814 -> 8.999 | T36: ='Resumen-DiarioHorario-Eólico'!AD871 -> 7.6678333 | U36: ='Resumen-DiarioHorario-Eólico'!AD928 -> 1.967 | V36: ='Resumen-DiarioHorario-Eólico'!AD985 -> 4.8336667 | W36: ='Resumen-DiarioHorario-Eólico'!AD1042 -> 48.785667 | X36: ='Resumen-DiarioHorario-Eólico'!AD1099 -> 23.845333 | Y36: ='Resumen-DiarioHorario-Eólico'!AD1156 -> 0 | Z36: ='Resumen-DiarioHorario-Eólico'!AD1213 -> 1.1518333 | AA36: ='Resumen-DiarioHorario-Eólico'!AD1270 -> 0 | AB36: ='Resumen-DiarioHorario-Eólico'!AD1327 -> 17.747667 | AC36: ='Resumen-DiarioHorario-Eólico'!AD1384 -> 179.34217 | AD36: ='Resumen-DiarioHorario-Eólico'!AD1441 -> 89.684333 | AE36: ='Resumen-DiarioHorario-Eólico'!AD1498 -> 55.668167 | AF36: ='Resumen-DiarioHorario-Eólico'!AD1554 -> 0 | AG36: ='Resumen-DiarioHorario-Eólico'!AD1610 -> 0 | AH36: =+'Resumen-DiarioHorario-Eólico'!AD1666 -> 0 | AI36: =+'Resumen-DiarioHorario-Eólico'!AD1722 -> 0 | AK36: =SUM(E36:AI36) -> 1070.7912
B37: PE-CABOLEONES-3 | E37: ='Resumen-DiarioHorario-Eólico'!AD17 -> 178.76633 | F37: ='Resumen-DiarioHorario-Eólico'!AD74 -> 187.3765 | G37: ='Resumen-DiarioHorario-Eólico'!AD131 -> 31.745833 | H37: ='Resumen-DiarioHorario-Eólico'!AD188 -> 2.5476667 | I37: ='Resumen-DiarioHorario-Eólico'!AD245 -> 6.0311667 | J37: ='Resumen-DiarioHorario-Eólico'!AD302 -> 86.807833 | K37: ='Resumen-DiarioHorario-Eólico'!AD359 -> 1.577 | L37: ='Resumen-DiarioHorario-Eólico'!AD416 -> 41.729333 | M37: ='Resumen-DiarioHorario-Eólico'!AD473 -> 37.2905 | N37: ='Resumen-DiarioHorario-Eólico'!AD530 -> 129.174 | O37: ='Resumen-DiarioHorario-Eólico'!AD587 -> 145.77683 | P37: ='Resumen-DiarioHorario-Eólico'!AD644 -> 84.874167 | Q37: ='Resumen-DiarioHorario-Eólico'!AD701 -> 34.894833 | R37: ='Resumen-DiarioHorario-Eólico'!AD758 -> 6.9266667 | S37: ='Resumen-DiarioHorario-Eólico'!AD815 -> 46.605333 | T37: ='Resumen-DiarioHorario-Eólico'!AD872 -> 22.388333 | U37: ='Resumen-DiarioHorario-Eólico'!AD929 -> 16.509333 | V37: ='Resumen-DiarioHorario-Eólico'!AD986 -> 22.4355 | W37: ='Resumen-DiarioHorario-Eólico'!AD1043 -> 20.649833 | X37: ='Resumen-DiarioHorario-Eólico'!AD1100 -> 31.441 | Y37: ='Resumen-DiarioHorario-Eólico'!AD1157 -> 0 | Z37: ='Resumen-DiarioHorario-Eólico'!AD1214 -> 1.33 | AA37: ='Resumen-DiarioHorario-Eólico'!AD1271 -> 6.3558333 | AB37: ='Resumen-DiarioHorario-Eólico'!AD1328 -> 0 | AC37: ='Resumen-DiarioHorario-Eólico'!AD1385 -> 290.13217 | AD37: ='Resumen-DiarioHorario-Eólico'!AD1442 -> 95.805333 | AE37: ='Resumen-DiarioHorario-Eólico'!AD1499 -> 150.29133 | AF37: ='Resumen-DiarioHorario-Eólico'!AD1555 -> 6.7233333 | AG37: ='Resumen-DiarioHorario-Eólico'!AD1611 -> 0 | AH37: =+'Resumen-DiarioHorario-Eólico'!AD1667 -> 0.67033333 | AI37: =+'Resumen-DiarioHorario-Eólico'!AD1723 -> 0 | AK37: =SUM(E37:AI37) -> 1686.8563
B38: PE-SANJUAN | E38: ='Resumen-DiarioHorario-Eólico'!AD18 -> 64.056 | F38: ='Resumen-DiarioHorario-Eólico'!AD75 -> 209.57917 | G38: ='Resumen-DiarioHorario-Eólico'!AD132 -> 5.512 | H38: ='Resumen-DiarioHorario-Eólico'!AD189 -> 5.6538333 | I38: ='Resumen-DiarioHorario-Eólico'!AD246 -> 41.632833 | J38: ='Resumen-DiarioHorario-Eólico'!AD303 -> 156.7615 | K38: ='Resumen-DiarioHorario-Eólico'!AD360 -> 26.170833 | L38: ='Resumen-DiarioHorario-Eólico'!AD417 -> 18.983333 | M38: ='Resumen-DiarioHorario-Eólico'!AD474 -> 0.222 | N38: ='Resumen-DiarioHorario-Eólico'!AD531 -> 47.200167 | O38: ='Resumen-DiarioHorario-Eólico'!AD588 -> 0 | P38: ='Resumen-DiarioHorario-Eólico'!AD645 -> 83.1685 | Q38: ='Resumen-DiarioHorario-Eólico'!AD702 -> 0.52633333 | R38: ='Resumen-DiarioHorario-Eólico'!AD759 -> 8.8158333 | S38: ='Resumen-DiarioHorario-Eólico'!AD816 -> 2.0835 | T38: ='Resumen-DiarioHorario-Eólico'!AD873 -> 19.1795 | U38: ='Resumen-DiarioHorario-Eólico'!AD930 -> 21.141667 | V38: ='Resumen-DiarioHorario-Eólico'!AD987 -> 38.271167 | W38: ='Resumen-DiarioHorario-Eólico'!AD1044 -> 43.6865 | X38: ='Resumen-DiarioHorario-Eólico'!AD1101 -> 4.3631667 | Y38: ='Resumen-DiarioHorario-Eólico'!AD1158 -> 0 | Z38: ='Resumen-DiarioHorario-Eólico'!AD1215 -> 0.0011666667 | AA38: ='Resumen-DiarioHorario-Eólico'!AD1272 -> 0 | AB38: ='Resumen-DiarioHorario-Eólico'!AD1329 -> 63.464 | AC38: ='Resumen-DiarioHorario-Eólico'!AD1386 -> 561.784 | AD38: ='Resumen-DiarioHorario-Eólico'!AD1443 -> 253.337 | AE38: ='Resumen-DiarioHorario-Eólico'!AD1500 -> 184.45717 | AF38: ='Resumen-DiarioHorario-Eólico'!AD1556 -> 0 | AG38: ='Resumen-DiarioHorario-Eólico'!AD1612 -> 0 | AH38: =+'Resumen-DiarioHorario-Eólico'!AD1668 -> 4.5465 | AI38: =+'Resumen-DiarioHorario-Eólico'!AD1724 -> 0 | AK38: =SUM(E38:AI38) -> 1864.5977
B39: PE-PUNTACOLORADA | E39: ='Resumen-DiarioHorario-Eólico'!AD19 -> 0 | F39: ='Resumen-DiarioHorario-Eólico'!AD76 -> 0 | G39: ='Resumen-DiarioHorario-Eólico'!AD133 -> 0 | H39: ='Resumen-DiarioHorario-Eólico'!AD190 -> 0 | I39: ='Resumen-DiarioHorario-Eólico'!AD247 -> 0 | J39: ='Resumen-DiarioHorario-Eólico'!AD304 -> 0 | K39: ='Resumen-DiarioHorario-Eólico'!AD361 -> 0 | L39: ='Resumen-DiarioHorario-Eólico'!AD418 -> 0 | M39: ='Resumen-DiarioHorario-Eólico'!AD475 -> 0 | N39: ='Resumen-DiarioHorario-Eólico'!AD532 -> 0 | O39: ='Resumen-DiarioHorario-Eólico'!AD589 -> 0 | P39: ='Resumen-DiarioHorario-Eólico'!AD646 -> 0 | Q39: ='Resumen-DiarioHorario-Eólico'!AD703 -> 0 | R39: ='Resumen-DiarioHorario-Eólico'!AD760 -> 0 | S39: ='Resumen-DiarioHorario-Eólico'!AD817 -> 0 | T39: ='Resumen-DiarioHorario-Eólico'!AD874 -> 0 | U39: ='Resumen-DiarioHorario-Eólico'!AD931 -> 0 | V39: ='Resumen-DiarioHorario-Eólico'!AD988 -> 0 | W39: ='Resumen-DiarioHorario-Eólico'!AD1045 -> 0 | X39: ='Resumen-DiarioHorario-Eólico'!AD1102 -> 0 | Y39: ='Resumen-DiarioHorario-Eólico'!AD1159 -> 0 | Z39: ='Resumen-DiarioHorario-Eólico'!AD1216 -> 0 | AA39: ='Resumen-DiarioHorario-Eólico'!AD1273 -> 0 | AB39: ='Resumen-DiarioHorario-Eólico'!AD1330 -> 0 | AC39: ='Resumen-DiarioHorario-Eólico'!AD1387 -> 0 | AD39: ='Resumen-DiarioHorario-Eólico'!AD1444 -> 0 | AE39: ='Resumen-DiarioHorario-Eólico'!AD1501 -> 0 | AF39: ='Resumen-DiarioHorario-Eólico'!AD1557 -> 0 | AG39: ='Resumen-DiarioHorario-Eólico'!AD1613 -> 0 | AH39: =+'Resumen-DiarioHorario-Eólico'!AD1669 -> 0 | AI39: =+'Resumen-DiarioHorario-Eólico'!AD1725 -> 0 | AK39: =SUM(E39:AI39) -> 0
... B72: PE-ATACAMA | E72: ='Resumen-DiarioHorario-Eólico'!AD52 -> 36.717333 | F72: ='Resumen-DiarioHorario-Eólico'!AD109 -> 460.93433 | G72: ='Resumen-DiarioHorario-Eólico'!AD166 -> 31.017167 | H72: ='Resumen-DiarioHorario-Eólico'!AD223 -> 40.8785 | I72: ='Resumen-DiarioHorario-Eólico'!AD280 -> 75.484 | J72: ='Resumen-DiarioHorario-Eólico'!AD337 -> 562.1945 | K72: ='Resumen-DiarioHorario-Eólico'!AD394 -> 356.09317 | L72: ='Resumen-DiarioHorario-Eólico'!AD451 -> 70.007167 | M72: ='Resumen-DiarioHorario-Eólico'!AD508 -> 4.599 | N72: ='Resumen-DiarioHorario-Eólico'!AD565 -> 542.719 | O72: ='Resumen-DiarioHorario-Eólico'!AD622 -> 522.13583 | P72: ='Resumen-DiarioHorario-Eólico'!AD679 -> 273.69133 | Q72: ='Resumen-DiarioHorario-Eólico'!AD736 -> 279.0275 | R72: ='Resumen-DiarioHorario-Eólico'!AD793 -> 102.03467 | S72: ='Resumen-DiarioHorario-Eólico'!AD850 -> 81.052 | T72: ='Resumen-DiarioHorario-Eólico'!AD907 -> 132.6205 | U72: ='Resumen-DiarioHorario-Eólico'!AD964 -> 198.53117 | V72: ='Resumen-DiarioHorario-Eólico'!AD1021 -> 22.444167 | W72: ='Resumen-DiarioHorario-Eólico'!AD1078 -> 1.834 | X72: ='Resumen-DiarioHorario-Eólico'!AD1135 -> 162.638 | Y72: ='Resumen-DiarioHorario-Eólico'!AD1192 -> 0 | Z72: ='Resumen-DiarioHorario-Eólico'!AD1249 -> 0.206 | AA72: ='Resumen-DiarioHorario-Eólico'!AD1306 -> 36.8085 | AB72: ='Resumen-DiarioHorario-Eólico'!AD1363 -> 319.393 | AC72: ='Resumen-DiarioHorario-Eólico'!AD1420 -> 722.85683 | AD72: ='Resumen-DiarioHorario-Eólico'!AD1477 -> 692.131 | AE72: ='Resumen-DiarioHorario-Eólico'!AD1534 -> 256.03367 | AF72: ='Resumen-DiarioHorario-Eólico'!AD1590 -> 22.579167 | AG72: ='Resumen-DiarioHorario-Eólico'!AD1646 -> 0 | AH72: =+'Resumen-DiarioHorario-Eólico'!AD1702 -> 2.6008333 | AI72: =+'Resumen-DiarioHorario-Eólico'!AD1758 -> 0 | AK72: =SUM(E72:AI72) -> 6009.2623
B73: PE-LACABANA | D73: † | E73: ='Resumen-DiarioHorario-Eólico'!AD53 -> 204.39667 | F73: ='Resumen-DiarioHorario-Eólico'!AD110 -> 0.27083333 | G73: ='Resumen-DiarioHorario-Eólico'!AD167 -> 131.84167 | H73: ='Resumen-DiarioHorario-Eólico'!AD224 -> 0 | I73: ='Resumen-DiarioHorario-Eólico'!AD281 -> 0 | J73: ='Resumen-DiarioHorario-Eólico'!AD338 -> 0 | K73: ='Resumen-DiarioHorario-Eólico'!AD395 -> 0 | L73: ='Resumen-DiarioHorario-Eólico'!AD452 -> 0 | M73: ='Resumen-DiarioHorario-Eólico'!AD509 -> 0 | N73: ='Resumen-DiarioHorario-Eólico'!AD566 -> 0 | O73: ='Resumen-DiarioHorario-Eólico'!AD623 -> 0 | P73: ='Resumen-DiarioHorario-Eólico'!AD680 -> 0 | Q73: ='Resumen-DiarioHorario-Eólico'!AD737 -> 0 | R73: ='Resumen-DiarioHorario-Eólico'!AD794 -> 0 | S73: ='Resumen-DiarioHorario-Eólico'!AD851 -> 0 | T73: ='Resumen-DiarioHorario-Eólico'!AD908 -> 0 | U73: ='Resumen-DiarioHorario-Eólico'!AD965 -> 0 | V73: ='Resumen-DiarioHorario-Eólico'!AD1022 -> 38.936833 | W73: ='Resumen-DiarioHorario-Eólico'!AD1079 -> 8.0235 | X73: ='Resumen-DiarioHorario-Eólico'!AD1136 -> 0 | Y73: ='Resumen-DiarioHorario-Eólico'!AD1193 -> 0 | Z73: ='Resumen-DiarioHorario-Eólico'!AD1250 -> 11.479167 | AA73: ='Resumen-DiarioHorario-Eólico'!AD1307 -> 0 | AB73: ='Resumen-DiarioHorario-Eólico'!AD1364 -> 0 | AC73: ='Resumen-DiarioHorario-Eólico'!AD1421 -> 0 | AD73: ='Resumen-DiarioHorario-Eólico'!AD1478 -> 0 | AE73: ='Resumen-DiarioHorario-Eólico'!AD1535 -> 0 | AF73: ='Resumen-DiarioHorario-Eólico'!AD1591 -> 0 | AG73: ='Resumen-DiarioHorario-Eólico'!AD1647 -> 0 | AH73: =+'Resumen-DiarioHorario-Eólico'!AD1703 -> 0 | AI73: =+'Resumen-DiarioHorario-Eólico'!AD1759 -> 0 | AK73: =SUM(E73:AI73) -> 394.94867
B74: PE-SANMATIAS | E74: ='Resumen-DiarioHorario-Eólico'!AD54 -> 104.44933 | F74: ='Resumen-DiarioHorario-Eólico'!AD111 -> 6.0428333 | G74: ='Resumen-DiarioHorario-Eólico'!AD168 -> 53.842 | H74: ='Resumen-DiarioHorario-Eólico'!AD225 -> 0.056333333 | I74: ='Resumen-DiarioHorario-Eólico'!AD282 -> 0 | J74: ='Resumen-DiarioHorario-Eólico'!AD339 -> 14.063167 | K74: ='Resumen-DiarioHorario-Eólico'!AD396 -> 22.918833 | L74: ='Resumen-DiarioHorario-Eólico'!AD453 -> 0 | M74: ='Resumen-DiarioHorario-Eólico'!AD510 -> 0 | N74: ='Resumen-DiarioHorario-Eólico'!AD567 -> 143.18067 | O74: ='Resumen-DiarioHorario-Eólico'!AD624 -> 0 | P74: ='Resumen-DiarioHorario-Eólico'!AD681 -> 0 | Q74: ='Resumen-DiarioHorario-Eólico'!AD738 -> 3.192 | R74: ='Resumen-DiarioHorario-Eólico'!AD795 -> 0.28016667 | S74: ='Resumen-DiarioHorario-Eólico'!AD852 -> 0.33933333 | T74: ='Resumen-DiarioHorario-Eólico'!AD909 -> 0.17616667 | U74: ='Resumen-DiarioHorario-Eólico'!AD966 -> 0 | V74: ='Resumen-DiarioHorario-Eólico'!AD1023 -> 63.430167 | W74: ='Resumen-DiarioHorario-Eólico'!AD1080 -> 25.7955 | X74: ='Resumen-DiarioHorario-Eólico'!AD1137 -> 0.080666667 | Y74: ='Resumen-DiarioHorario-Eólico'!AD1194 -> 0 | Z74: ='Resumen-DiarioHorario-Eólico'!AD1251 -> 0 | AA74: ='Resumen-DiarioHorario-Eólico'!AD1308 -> 0.48833333 | AB74: ='Resumen-DiarioHorario-Eólico'!AD1365 -> 84.218667 | AC74: ='Resumen-DiarioHorario-Eólico'!AD1422 -> 89.7575 | AD74: ='Resumen-DiarioHorario-Eólico'!AD1479 -> 182.23783 | AE74: ='Resumen-DiarioHorario-Eólico'!AD1536 -> 140.70167 | AF74: ='Resumen-DiarioHorario-Eólico'!AD1592 -> 19.255167 | AG74: ='Resumen-DiarioHorario-Eólico'!AD1648 -> 0 | AH74: =+'Resumen-DiarioHorario-Eólico'!AD1704 -> 1.887 | AI74: =+'Resumen-DiarioHorario-Eólico'!AD1760 -> 0 | AK74: =SUM(E74:AI74) -> 956.39333
B75: PE-CARDONAL | E75: ='Resumen-DiarioHorario-Eólico'!AD55 -> 9.9089 | F75: ='Resumen-DiarioHorario-Eólico'!AD112 -> 8.1089233 | G75: ='Resumen-DiarioHorario-Eólico'!AD169 -> 0.009195 | H75: ='Resumen-DiarioHorario-Eólico'!AD226 -> 0.0175 | I75: ='Resumen-DiarioHorario-Eólico'!AD283 -> 0 | J75: ='Resumen-DiarioHorario-Eólico'!AD340 -> 12.929407 | K75: ='Resumen-DiarioHorario-Eólico'!AD397 -> 0 | L75: ='Resumen-DiarioHorario-Eólico'!AD454 -> 0 | M75: ='Resumen-DiarioHorario-Eólico'!AD511 -> 0 | N75: ='Resumen-DiarioHorario-Eólico'!AD568 -> 17.304307 | O75: ='Resumen-DiarioHorario-Eólico'!AD625 -> 0 | P75: ='Resumen-DiarioHorario-Eólico'!AD682 -> 0 | Q75: ='Resumen-DiarioHorario-Eólico'!AD739 -> 0.42747833 | R75: ='Resumen-DiarioHorario-Eólico'!AD796 -> 0 | S75: ='Resumen-DiarioHorario-Eólico'!AD853 -> 0 | T75: ='Resumen-DiarioHorario-Eólico'!AD910 -> 0 | U75: ='Resumen-DiarioHorario-Eólico'!AD967 -> 0.80182833 | V75: ='Resumen-DiarioHorario-Eólico'!AD1024 -> 0.39697667 | W75: ='Resumen-DiarioHorario-Eólico'!AD1081 -> 0.017973333 | X75: ='Resumen-DiarioHorario-Eólico'!AD1138 -> 0 | Y75: ='Resumen-DiarioHorario-Eólico'!AD1195 -> 0 | Z75: ='Resumen-DiarioHorario-Eólico'!AD1252 -> 0 | AA75: ='Resumen-DiarioHorario-Eólico'!AD1309 -> 0 | AB75: ='Resumen-DiarioHorario-Eólico'!AD1366 -> 1.2822783 | AC75: ='Resumen-DiarioHorario-Eólico'!AD1423 -> 0 | AD75: ='Resumen-DiarioHorario-Eólico'!AD1480 -> 0 | AE75: ='Resumen-DiarioHorario-Eólico'!AD1537 -> 0 | AF75: ='Resumen-DiarioHorario-Eólico'!AD1593 -> 0.21189333 | AG75: ='Resumen-DiarioHorario-Eólico'!AD1649 -> 0 | AH75: =+'Resumen-DiarioHorario-Eólico'!AD1705 -> 0 | AI75: =+'Resumen-DiarioHorario-Eólico'!AD1761 -> 0 | AK75: =SUM(E75:AI75) -> 51.41666
B76: PE-CERRILLOS | E76: ='Resumen-DiarioHorario-Eólico'!AD56 -> 10.30801 | F76: ='Resumen-DiarioHorario-Eólico'!AD113 -> 9.9018067 | G76: ='Resumen-DiarioHorario-Eólico'!AD170 -> 0.00642 | H76: ='Resumen-DiarioHorario-Eólico'!AD227 -> 11.060307 | I76: ='Resumen-DiarioHorario-Eólico'!AD284 -> 0 | J76: ='Resumen-DiarioHorario-Eólico'!AD341 -> 19.536737 | K76: ='Resumen-DiarioHorario-Eólico'!AD398 -> 0 | L76: ='Resumen-DiarioHorario-Eólico'!AD455 -> 0 | M76: ='Resumen-DiarioHorario-Eólico'!AD512 -> 0 | N76: ='Resumen-DiarioHorario-Eólico'!AD569 -> 10.007107 | O76: ='Resumen-DiarioHorario-Eólico'!AD626 -> 0 | P76: ='Resumen-DiarioHorario-Eólico'!AD683 -> 4.6803033 | Q76: ='Resumen-DiarioHorario-Eólico'!AD740 -> 0.83941333 | R76: ='Resumen-DiarioHorario-Eólico'!AD797 -> 0 | S76: ='Resumen-DiarioHorario-Eólico'!AD854 -> 0 | T76: ='Resumen-DiarioHorario-Eólico'!AD911 -> 0 | U76: ='Resumen-DiarioHorario-Eólico'!AD968 -> 7.72007 | V76: ='Resumen-DiarioHorario-Eólico'!AD1025 -> 4.67174 | W76: ='Resumen-DiarioHorario-Eólico'!AD1082 -> 0.010106667 | X76: ='Resumen-DiarioHorario-Eólico'!AD1139 -> 0 | Y76: ='Resumen-DiarioHorario-Eólico'!AD1196 -> 0 | Z76: ='Resumen-DiarioHorario-Eólico'!AD1253 -> 0 | AA76: ='Resumen-DiarioHorario-Eólico'!AD1310 -> 0 | AB76: ='Resumen-DiarioHorario-Eólico'!AD1367 -> 0.11284 | AC76: ='Resumen-DiarioHorario-Eólico'!AD1424 -> 0 | AD76: ='Resumen-DiarioHorario-Eólico'!AD1481 -> 0 | AE76: ='Resumen-DiarioHorario-Eólico'!AD1538 -> 0.45289333 | AF76: ='Resumen-DiarioHorario-Eólico'!AD1594 -> 1.3843 | AG76: ='Resumen-DiarioHorario-Eólico'!AD1650 -> 0 | AH76: =+'Resumen-DiarioHorario-Eólico'!AD1706 -> 0 | AI76: =+'Resumen-DiarioHorario-Eólico'!AD1762 -> 0 | AK76: =SUM(E76:AI76) -> 80.692053
B77: PE-MANANTIALES | E77: ='Resumen-DiarioHorario-Eólico'!AD57 -> 10.664907 | F77: ='Resumen-DiarioHorario-Eólico'!AD114 -> 16.07077 | G77: ='Resumen-DiarioHorario-Eólico'!AD171 -> 3.5e-05 | H77: ='Resumen-DiarioHorario-Eólico'!AD228 -> 1.3029117 | I77: ='Resumen-DiarioHorario-Eólico'!AD285 -> 0 | J77: ='Resumen-DiarioHorario-Eólico'!AD342 -> 19.648947 | K77: ='Resumen-DiarioHorario-Eólico'!AD399 -> 0 | L77: ='Resumen-DiarioHorario-Eólico'!AD456 -> 0 | M77: ='Resumen-DiarioHorario-Eólico'!AD513 -> 0 | N77: ='Resumen-DiarioHorario-Eólico'!AD570 -> 21.701087 | O77: ='Resumen-DiarioHorario-Eólico'!AD627 -> 0 | P77: ='Resumen-DiarioHorario-Eólico'!AD684 -> 1.9628883 | Q77: ='Resumen-DiarioHorario-Eólico'!AD741 -> 0.65963333 | R77: ='Resumen-DiarioHorario-Eólico'!AD798 -> 0 | S77: ='Resumen-DiarioHorario-Eólico'!AD855 -> 0 | T77: ='Resumen-DiarioHorario-Eólico'!AD912 -> 0 | U77: ='Resumen-DiarioHorario-Eólico'!AD969 -> 5.3930167 | V77: ='Resumen-DiarioHorario-Eólico'!AD1026 -> 4.37622 | W77: ='Resumen-DiarioHorario-Eólico'!AD1083 -> 0.024253333 | X77: ='Resumen-DiarioHorario-Eólico'!AD1140 -> 0 | Y77: ='Resumen-DiarioHorario-Eólico'!AD1197 -> 0 | Z77: ='Resumen-DiarioHorario-Eólico'!AD1254 -> 0 | AA77: ='Resumen-DiarioHorario-Eólico'!AD1311 -> 0 | AB77: ='Resumen-DiarioHorario-Eólico'!AD1368 -> 1.3610967 | AC77: ='Resumen-DiarioHorario-Eólico'!AD1425 -> 0 | AD77: ='Resumen-DiarioHorario-Eólico'!AD1482 -> 0 | AE77: ='Resumen-DiarioHorario-Eólico'!AD1539 -> 0.72060333 | AF77: ='Resumen-DiarioHorario-Eólico'!AD1595 -> 0.075836667 | AG77: ='Resumen-DiarioHorario-Eólico'!AD1651 -> 0 | AH77: =+'Resumen-DiarioHorario-Eólico'!AD1707 -> 0 | AI77: =+'Resumen-DiarioHorario-Eólico'!AD1763 -> 0 | AK77: =SUM(E77:AI77) -> 83.962205
B78: PE-KALLPA | E78: ='Resumen-DiarioHorario-Eólico'!AD58 -> 0 | F78: ='Resumen-DiarioHorario-Eólico'!AD115 -> 0 | G78: ='Resumen-DiarioHorario-Eólico'!AD172 -> 0 | H78: ='Resumen-DiarioHorario-Eólico'!AD229 -> 0 | I78: ='Resumen-DiarioHorario-Eólico'!AD286 -> 0 | J78: ='Resumen-DiarioHorario-Eólico'!AD343 -> 0 | K78: ='Resumen-DiarioHorario-Eólico'!AD400 -> 0 | L78: ='Resumen-DiarioHorario-Eólico'!AD457 -> 0 | M78: ='Resumen-DiarioHorario-Eólico'!AD514 -> 0 | N78: ='Resumen-DiarioHorario-Eólico'!AD571 -> 512.0045 | O78: ='Resumen-DiarioHorario-Eólico'!AD628 -> 0 | P78: ='Resumen-DiarioHorario-Eólico'!AD685 -> 99.591167 | Q78: ='Resumen-DiarioHorario-Eólico'!AD742 -> 96.388 | R78: ='Resumen-DiarioHorario-Eólico'!AD799 -> 3.0988333 | S78: ='Resumen-DiarioHorario-Eólico'!AD856 -> 24.049333 | T78: ='Resumen-DiarioHorario-Eólico'!AD913 -> 0 | U78: ='Resumen-DiarioHorario-Eólico'!AD970 -> 111.408 | V78: ='Resumen-DiarioHorario-Eólico'!AD1027 -> 144.69867 | W78: ='Resumen-DiarioHorario-Eólico'!AD1084 -> 69.239 | X78: ='Resumen-DiarioHorario-Eólico'!AD1141 -> 0 | Y78: ='Resumen-DiarioHorario-Eólico'!AD1198 -> 0 | Z78: ='Resumen-DiarioHorario-Eólico'!AD1255 -> 11.634333 | AA78: ='Resumen-DiarioHorario-Eólico'!AD1312 -> 0 | AB78: ='Resumen-DiarioHorario-Eólico'!AD1369 -> 306.31283 | AC78: ='Resumen-DiarioHorario-Eólico'!AD1426 -> 0 | AD78: ='Resumen-DiarioHorario-Eólico'!AD1483 -> 0 | AE78: ='Resumen-DiarioHorario-Eólico'!AD1540 -> 274.23833 | AF78: ='Resumen-DiarioHorario-Eólico'!AD1596 -> 44.878167 | AG78: ='Resumen-DiarioHorario-Eólico'!AD1652 -> 0 | AH78: =+'Resumen-DiarioHorario-Eólico'!AD1708 -> 0 | AI78: =+'Resumen-DiarioHorario-Eólico'!AD1764 -> 0 | AK78: =SUM(E78:AI78) -> 1697.5412
B81: DESGLOSE DIARIO DE CURTAILMENTS DE ENERGÍA SOLAR
B83: Central / Día | E83: =E26 -> 45748 | F83: =F26 -> 45749 | G83: =G26 -> 45750 | H83: =H26 -> 45751 | I83: =I26 -> 45752 | J83: =J26 -> 45753 | K83: =K26 -> 45754 | L83: =L26 -> 45755 | ... AI83: =AI26 -> - | AJ83: Total
B84: Total | E84: =SUM(E85:E155) -> 6952.9857 | F84: =SUM(F85:F155) -> 5282.4704 | G84: =SUM(G85:G155) -> 9749.4036 | H84: =SUM(H85:H155) -> 3289.8569 | I84: =SUM(I85:I155) -> 2302.0297 | J84: =SUM(J85:J155) -> 9598.8184 | K84: =SUM(K85:K155) -> 15858.613 | L84: =SUM(L85:L155) -> 14126.187 | ... AI84: =SUM(AI85:AI155) -> 0 | AJ84: =SUM(AK85:AK155) -> 266285.83
...

Sheet Resumen-DiarioHorario-Eólico
B2: CURTAILMENTS EÓLICAS POR CENTRALES EN FORMA DIARIA/HORARIA
B5: ='Resumen-Mensual'!$E$26 -> 45748
B7: Central/Hora | E7: 1 | F7: 2 | G7: 3 | H7: 4 | I7: 5 | J7: 6 | K7: 7 | L7: 8 | M7: 9 | N7: 10 | O7: 11 | P7: 12 | Q7: 13 | R7: 14 | S7: 15 | T7: 16 | U7: 17 | V7: 18 | W7: 19 | X7: 20 | Y7: 21 | Z7: 22 | AA7: 23 | AB7: 24 | AC7: Total
B8: PE-TCHAMMA | E8: 0 | F8: 0.011333333 | G8: 0 | H8: 0 | I8: 0 | J8: 0 | K8: 0 | L8: 0 | M8: 0 | N8: 0 | O8: 0 | P8: 0 | Q8: 5.625 | R8: 25.682667 | S8: 27.25 | T8: 23.115333 | U8: 34.0245 | V8: 28.511667 | W8: 10.4885 | X8: 0 | Y8: 0 | Z8: 0 | AA8: 0 | AB8: 0 | AD8: =SUM(E8:AB8) -> 154.709
B9: PE-SIERRAGORDA | E9: 2.97 | F9: 2.0578333 | G9: 1.1956667 | H9: 0 | I9: 2.2366667 | J9: 0 | K9: 0 | L9: 0 | M9: 0 | N9: 4.9283333 | O9: 6.6706667 | P9: 1.9495 | Q9: 7.7148333 | R9: 23.605833 | S9: 29.467 | T9: 37.167833 | U9: 41.3205 | V9: 32.1945 | W9: 6.1006667 | X9: 0 | Y9: 0 | Z9: 0 | AA9: 0 | AB9: 0 | AD9: =SUM(E9:AB9) -> 199.57983
B10: PE-VALLEDELOSVIENTOS | E10: 0.87583333 | F10: 0.3485 | G10: 0.57816667 | H10: 0.93466667 | I10: 1.6385 | J10: 0 | K10: 0 | L10: 0 | M10: 0 | N10: 2.8616667 | O10: 1.8023333 | P10: 0.948 | Q10: 8.0425 | R10: 35.4065 | S10: 45.072 | T10: 44.724 | U10: 28.690833 | V10: 27.134333 | W10: 8.6211667 | X10: 0 | Y10: 0 | Z10: 0 | AA10: 0 | AB10: 0 | AD10: =SUM(E10:AB10) -> 207.679
B11: PE-CERROTIGRE | E11: 1.1666667 | F11: 0.28 | G11: 0.62 | H11: 1.07 | I11: 2.256 | J11: 0 | K11: 0 | L11: 0 | M11: 0 | N11: 0.088 | O11: 0.08 | P11: 0.2345 | Q11: 5.7695 | R11: 43.265833 | S11: 110.08467 | T11: 125.29133 | U11: 100.7955 | V11: 141.9795 | W11: 20.586333 | X11: 0 | Y11: 0 | Z11: 0 | AA11: 0 | AB11: 0 | AD11: =SUM(E11:AB11) -> 553.56783
B12: PE-CALAMA | E12: 0.63083333 | F12: 0.089 | G12: 0.083 | H12: 0 | I12: 0.17783333 | J12: 0 | K12: 0 | L12: 0 | M12: 0 | N12: 4.156 | O12: 2.7336667 | P12: 0.164 | Q12: 1.1811667 | R12: 13.495333 | S12: 72.908167 | T12: 74.708833 | U12: 41.064333 | V12: 32.416167 | W12: 9.1651667 | X12: 0 | Y12: 0 | Z12: 0 | AA12: 0 | AB12: 0 | AD12: =SUM(E12:AB12) -> 252.9735
B13: PE-TALTAL | E13: 4.0653333 | F13: 2.098 | G13: 0 | H13: 5.1243333 | I13: 8.7353333 | J13: 0 | K13: 0 | L13: 0 | M13: 0 | N13: 3.389 | O13: 0 | P13: 0 | Q13: 3.5746667 | R13: 8.629 | S13: 7.0588333 | T13: 4.6556667 | U13: 6.9218333 | V13: 9.1035 | W13: 1.9281667 | X13: 0 | Y13: 0 | Z13: 0 | AA13: 0 | AB13: 0 | AD13: =SUM(E13:AB13) -> 65.283667
B14: PE-SARCO | E14: 36.591 | F14: 22.296333 | G14: 13.425667 | H14: 10.153833 | I14: 4.2191667 | J14: 0 | K14: 0 | L14: 0 | M14: 0 | N14: 2.3603333 | O14: 3.4436667 | P14: 1.0266667 | Q14: 0 | R14: 0 | S14: 0 | T14: 0 | U14: 7.7645 | V14: 19.232167 | W14: 16.156833 | X14: 0 | Y14: 0 | Z14: 0 | AA14: 0 | AB14: 0 | AD14: =SUM(E14:AB14) -> 136.67017
B15: PE-CABOLEONES-1 | E15: 17.163 | F15: 11.527667 | G15: 7.8073333 | H15: 4.9366667 | I15: 4.1145 | J15: 0 | K15: 0 | L15: 0 | M15: 0 | N15: 3.232 | O15: 4.852 | P15: 1.8721667 | Q15: 0 | R15: 0 | S15: 0 | T15: 0.0048333333 | U15: 12.171833 | V15: 19.832167 | W15: 5.1905 | X15: 0 | Y15: 0 | Z15: 0 | AA15: 0 | AB15: 0 | AD15: =SUM(E15:AB15) -> 92.704667
B16: PE-CABOLEONES-2 | E16: 21.09 | F16: 12.45 | G16: 6.8735 | H16: 4.0605 | I16: 4.328 | J16: 0 | K16: 0 | L16: 0 | M16: 0 | N16: 6.2493333 | O16: 9.9131667 | P16: 3.864 | Q16: 1.3086667 | R16: 0.72333333 | S16: 0 | T16: 0.004 | U16: 9.6186667 | V16: 15.651667 | W16: 3.557 | X16: 0 | Y16: 0 | Z16: 0 | AA16: 0 | AB16: 0 | AD16: =SUM(E16:AB16) -> 99.691833
B17: PE-CABOLEONES-3 | E17: 39.066333 | F17: 26.938 | G17: 17.846667 | H17: 11.290833 | I17: 7.5343333 | J17: 0 | K17: 0 | L17: 0 | M17: 0 | N17: 1.035 | O17: 1.811 | P17: 0.93683333 | Q17: 1.7995 | R17: 1.0655 | S17: 0.378 | T17: 8.6825 | U17: 21.608167 | V17: 29.779167 | W17: 8.9945 | X17: 0 | Y17: 0 | Z17: 0 | AA17: 0 | AB17: 0 | AD17: =SUM(E17:AB17) -> 178.76633
B18: PE-SANJUAN | E18: 3.01 | F18: 0.19033333 | G18: 0.62 | H18: 0.6 | I18: 0.468 | J18: 0 | K18: 0 | L18: 0 | M18: 0 | N18: 1.3228333 | O18: 2.2573333 | P18: 0.70216667 | Q18: 1.6133333 | R18: 0.95266667 | S18: 0.0078333333 | T18: 11.3245 | U18: 16.33 | V18: 18.841667 | W18: 5.8153333 | X18: 0 | Y18: 0 | Z18: 0 | AA18: 0 | AB18: 0 | AD18: =SUM(E18:AB18) -> 64.056
B19: PE-PUNTACOLORADA | E19: 0 | F19: 0 | G19: 0 | H19: 0 | I19: 0 | J19: 0 | K19: 0 | L19: 0 | M19: 0 | N19: 0 | O19: 0 | P19: 0 | Q19: 0 | R19: 0 | S19: 0 | T19: 0 | U19: 0 | V19: 0 | W19: 0 | X19: 0 | Y19: 0 | Z19: 0 | AA19: 0 | AB19: 0 | AD19: =SUM(E19:AB19) -> 0
... B57: PE-MANANTIALES | E57: 0 | F57: 0 | G57: 0 | H57: 0 | I57: 0 | J57: 0 | K57: 0 | L57: 0 | M57: 0 | N57: 0 | O57: 0 | P57: 0 | Q57: 0.67742 | R57: 0.35866167 | S57: 0.11988 | T57: 0.81149333 | U57: 1.6886717 | V57: 4.5447433 | W57: 2.4640367 | X57: 0 | Y57: 0 | Z57: 0 | AA57: 0 | AB57: 0 | AD57: =SUM(E57:AB57) -> 10.664907
B58: PE-KALLPA | AD58: =SUM(E58:AB58) -> 0
B59: Total | E59: =SUM(E8:E58) -> 255.59133 | F59: =SUM(F8:F58) -> 216.20467 | G59: =SUM(G8:G58) -> 221.0455 | H59: =SUM(H8:H58) -> 224.2755 | I59: =SUM(I8:I58) -> 269.41983 | J59: =SUM(J8:J58) -> 132.00267 | K59: =SUM(K8:K58) -> 178.799 | L59: =SUM(L8:L58) -> 0 | ... AB59: =SUM(AB8:AB58) -> 0 | AC59: =SUM(AC8:AE58) -> 4559.9606
B62: ='Resumen-Mensual'!$F$26 -> 45749
B64: Central/Hora | E64: 1 | F64: 2 | G64: 3 | H64: 4 | I64: 5 | J64: 6 | K64: 7 | L64: 8 | M64: 9 | N64: 10 | O64: 11 | P64: 12 | Q64: 13 | R64: 14 | S64: 15 | T64: 16 | U64: 17 | V64: 18 | W64: 19 | X64: 20 | Y64: 21 | Z64: 22 | AA64: 23 | AB64: 24 | AC64: Total
B65: PE-TCHAMMA | E65: 0 | F65: 0 | G65: 0 | H65: 0 | I65: 0 | J65: 0 | K65: 0 | L65: 0 | M65: 0 | N65: 3.9528333 | O65: 4.3875 | P65: 3.8268333 | Q65: 3.9571667 | R65: 10.566833 | S65: 13.674833 | T65: 13.293167 | U65: 5.2806667 | V65: 2.8681667 | W65: 3.703 | X65: 0 | Y65: 0 | Z65: 0 | AA65: 0 | AB65: 0 | AD65: =SUM(E65:AB65) -> 65.511
B66: PE-SIERRAGORDA | E66: 0 | F66: 0 | G66: 0 | H66: 0 | I66: 0 | J66: 0 | K66: 0 | L66: 0 | M66: 0 | N66: 8.8973333 | O66: 10.209167 | P66: 5.0363333 | Q66: 8.3431667 | R66: 13.8335 | S66: 23.913333 | T66: 29.5735 | U66: 34.1505 | V66: 37.542833 | W66: 10.667167 | X66: 0 | Y66: 0 | Z66: 0 | AA66: 0 | AB66: 0 | AD66: =SUM(E66:AB66) -> 182.16683
B67: PE-VALLEDELOSVIENTOS | E67: 0 | F67: 0 | G67: 0 | H67: 0 | I67: 0 | J67: 0 | K67: 0 | L67: 0 | M67: 0 | N67: 4.1691667 | O67: 2.9345 | P67: 2.0366667 | Q67: 5.9268333 | R67: 17.936667 | S67: 36.601333 | T67: 32.683333 | U67: 21.538333 | V67: 23.965 | W67: 14.771667 | X67: 0 | Y67: 0 | Z67: 0 | AA67: 0 | AB67: 0 | AD67: =SUM(E67:AB67) -> 162.5635
B68: PE-CERROTIGRE | E68: 0 | F68: 0 | G68: 0 | H68: 0 | I68: 0 | J68: 0 | K68: 0 | L68: 0 | M68: 0 | N68: 0.36233333 | O68: 0.0041666667 | P68: 0.22233333 | Q68: 8.65 | R68: 42.643333 | S68: 100.59033 | T68: 122.58817 | U68: 121.18417 | V68: 139.39233 | W68: 6.4628333 | X68: 0 | Y68: 0 | Z68: 0 | AA68: 0 | AB68: 0 | AD68: =SUM(E68:AB68) -> 542.1
B69: PE-CALAMA | E69: 0 | F69: 0 | G69: 0 | H69: 0 | I69: 0 | J69: 0 | K69: 0 | L69: 0 | M69: 0 | N69: 16.0815 | O69: 9.4026667 | P69: 2.2786667 | Q69: 1.1588333 | R69: 4.075 | S69: 28.817167 | T69: 49.483333 | U69: 37.946833 | V69: 73.336667 | W69: 22.7485 | X69: 0 | Y69: 0 | Z69: 0 | AA69: 0 | AB69: 0 | AD69: =SUM(E69:AB69) -> 245.32917
B70: PE-TALTAL | E70: 0 | F70: 0 | G70: 0 | H70: 0 | I70: 0 | J70: 0 | K70: 0 | L70: 0 | M70: 0 | N70: 6.3353333 | O70: 4.2025 | P70: 0.56 | Q70: 0.68 | R70: 4.8 | S70: 14.7435 | T70: 13.096833 | U70: 7.037 | V70: 0 | W70: 0 | X70: 0 | Y70: 0 | Z70: 0 | AA70: 0 | AB70: 0 | AD70: =SUM(E70:AB70) -> 51.455167
B71: PE-SARCO | E71: 0 | F71: 0 | G71: 0 | H71: 0 | I71: 0 | J71: 0 | K71: 0 | L71: 0 | M71: 0 | N71: 0.13033333 | O71: 4.0701667 | P71: 3.1588333 | Q71: 3.0213333 | R71: 2.5328333 | S71: 7.2385 | T71: 26.038667 | U71: 46.014167 | V71: 69.787667 | W71: 30.721167 | X71: 0 | Y71: 0 | Z71: 0 | AA71: 0 | AB71: 0 | AD71: =SUM(E71:AB71) -> 192.71367
B72: PE-CABOLEONES-1 | E72: 0 | F72: 0 | G72: 0 | H72: 0 | I72: 0 | J72: 0 | K72: 0 | L72: 0 | M72: 0 | N72: 1.2393333 | O72: 1.371 | P72: 1.421 | Q72: 3.1388333 | R72: 7.2386667 | S72: 11.911333 | T72: 21.817167 | U72: 29.717 | V72: 36.568833 | W72: 6.9763333 | X72: 0 | Y72: 0 | Z72: 0 | AA72: 0 | AB72: 0 | AD72: =SUM(E72:AB72) -> 121.3995
B73: PE-CABOLEONES-2 | E73: 0 | F73: 0 | G73: 0 | H73: 0 | I73: 0 | J73: 0 | K73: 0 | L73: 0 | M73: 0 | N73: 3.225 | O73: 4.883 | P73: 4.6855 | Q73: 5.2925 | R73: 5.3656667 | S73: 6.9808333 | T73: 12.115167 | U73: 21.8415 | V73: 34.584167 | W73: 3.1658333 | X73: 0 | Y73: 0 | Z73: 0 | AA73: 0 | AB73: 0 | AD73: =SUM(E73:AB73) -> 102.13917
B74: PE-CABOLEONES-3 | E74: 0 | F74: 0 | G74: 0 | H74: 0 | I74: 0 | J74: 0 | K74: 0 | L74: 0 | M74: 0 | N74: 2.3276667 | O74: 3.514 | P74: 4.4951667 | Q74: 7.3298333 | R74: 11.034333 | S74: 18.001 | T74: 38.825 | U74: 49.079167 | V74: 44.759833 | W74: 8.0105 | X74: 0 | Y74: 0 | Z74: 0 | AA74: 0 | AB74: 0 | AD74: =SUM(E74:AB74) -> 187.3765
B75: PE-SANJUAN | E75: 0 | F75: 0 | G75: 0 | H75: 0 | I75: 0 | J75: 0 | K75: 0 | L75: 0 | M75: 0 | N75: 0.00016666667 | O75: 0 | P75: 0.41866667 | Q75: 1.5406667 | R75: 10.976167 | S75: 17.729 | T75: 31.671667 | U75: 60.863833 | V75: 75.356833 | W75: 11.022167 | X75: 0 | Y75: 0 | Z75: 0 | AA75: 0 | AB75: 0 | AD75: =SUM(E75:AB75) -> 209.57917
B76: PE-PUNTACOLORADA | E76: 0 | F76: 0 | G76: 0 | H76: 0 | I76: 0 | J76: 0 | K76: 0 | L76: 0 | M76: 0 | N76: 0 | O76: 0 | P76: 0 | Q76: 0 | R76: 0 | S76: 0 | T76: 0 | U76: 0 | V76: 0 | W76: 0 | X76: 0 | Y76: 0 | Z76: 0 | AA76: 0 | AB76: 0 | AD76: =SUM(E76:AB76) -> 0
... B114: PE-MANANTIALES | E114: 0 | F114: 0 | G114: 0 | H114: 0 | I114: 0 | J114: 0 | K114: 0 | L114: 0 | M114: 0 | N114: 0 | O114: 0 | P114: 0 | Q114: 0 | R114: 0 | S114: 0 | T114: 0.90847667 | U114: 12.983552 | V114: 0 | W114: 2.1787417 | X114: 0 | Y114: 0 | Z114: 0 | AA114: 0 | AB114: 0 | AD114: =SUM(E114:AB114) -> 16.07077
B115: PE-KALLPA | AD115: =SUM(E115:AB115) -> 0
B116: Total | E116: =SUM(E65:E115) -> 0 | F116: =SUM(F65:F115) -> 0 | G116: =SUM(G65:G115) -> 0 | H116: =SUM(H65:H115) -> 0 | I116: =SUM(I65:I115) -> 0 | J116: =SUM(J65:J115) -> 0 | K116: =SUM(K65:K115) -> 0 | L116: =SUM(L65:L115) -> 0 | ... AB116: =SUM(AB65:AB115) -> 0 | AC116: =SUM(AC65:AE115) -> 3733.3025
B119: ='Resumen-Mensual'!$G$26 -> 45750
B121: Central/Hora | E121: 1 | F121: 2 | G121: 3 | H121: 4 | I121: 5 | J121: 6 | K121: 7 | L121: 8 | M121: 9 | N121: 10 | O121: 11 | P121: 12 | Q121: 13 | R121: 14 | S121: 15 | T121: 16 | U121: 17 | V121: 18 | W121: 19 | X121: 20 | Y121: 21 | Z121: 22 | AA121: 23 | AB121: 24 | AC121: Total
B122: PE-TCHAMMA | E122: 0 | F122: 0 | G122: 0 | H122: 0 | I122: 0 | J122: 0 | K122: 0 | L122: 0 | M122: 0 | N122: 0 | O122: 0 | P122: 0 | Q122: 0 | R122: 0 | S122: 0 | T122: 0 | U122: 0 | V122: 0 | W122: 29.539 | X122: 0 | Y122: 0 | Z122: 0 | AA122: 0 | AB122: 0 | AD122: =SUM(E122:AB122) -> 29.539
B123: PE-SIERRAGORDA | E123: 0 | F123: 0 | G123: 0 | H123: 0 | I123: 0 | J123: 0 | K123: 0 | L123: 0 | M123: 0.2825 | N123: 5.1208333 | O123: 9.5105 | P123: 1.5178333 | Q123: 2.056 | R123: 12.088667 | S123: 15.146167 | T123: 11.621667 | U123: 7.8051667 | V123: 19.1 | W123: 26.075333 | X123: 0 | Y123: 0 | Z123: 0 | AA123: 0 | AB123: 0 | AD123: =SUM(E123:AB123) -> 110.32467
B124: PE-VALLEDELOSVIENTOS | E124: 0 | F124: 0 | G124: 0 | H124: 0 | I124: 0 | J124: 0 | K124: 0 | L124: 0 | M124: 0.79783333 | N124: 2.8678333 | O124: 2.4193333 | P124: 1.6115 | Q124: 0.706 | R124: 0.29733333 | S124: 0 | T124: 16.948333 | U124: 24.224 | V124: 24.196 | W124: 10.059667 | X124: 0 | Y124: 0 | Z124: 0 | AA124: 0 | AB124: 0 | AD124: =SUM(E124:AB124) -> 84.127833
...

Sheet Resumen-DiarioHorario-Solar
B2: CURTAILMENTS SOLAR POR CENTRALES EN FORMA DIARIA/HORARIA
B5: ='Resumen-Mensual'!$E$26 -> 45748
B7: Central/Hora | E7: 1 | F7: 2 | G7: 3 | H7: 4 | I7: 5 | J7: 6 | K7: 7 | L7: 8 | M7: 9 | N7: 10 | O7: 11 | P7: 12 | Q7: 13 | R7: 14 | S7: 15 | T7: 16 | U7: 17 | V7: 18 | W7: 19 | X7: 20 | Y7: 21 | Z7: 22 | AA7: 23 | AB7: 24 | AC7: Total
B8: PFV-POZOALMONTE-2 | E8: 0 | F8: 0 | G8: 0 | H8: 0 | I8: 0 | J8: 0 | K8: 0 | L8: 0 | M8: 0 | N8: 0 | O8: 0 | P8: 0 | Q8: 0.14383333 | R8: 0.2485 | S8: 0.12133333 | T8: 0 | U8: 0 | V8: 0 | W8: 0 | X8: 0 | Y8: 0 | Z8: 0 | AA8: 0 | AB8: 0 | AD8: =SUM(E8:AB8) -> 0.51366667
B9: PFV-POZOALMONTE-3 | E9: 0 | F9: 0 | G9: 0 | H9: 0 | I9: 0 | J9: 0 | K9: 0 | L9: 0 | M9: 0 | N9: 0 | O9: 0.71916667 | P9: 0.20033333 | Q9: 0.11216667 | R9: 0.0023333333 | S9: 0 | T9: 0 | U9: 0.40483333 | V9: 0.54516667 | W9: 0.0071666667 | X9: 0 | Y9: 0 | Z9: 0 | AA9: 0 | AB9: 0 | AD9: =SUM(E9:AB9) -> 1.9911667
B10: PFV-LAHUAYCA-2 | E10: 0 | F10: 0 | G10: 0 | H10: 0 | I10: 0 | J10: 0 | K10: 0 | L10: 0 | M10: 0 | N10: 5.2103333 | O10: 8.6965 | P10: 2.6205 | Q10: 2.7431667 | R10: 5.9995 | S10: 5.6783333 | T10: 5.6373333 | U10: 5.6545 | V10: 2.6348333 | W10: 0.027666667 | X10: 0 | Y10: 0 | Z10: 0 | AA10: 0 | AB10: 0 | AD10: =SUM(E10:AB10) -> 44.902667
B11: PFV-SANTAISABEL | E11: 0 | F11: 0 | G11: 0 | H11: 0 | I11: 0 | J11: 0 | K11: 0 | L11: 0 | M11: 0 | N11: 15.247833 | O11: 23.511667 | P11: 7.6263333 | Q11: 13.7885 | R11: 24.993667 | S11: 28.332833 | T11: 33.264167 | U11: 31.622333 | V11: 16.5155 | W11: 0 | X11: 0 | Y11: 0 | Z11: 0 | AA11: 0 | AB11: 0 | AD11: =SUM(E11:AB11) -> 194.90283
B12: PFV-HUATACONDO | E12: 0 | F12: 0 | G12: 0 | H12: 0 | I12: 0 | J12: 0 | K12: 0 | L12: 0 | M12: 0 | N12: 0 | O12: 0 | P12: 0 | Q12: 0 | R12: 0 | S12: 0 | T12: 0 | U12: 0 | V12: 0 | W12: 0 | X12: 0 | Y12: 0 | Z12: 0 | AA12: 0 | AB12: 0 | AD12: =SUM(E12:AB12) -> 0
B13: PFV-ATACAMASOLAR-2 | E13: 0 | F13: 0 | G13: 0 | H13: 0 | I13: 0 | J13: 0 | K13: 0 | L13: 0 | M13: 0 | N13: 0.114 | O13: 35.230667 | P13: 19.858333 | Q13: 8.3486667 | R13: 29.982 | S13: 65.319 | T13: 37.403667 | U13: 21.6485 | V13: 13.719167 | W13: 0 | X13: 0 | Y13: 0 | Z13: 0 | AA13: 0 | AB13: 0 | AD13: =SUM(E13:AB13) -> 231.624
B14: PFV-NUEVOQUILLAGUA | E14: 0 | F14: 0 | G14: 0 | H14: 0 | I14: 0 | J14: 0 | K14: 0 | L14: 0 | M14: 0 | N14: 0 | O14: 0 | P14: 0 | Q14: 0 | R14: 0 | S14: 0 | T14: 0 | U14: 0 | V14: 0 | W14: 0 | X14: 0 | Y14: 0 | Z14: 0 | AA14: 0 | AB14: 0 | AD14: =SUM(E14:AB14) -> 0
B15: PFV-GRANJA | E15: 0 | F15: 0 | G15: 0 | H15: 0 | I15: 0 | J15: 0 | K15: 0 | L15: 0 | M15: 0 | N15: 24.3285 | O15: 17.2055 | P15: 0.68366667 | Q15: 7.548 | R15: 16.470167 | S15: 14.184167 | T15: 0 | U15: 4.6896667 | V15: 0.44633333 | W15: 0 | X15: 0 | Y15: 0 | Z15: 0 | AA15: 0 | AB15: 0 | AD15: =SUM(E15:AB15) -> 85.556
B16: PFV-USYA | E16: 0 | F16: 0 | G16: 0 | H16: 0 | I16: 0 | J16: 0 | K16: 0 | L16: 0 | M16: 0 | N16: 2.532 | O16: 24.258 | P16: 12.1795 | Q16: 6.3481667 | R16: 14.008667 | S16: 12.533167 | T16: 12.278667 | U16: 0 | V16: 0 | W16: 0 | X16: 0 | Y16: 0 | Z16: 0 | AA16: 0 | AB16: 0 | AD16: =SUM(E16:AB16) -> 84.138167
B17: PFV-SANPEDRO-GPG | E17: 0 | F17: 0 | G17: 0 | H17: 0 | I17: 0 | J17: 0 | K17: 0 | L17: 0 | M17: 0 | N17: 15.169167 | O17: 15.294167 | P17: 7.0853333 | Q17: 10.415833 | R17: 14.531 | S17: 18.088667 | T17: 17.878167 | U17: 20.349 | V17: 7.1236667 | W17: 0 | X17: 0 | Y17: 0 | Z17: 0 | AA17: 0 | AB17: 0 | AD17: =SUM(E17:AB17) -> 125.935
B18: PFV-JAMA-1 | E18: 0 | F18: 0 | G18: 0 | H18: 0 | I18: 0 | J18: 0 | K18: 0 | L18: 0 | M18: 0 | N18: 17.544 | O18: 26 | P18: 9.1 | Q18: 15.6 | R18: 18.17 | S18: 10.04 | T18: 7.45 | U18: 5.7 | V18: 6.48 | W18: 2.3 | X18: 0 | Y18: 0 | Z18: 0 | AA18: 0 | AB18: 0 | AD18: =SUM(E18:AB18) -> 118.384
B19: PFV-JAMA-2 | E19: 0 | F19: 0 | G19: 0 | H19: 0 | I19: 0 | J19: 0 | K19: 0 | L19: 0 | M19: 0 | N19: 10.557167 | O19: 17.347333 | P19: 6.2355 | Q19: 9.5476667 | R19: 18.759833 | S19: 15.046833 | T19: 7.393 | U19: 6.4 | V19: 6.3348333 | W19: 0.024166667 | X19: 0 | Y19: 0 | Z19: 0 | AA19: 0 | AB19: 0 | AD19: =SUM(E19:AB19) -> 97.646333
... B76: PFV-ANDESIV | E76: 0 | F76: 0 | G76: 0 | H76: 0 | I76: 0 | J76: 0 | K76: 0 | L76: 0 | M76: 0 | N76: 0 | O76: 0 | P76: 0 | Q76: 0 | R76: 0 | S76: 0 | T76: 0 | U76: 0 | V76: 0 | W76: 0 | X76: 0 | Y76: 0 | Z76: 0 | AA76: 0 | AB76: 0 | AD76: =SUM(E76:AB76) -> 0
B77: PFV-TAMARICO | AD77: =SUM(E77:AB77) -> 0
B78: PFV-TAIRA | AD78: =SUM(E78:AB78) -> 0
B79: Total | E79: =SUM(E8:E78) -> 0 | F79: =SUM(F8:F78) -> 0 | G79: =SUM(G8:G78) -> 0 | H79: =SUM(H8:H78) -> 0 | I79: =SUM(I8:I78) -> 0 | J79: =SUM(J8:J78) -> 0 | K79: =SUM(K8:K78) -> 0 | L79: =SUM(L8:L78) -> 0 | ... AB79: =SUM(AB8:AB78) -> 0 | AC79: =SUM(AC8:AE78) -> 6952.9857
B82: ='Resumen-Mensual'!$F$26 -> 45749
B84: Central/Hora | E84: 1 | F84: 2 | G84: 3 | H84: 4 | I84: 5 | J84: 6 | K84: 7 | L84: 8 | M84: 9 | N84: 10 | O84: 11 | P84: 12 | Q84: 13 | R84: 14 | S84: 15 | T84: 16 | U84: 17 | V84: 18 | W84: 19 | X84: 20 | Y84: 21 | Z84: 22 | AA84: 23 | AB84: 24 | AC84: Total
B85: PFV-POZOALMONTE-2 | E85: 0 | F85: 0 | G85: 0 | H85: 0 | I85: 0 | J85: 0 | K85: 0 | L85: 0 | M85: 0 | N85: 0 | O85: 0 | P85: 0 | Q85: 0 | R85: 0 | S85: 0 | T85: 0.17016667 | U85: 0.28033333 | V85: 0 | W85: 0 | X85: 0 | Y85: 0 | Z85: 0 | AA85: 0 | AB85: 0 | AD85: =SUM(E85:AB85) -> 0.4505
B86: PFV-POZOALMONTE-3 | E86: 0 | F86: 0 | G86: 0 | H86: 0 | I86: 0 | J86: 0 | K86: 0 | L86: 0 | M86: 0 | N86: 0 | O86: 0 | P86: 0 | Q86: 0 | R86: 0 | S86: 0 | T86: 0 | U86: 0 | V86: 0 | W86: 0 | X86: 0 | Y86: 0 | Z86: 0 | AA86: 0 | AB86: 0 | AD86: =SUM(E86:AB86) -> 0
B87: PFV-LAHUAYCA-2 | E87: 0 | F87: 0 | G87: 0 | H87: 0 | I87: 0 | J87: 0 | K87: 0 | L87: 0 | M87: 0 | N87: 3.2071667 | O87: 6.1733333 | P87: 4.7135 | Q87: 6.5501667 | R87: 5.7228333 | S87: 4.5366667 | T87: 6.7345 | U87: 7.3605 | V87: 1.6585 | W87: 0.3005 | X87: 0 | Y87: 0 | Z87: 0 | AA87: 0 | AB87: 0 | AD87: =SUM(E87:AB87) -> 46.957667
B88: PFV-SANTAISABEL | E88: 0 | F88: 0 | G88: 0 | H88: 0 | I88: 0 | J88: 0 | K88: 0 | L88: 0 | M88: 0 | N88: 13.676833 | O88: 25.008833 | P88: 22.022333 | Q88: 19.776667 | R88: 21.333167 | S88: 22.675167 | T88: 28.225833 | U88: 25.550833 | V88: 11.326667 | W88: 3.4606667 | X88: 0 | Y88: 0 | Z88: 0 | AA88: 0 | AB88: 0 | AD88: =SUM(E88:AB88) -> 193.057
B89: PFV-HUATACONDO | E89: 0 | F89: 0 | G89: 0 | H89: 0 | I89: 0 | J89: 0 | K89: 0 | L89: 0 | M89: 0 | N89: 0 | O89: 0 | P89: 0 | Q89: 0 | R89: 0 | S89: 0 | T89: 0 | U89: 0 | V89: 0 | W89: 0 | X89: 0 | Y89: 0 | Z89: 0 | AA89: 0 | AB89: 0 | AD89: =SUM(E89:AB89) -> 0
B90: PFV-ATACAMASOLAR-2 | E90: 0 | F90: 0 | G90: 0 | H90: 0 | I90: 0 | J90: 0 | K90: 0 | L90: 0 | M90: 0 | N90: 0 | O90: 22.144333 | P90: 44.9135 | Q90: 82.540333 | R90: 84.980167 | S90: 87.243167 | T90: 59.1805 | U90: 17.539833 | V90: 56.507667 | W90: 5.2256667 | X90: 0 | Y90: 0 | Z90: 0 | AA90: 0 | AB90: 0 | AD90: =SUM(E90:AB90) -> 460.27517
B91: PFV-NUEVOQUILLAGUA | E91: 0 | F91: 0 | G91: 0 | H91: 0 | I91: 0 | J91: 0 | K91: 0 | L91: 0 | M91: 0 | N91: 0 | O91: 0 | P91: 0 | Q91: 0 | R91: 0 | S91: 0 | T91: 0 | U91: 0 | V91: 0 | W91: 0 | X91: 0 | Y91: 0 | Z91: 0 | AA91: 0 | AB91: 0 | AD91: =SUM(E91:AB91) -> 0
B92: PFV-GRANJA | E92: 0 | F92: 0 | G92: 0 | H92: 0 | I92: 0 | J92: 0 | K92: 0 | L92: 0 | M92: 0 | N92: 0 | O92: 0 | P92: 1.588 | Q92: 0.0013333333 | R92: 0.053166667 | S92: 0 | T92: 0 | U92: 7.6736667 | V92: 13.566167 | W92: 0.43233333 | X92: 0 | Y92: 0 | Z92: 0 | AA92: 0 | AB92: 0 | AD92: =SUM(E92:AB92) -> 23.314667
B93: PFV-USYA | E93: 0 | F93: 0 | G93: 0 | H93: 0 | I93: 0 | J93: 0 | K93: 0 | L93: 0 | M93: 0 | N93: 0 | O93: 0 | P93: 0 | Q93: 0.014833333 | R93: 0 | S93: 0 | T93: 0 | U93: 0 | V93: 0 | W93: 0.0036666667 | X93: 0 | Y93: 0 | Z93: 0 | AA93: 0 | AB93: 0 | AD93: =SUM(E93:AB93) -> 0.0185
