Workbook

Sheet Resumen-Mensual
B2: RESUMEN DE CURTAILMENTS ACUMULADO DE CENTRALES EÓLICAS, SOLARES HIDRÁULICAS DE PASADA, EMBALSES Y SERIES HÍDRICAS AÑO 2025
C4: Resumen Anual / Mensual (GWh)
C6: Acumulado 2025
B7: Eólica | C7: =SUM(C14,F14,I14,L14,O14,R14,U14,X14,AA14,AD14,AG14,AJ14) -> 1157.2196 | E7: =IF($C$11=0,"-",+C7/$C$11) -> 0.25378033
B8: Solar | C8: =SUM(C15,F15,I15,L15,O15,R15,U15,X15,AA15,AD15,AG15,AJ15) -> 3286.6921 | E8: =IF($C$11=0,"-",+C8/$C$11) -> 0.72077748 | Y8: =+AJ87/1000-X15 -> 183.85022
B9: Hidro Pasada | C9: =SUM(C16,F16,I16,L16,O16,R16,U16,X16,AA16,AD16,AG16,AJ16) -> 101.92648 | E9: =IF($C$11=0,"-",+C9/$C$11) -> 0.02235266
B10: Hidro Embalse | C10: =SUM(C17,F17,I17,L17,O17,R17,U17,X17,AA17,AD17,AG17,AJ17) -> 14.088062 | E10: =IF($C$11=0,"-",+C10/$C$11) -> 0.0030895372
B11: Total | C11: =SUM(C7:C10) -> 4559.9263 | E11: =SUM(E7:E10) -> 1
C13: 45658 | F13: 45689 | I13: 45717 | L13: 45748 | O13: 45778 | R13: 45809 | U13: 45839 | X13: 45870 | AA13: 45901 | AD13: 45931 | AG13: 45962 | AJ13: 45992
B14: Eólica | C14: ='Acumulado-Anual-Eólico'!AJ10/1000 -> 147.02888 | E14: =IF($C$18=0,"-",+C14/$C$18) -> 0.22184096 | F14: ='Acumulado-Anual-Eólico'!AJ65/1000 -> 100.28563 | H14: =IF($F$18=0,"-",+F14/$F$18) -> 0.23812007 | I14: ='Acumulado-Anual-Eólico'!$AJ$120/1000 -> 121.00713 | K14: =IF($I$18=0,"-",+I14/$I$18) -> 0.2223667 | L14: ='Acumulado-Anual-Eólico'!AJ175/1000 -> 65.27924 | N14: =IF($L$18=0,"-",+L14/$L$18) -> 0.19569124 | O14: =+'Acumulado-Anual-Eólico'!AJ231/1000 -> 44.241988 | Q14: =IF($O$18=0,"-",+O14/$O$18) -> 0.23459099 | R14: ='Acumulado-Anual-Eólico'!$AJ$287/1000 -> 69.493758 | T14: =IF($R$18=0,"-",+R14/$R$18) -> 0.2403998 | U14: ='Acumulado-Anual-Eólico'!AJ343/1000 -> 67.553137 | W14: =IF($U$18=0,"-",+U14/$U$18) -> 0.27546315 | X14: =+'Acumulado-Anual-Eólico'!AJ400/1000 -> 151.15361 | Z14: =IF($X$18=0,"-",+X14/$X$18) -> 0.30070643 | AA14: ='Acumulado-Anual-Eólico'!$AJ$459/1000 -> 182.70199 | AC14: =IF($AA$18=0,"-",+AA14/$AA$18) -> 0.29740694 | AD14: ='Acumulado-Anual-Eólico'!$AJ$518/1000 -> 208.47422 | AF14: =IF($AD$18=0,"-",+AD14/$AD$18) -> 0.27490079 | AG14: 0 | AI14: =IF($AG$18=0,"-",+AG14/$AG$18) -> - | AJ14: 0 | AL14: =IF($AJ$18=0,"-",+AJ14/$AJ$18) -> -
B15: Solar | C15: ='Acumulado-Anual-Solar'!AJ10/1000 -> 494.3341 | E15: =IF($C$18=0,"-",+C15/$C$18) -> 0.74586401 | F15: ='Acumulado-Anual-Solar'!AJ84/1000 -> 311.23959 | H15: =IF($F$18=0,"-",+F15/$F$18) -> 0.73901313 | I15: ='Acumulado-Anual-Solar'!$AJ$158/1000 -> 415.98783 | K15: =IF($I$18=0,"-",+I15/$I$18) -> 0.76443301 | L15: ='Acumulado-Anual-Solar'!AJ232/1000 -> 266.28583 | N15: =IF($L$18=0,"-",+L15/$L$18) -> 0.79825998 | O15: =+'Acumulado-Anual-Solar'!AJ308/1000 -> 142.0184 | Q15: =IF($O$18=0,"-",+O15/$O$18) -> 0.75304566 | R15: ='Acumulado-Anual-Solar'!AJ384/1000 -> 218.23988 | T15: =IF($R$18=0,"-",+R15/$R$18) -> 0.75495734 | U15: =+'Acumulado-Anual-Solar'!AJ460/1000 -> 174.50246 | W15: =IF($U$18=0,"-",+U15/$U$18) -> 0.7115731 | X15: =+'Acumulado-Anual-Solar'!AJ536/1000 -> 336.60074 | Z15: =IF($X$18=0,"-",+X15/$X$18) -> 0.6696367 | AA15: ='Acumulado-Anual-Solar'!$AJ$612/1000 -> 407.03238 | AC15: =IF($AA$18=0,"-",+AA15/$AA$18) -> 0.66257764 | AD15: ='Acumulado-Anual-Solar'!$AJ$688/1000 -> 520.45095 | AF15: =IF($AD$18=0,"-",+AD15/$AD$18) -> 0.68628333 | AG15: 0 | AI15: =IF($AG$18=0,"-",+AG15/$AG$18) -> - | AJ15: 0 | AL15: =IF($AJ$18=0,"-",+AJ15/$AJ$18) -> -
B16: Hidro Pasada | C16: =+'Acumulado-Anual-HP'!AJ11/1000 -> 20.43018 | E16: =IF($C$18=0,"-",+C16/$C$18) -> 0.030825581 | F16: =+'Acumulado-Anual-HP'!AJ152/1000 -> 8.6135453 | H16: =IF($F$18=0,"-",+F16/$F$18) -> 0.020452164 | I16: ='Acumulado-Anual-HP'!AJ293/1000 -> 7.18331 | K16: =IF($I$18=0,"-",+I16/$I$18) -> 0.013200288 | L16: ='Acumulado-Anual-HP'!AJ434/1000 -> 2.0177691 | N16: =IF($L$18=0,"-",+L16/$L$18) -> 0.0060487797 | O16: =+'Acumulado-Anual-HP'!AJ575/1000 -> 2.3316291 | Q16: =IF($O$18=0,"-",+O16/$O$18) -> 0.01236335 | R16: ='Acumulado-Anual-HP'!$AJ$716/1000 -> 1.3421382 | T16: =IF($R$18=0,"-",+R16/$R$18) -> 0.0046428596 | U16: ='Acumulado-Anual-HP'!AJ859/1000 -> 3.1791624 | W16: =IF($U$18=0,"-",+U16/$U$18) -> 0.012963751 | X16: ='Acumulado-Anual-HP'!$AJ$1002/1000 -> 14.225515 | Z16: =IF($X$18=0,"-",+X16/$X$18) -> 0.028300375 | AA16: ='Acumulado-Anual-HP'!$AJ$1145/1000 -> 19.130508 | AC16: =IF($AA$18=0,"-",+AA16/$AA$18) -> 0.031141127 | AD16: ='Acumulado-Anual-HP'!$AJ$1288/1000 -> 23.472725 | AF16: =IF($AD$18=0,"-",+AD16/$AD$18) -> 0.030951889 | AG16: 0 | AI16: =IF($AG$18=0,"-",+AG16/$AG$18) -> - | AJ16: 0 | AL16: =IF($AJ$18=0,"-",+AJ16/$AJ$18) -> -
B17: Hidro Embalse | C17: ='Acumulado-Anual-HE'!AJ10/1000 -> 0.97390005 | E17: =IF($C$18=0,"-",+C17/$C$18) -> 0.0014694455 | F17: =+'Acumulado-Anual-HE'!AJ44/1000 -> 1.0169386 | H17: =IF($F$18=0,"-",+F17/$F$18) -> 0.0024146381 | I17: ='Acumulado-Anual-HE'!AJ78 -> 0 | K17: =IF($I$18=0,"-",+I17/$I$18) -> 0 | L17: ='Acumulado-Anual-HE'!AJ112 -> 0 | N17: =IF($L$18=0,"-",+L17/$L$18) -> 0 | O17: =+'Acumulado-Anual-HE'!AJ146/1000 -> 0 | Q17: =IF($O$18=0,"-",+O17/$O$18) -> 0 | R17: ='Acumulado-Anual-HE'!$AJ$180 -> 0 | T17: =IF($R$18=0,"-",+R17/$R$18) -> 0 | U17: =+'Acumulado-Anual-HE'!AJ214/1000 -> 0 | W17: =IF($U$18=0,"-",+U17/$U$18) -> 0 | X17: ='Acumulado-Anual-HE'!$AJ$248/1000 -> 0.68185328 | Z17: =IF($X$18=0,"-",+X17/$X$18) -> 0.0013564854 | AA17: ='Acumulado-Anual-HE'!$AJ$282/1000 -> 5.4516235 | AC17: =IF($AA$18=0,"-",+AA17/$AA$18) -> 0.0088742912 | AD17: ='Acumulado-Anual-HE'!$AJ$316/1000 -> 5.9637463 | AF17: =IF($AD$18=0,"-",+AD17/$AD$18) -> 0.0078639874 | AG17: 0 | AI17: =IF($AG$18=0,"-",+AG17/$AG$18) -> - | AJ17: 0 | AL17: =IF($AJ$18=0,"-",+AJ17/$AJ$18) -> -
B18: Total | C18: =SUM(C14:D17) -> 662.76706 | E18: =SUM(E14:E17) -> 1 | F18: =SUM(F14:G17) -> 421.1557 | H18: =SUM(H14:H17) -> 1 | I18: =SUM(I14:I17) -> 544.17827 | K18: =SUM(K14:K17) -> 1 | L18: =SUM(L14:L17) -> 333.58284 | N18: =SUM(N14:N17) -> 1 | O18: =SUM(O14:O17) -> 188.59202 | Q18: =SUM(Q14:Q17) -> 1 | R18: =SUM(R14:R17) -> 289.07578 | T18: =SUM(T14:T17) -> 1 | U18: =SUM(U14:U17) -> 245.23476 | W18: =SUM(W14:W17) -> 1 | X18: =SUM(X14:X17) -> 502.66172 | Z18: =SUM(Z14:Z17) -> 1 | AA18: =SUM(AA14:AA17) -> 614.3165 | AC18: =SUM(AC14:AC17) -> 1 | AD18: =SUM(AD14:AD17) -> 758.36164 | AF18: =SUM(AF14:AF17) -> 1 | AG18: =SUM(AG14:AG17) -> 0 | AI18: =SUM(AI14:AI17) -> 0 | AJ18: =SUM(AJ14:AJ17) -> 0 | AL18: =SUM(AL14:AL17) -> 0
B21: RESUMEN DE CURTAILMENTS CENTRALES EÓLICAS, SOLARES, HIDRÁULICAS DE PASADA, EMBALSES Y SERIES HÍDRICAS CORRESPONDIENTE A OCTUBRE 2025 (MWh)
B24: DESGLOSE DIARIO DE CURTAILMENTS DE ENERGÍA EÓLICA
B26: Central / Día | E26: 45931 | F26: =+E26+1 -> 45932 | G26: =+F26+1 -> 45933 | H26: =+G26+1 -> 45934 | I26: =+H26+1 -> 45935 | J26: =+I26+1 -> 45936 | K26: =+J26+1 -> 45937 | L26: =+K26+1 -> 45938 | M26: =+L26+1 -> 45939 | ... AI26: =+AH26+1 -> 45961 | AJ26: Total
B27: Total | E27: =SUM(E28:E81) -> 5511.0457 | F27: =SUM(F28:F81) -> 2682.814 | G27: =SUM(G28:G81) -> 5126.3706 | H27: =SUM(H28:H81) -> 4962.0839 | I27: =SUM(I28:I81) -> 7325.7052 | J27: =SUM(J28:J81) -> 8778.8924 | K27: =SUM(K28:K81) -> 9567.5687 | L27: =SUM(L28:L81) -> 7346.5503 | ... AI27: =SUM(AI28:AI81) -> 10461.931 | AK27: =SUM(AK28:AK81) -> 208474.22
B28: PE-TCHAMMA | E28: ='Resumen-DiarioHorario-Eólico'!AD8 -> 188.26683 | F28: ='Resumen-DiarioHorario-Eólico'!AD68 -> 60.774333 | G28: ='Resumen-DiarioHorario-Eólico'!AD128 -> 97.160167 | H28: ='Resumen-DiarioHorario-Eólico'!AD188 -> 115.36917 | I28: ='Resumen-DiarioHorario-Eólico'!AD248 -> 81.9515 | J28: ='Resumen-DiarioHorario-Eólico'!AD308 -> 166.658 | K28: ='Resumen-DiarioHorario-Eólico'!AD368 -> 115.44083 | L28: ='Resumen-DiarioHorario-Eólico'!AD428 -> 187.29567 | M28: ='Resumen-DiarioHorario-Eólico'!AD488 -> 237.90733 | N28: ='Resumen-DiarioHorario-Eólico'!AD548 -> 303.8465 | O28: ='Resumen-DiarioHorario-Eólico'!AD608 -> 304.09217 | P28: ='Resumen-DiarioHorario-Eólico'!AD668 -> 193.46517 | Q28: ='Resumen-DiarioHorario-Eólico'!AD728 -> 298.76633 | R28: ='Resumen-DiarioHorario-Eólico'!AD788 -> 218.8305 | S28: ='Resumen-DiarioHorario-Eólico'!AD848 -> 274.98083 | T28: ='Resumen-DiarioHorario-Eólico'!AD908 -> 306.8985 | U28: ='Resumen-DiarioHorario-Eólico'!AD968 -> 327.65117 | V28: ='Resumen-DiarioHorario-Eólico'!AD1028 -> 127.4255 | W28: ='Resumen-DiarioHorario-Eólico'!AD1088 -> 185.5535 | X28: ='Resumen-DiarioHorario-Eólico'!AD1148 -> 131.55267 | Y28: ='Resumen-DiarioHorario-Eólico'!AD1208 -> 208.30917 | Z28: ='Resumen-DiarioHorario-Eólico'!AD1268 -> 313.16733 | AA28: ='Resumen-DiarioHorario-Eólico'!AD1328 -> 328.323 | AB28: ='Resumen-DiarioHorario-Eólico'!AD1388 -> 265.175 | AC28: ='Resumen-DiarioHorario-Eólico'!AD1448 -> 195.088 | AD28: ='Resumen-DiarioHorario-Eólico'!AD1508 -> 143.0985 | AE28: ='Resumen-DiarioHorario-Eólico'!AD1568 -> 277.46533 | AF28: ='Resumen-DiarioHorario-Eólico'!AD1627 -> 226.85817 | AG28: ='Resumen-DiarioHorario-Eólico'!AD1686 -> 306.227 | AH28: =+'Resumen-DiarioHorario-Eólico'!AD1745 -> 273.70333 | AI28: =+'Resumen-DiarioHorario-Eólico'!AD1804 -> 156.4225 | AK28: =SUM(E28:AI28) -> 6617.724
B29: PE-SIERRAGORDA | E29: ='Resumen-DiarioHorario-Eólico'!AD9 -> 146.39433 | F29: ='Resumen-DiarioHorario-Eólico'!AD69 -> 113.47983 | G29: ='Resumen-DiarioHorario-Eólico'!AD129 -> 143.9025 | H29: ='Resumen-DiarioHorario-Eólico'!AD189 -> 64.988667 | I29: ='Resumen-DiarioHorario-Eólico'!AD249 -> 157.47967 | J29: ='Resumen-DiarioHorario-Eólico'!AD309 -> 87.841 | K29: ='Resumen-DiarioHorario-Eólico'!AD369 -> 217.61783 | L29: ='Resumen-DiarioHorario-Eólico'!AD429 -> 190.01317 | M29: ='Resumen-DiarioHorario-Eólico'!AD489 -> 0 | N29: ='Resumen-DiarioHorario-Eólico'!AD549 -> 0 | O29: ='Resumen-DiarioHorario-Eólico'!AD609 -> 0 | P29: ='Resumen-DiarioHorario-Eólico'!AD669 -> 0 | Q29: ='Resumen-DiarioHorario-Eólico'!AD729 -> 0 | R29: ='Resumen-DiarioHorario-Eólico'!AD789 -> 268.11183 | S29: ='Resumen-DiarioHorario-Eólico'!AD849 -> 252.66433 | T29: ='Resumen-DiarioHorario-Eólico'!AD909 -> 327.25617 | U29: ='Resumen-DiarioHorario-Eólico'!AD969 -> 283.82317 | V29: ='Resumen-DiarioHorario-Eólico'!AD1029 -> 212.7235 | W29: ='Resumen-DiarioHorario-Eólico'!AD1089 -> 131.6485 | X29: ='Resumen-DiarioHorario-Eólico'!AD1149 -> 105.794 | Y29: ='Resumen-DiarioHorario-Eólico'!AD1209 -> 65.942 | Z29: ='Resumen-DiarioHorario-Eólico'!AD1269 -> 105.37683 | AA29: ='Resumen-DiarioHorario-Eólico'!AD1329 -> 194.70483 | AB29: ='Resumen-DiarioHorario-Eólico'!AD1389 -> 109.46 | AC29: ='Resumen-DiarioHorario-Eólico'!AD1449 -> 199.62217 | AD29: ='Resumen-DiarioHorario-Eólico'!AD1509 -> 184.70867 | AE29: ='Resumen-DiarioHorario-Eólico'!AD1569 -> 129.65517 | AF29: ='Resumen-DiarioHorario-Eólico'!AD1628 -> 306.43567 | AG29: ='Resumen-DiarioHorario-Eólico'!AD1687 -> 182.83567 | AH29: =+'Resumen-DiarioHorario-Eólico'!AD1746 -> 225.696 | AI29: =+'Resumen-DiarioHorario-Eólico'!AD1805 -> 274.87483 | AK29: =SUM(E29:AI29) -> 4683.0503
B30: PE-VALLEDELOSVIENTOS | E30: ='Resumen-DiarioHorario-Eólico'!AD10 -> 284.344 | F30: ='Resumen-DiarioHorario-Eólico'!AD70 -> 167.59583 | G30: ='Resumen-DiarioHorario-Eólico'!AD130 -> 189.48867 | H30: ='Resumen-DiarioHorario-Eólico'!AD190 -> 195.165 | I30: ='Resumen-DiarioHorario-Eólico'!AD250 -> 168.01283 | J30: ='Resumen-DiarioHorario-Eólico'!AD310 -> 338.7175 | K30: ='Resumen-DiarioHorario-Eólico'!AD370 -> 270.2695 | L30: ='Resumen-DiarioHorario-Eólico'!AD430 -> 216.5705 | M30: ='Resumen-DiarioHorario-Eólico'!AD490 -> 199.7145 | N30: ='Resumen-DiarioHorario-Eólico'!AD550 -> 277.936 | O30: ='Resumen-DiarioHorario-Eólico'!AD610 -> 383.42833 | P30: ='Resumen-DiarioHorario-Eólico'!AD670 -> 371.42083 | Q30: ='Resumen-DiarioHorario-Eólico'!AD730 -> 281.8475 | R30: ='Resumen-DiarioHorario-Eólico'!AD790 -> 315.9185 | S30: ='Resumen-DiarioHorario-Eólico'!AD850 -> 336.45567 | T30: ='Resumen-DiarioHorario-Eólico'!AD910 -> 373.574 | U30: ='Resumen-DiarioHorario-Eólico'!AD970 -> 299.244 | V30: ='Resumen-DiarioHorario-Eólico'!AD1030 -> 228.14967 | W30: ='Resumen-DiarioHorario-Eólico'!AD1090 -> 239.79617 | X30: ='Resumen-DiarioHorario-Eólico'!AD1150 -> 166.02933 | Y30: ='Resumen-DiarioHorario-Eólico'!AD1210 -> 238.25583 | Z30: ='Resumen-DiarioHorario-Eólico'!AD1270 -> 209.66083 | AA30: ='Resumen-DiarioHorario-Eólico'!AD1330 -> 198.077 | AB30: ='Resumen-DiarioHorario-Eólico'!AD1390 -> 190.5395 | AC30: ='Resumen-DiarioHorario-Eólico'!AD1450 -> 249.40883 | AD30: ='Resumen-DiarioHorario-Eólico'!AD1510 -> 271.73483 | AE30: ='Resumen-DiarioHorario-Eólico'!AD1570 -> 197.95433 | AF30: ='Resumen-DiarioHorario-Eólico'!AD1629 -> 141.5895 | AG30: ='Resumen-DiarioHorario-Eólico'!AD1688 -> 178.83283 | AH30: =+'Resumen-DiarioHorario-Eólico'!AD1747 -> 221.69117 | AI30: =+'Resumen-DiarioHorario-Eólico'!AD1806 -> 196.414 | AK30: =SUM(E30:AI30) -> 7597.837
B31: PE-CERROTIGRE | E31: ='Resumen-DiarioHorario-Eólico'!AD11 -> 386.68117 | F31: ='Resumen-DiarioHorario-Eólico'!AD71 -> 236.30017 | G31: ='Resumen-DiarioHorario-Eólico'!AD131 -> 330.489 | H31: ='Resumen-DiarioHorario-Eólico'!AD191 -> 214.007 | I31: ='Resumen-DiarioHorario-Eólico'!AD251 -> 256.54717 | J31: ='Resumen-DiarioHorario-Eólico'!AD311 -> 252.292 | K31: ='Resumen-DiarioHorario-Eólico'!AD371 -> 346.8295 | L31: ='Resumen-DiarioHorario-Eólico'!AD431 -> 276.294 | M31: ='Resumen-DiarioHorario-Eólico'!AD491 -> 283.82533 | N31: ='Resumen-DiarioHorario-Eólico'!AD551 -> 490.46567 | O31: ='Resumen-DiarioHorario-Eólico'!AD611 -> 489.627 | P31: ='Resumen-DiarioHorario-Eólico'!AD671 -> 387.89967 | Q31: ='Resumen-DiarioHorario-Eólico'!AD731 -> 534.60067 | R31: ='Resumen-DiarioHorario-Eólico'!AD791 -> 419.16033 | S31: ='Resumen-DiarioHorario-Eólico'!AD851 -> 531.393 | T31: ='Resumen-DiarioHorario-Eólico'!AD911 -> 692.9135 | U31: ='Resumen-DiarioHorario-Eólico'!AD971 -> 521.44567 | V31: ='Resumen-DiarioHorario-Eólico'!AD1031 -> 308.10783 | W31: ='Resumen-DiarioHorario-Eólico'!AD1091 -> 213.03067 | X31: ='Resumen-DiarioHorario-Eólico'!AD1151 -> 153.72533 | Y31: ='Resumen-DiarioHorario-Eólico'!AD1211 -> 97.756333 | Z31: ='Resumen-DiarioHorario-Eólico'!AD1271 -> 283.07033 | AA31: ='Resumen-DiarioHorario-Eólico'!AD1331 -> 446.825 | AB31: ='Resumen-DiarioHorario-Eólico'!AD1391 -> 176.371 | AC31: ='Resumen-DiarioHorario-Eólico'!AD1451 -> 342.19383 | AD31: ='Resumen-DiarioHorario-Eólico'!AD1511 -> 406.6025 | AE31: ='Resumen-DiarioHorario-Eólico'!AD1571 -> 216.289 | AF31: ='Resumen-DiarioHorario-Eólico'!AD1630 -> 397.51117 | AG31: ='Resumen-DiarioHorario-Eólico'!AD1689 -> 355.20183 | AH31: =+'Resumen-DiarioHorario-Eólico'!AD1748 -> 371.56183 | AI31: =+'Resumen-DiarioHorario-Eólico'!AD1807 -> 357.34883 | AK31: =SUM(E31:AI31) -> 10776.366
B32: PE-CALAMA | E32: ='Resumen-DiarioHorario-Eólico'!AD12 -> 202.084 | F32: ='Resumen-DiarioHorario-Eólico'!AD72 -> 265.9245 | G32: ='Resumen-DiarioHorario-Eólico'!AD132 -> 246.13983 | H32: ='Resumen-DiarioHorario-Eólico'!AD192 -> 203.04267 | I32: ='Resumen-DiarioHorario-Eólico'!AD252 -> 300.94483 | J32: ='Resumen-DiarioHorario-Eólico'!AD312 -> 565.95367 | K32: ='Resumen-DiarioHorario-Eólico'!AD372 -> 237.263 | L32: ='Resumen-DiarioHorario-Eólico'!AD432 -> 230.85333 | M32: ='Resumen-DiarioHorario-Eólico'!AD492 -> 247.533 | N32: ='Resumen-DiarioHorario-Eólico'!AD552 -> 339.24117 | O32: ='Resumen-DiarioHorario-Eólico'!AD612 -> 316.98983 | P32: ='Resumen-DiarioHorario-Eólico'!AD672 -> 220.68583 | Q32: ='Resumen-DiarioHorario-Eólico'!AD732 -> 274.352 | R32: ='Resumen-DiarioHorario-Eólico'!AD792 -> 299.41217 | S32: ='Resumen-DiarioHorario-Eólico'!AD852 -> 402.6415 | T32: ='Resumen-DiarioHorario-Eólico'!AD912 -> 356.44933 | U32: ='Resumen-DiarioHorario-Eólico'!AD972 -> 222.70567 | V32: ='Resumen-DiarioHorario-Eólico'!AD1032 -> 247.75667 | W32: ='Resumen-DiarioHorario-Eólico'!AD1092 -> 262.733 | X32: ='Resumen-DiarioHorario-Eólico'!AD1152 -> 263.23633 | Y32: ='Resumen-DiarioHorario-Eólico'!AD1212 -> 103.17467 | Z32: ='Resumen-DiarioHorario-Eólico'!AD1272 -> 41.276333 | AA32: ='Resumen-DiarioHorario-Eólico'!AD1332 -> 369.5625 | AB32: ='Resumen-DiarioHorario-Eólico'!AD1392 -> 105.54167 | AC32: ='Resumen-DiarioHorario-Eólico'!AD1452 -> 108.16567 | AD32: ='Resumen-DiarioHorario-Eólico'!AD1512 -> 166.59767 | AE32: ='Resumen-DiarioHorario-Eólico'!AD1572 -> 124.21433 | AF32: ='Resumen-DiarioHorario-Eólico'!AD1631 -> 189.55317 | AG32: ='Resumen-DiarioHorario-Eólico'!AD1690 -> 316.2005 | AH32: =+'Resumen-DiarioHorario-Eólico'!AD1749 -> 226.319 | AI32: =+'Resumen-DiarioHorario-Eólico'!AD1808 -> 147.9535 | AK32: =SUM(E32:AI32) -> 7604.5013
B33: PE-TALTAL | E33: ='Resumen-DiarioHorario-Eólico'!AD13 -> 0 | F33: ='Resumen-DiarioHorario-Eólico'!AD73 -> 19.464 | G33: ='Resumen-DiarioHorario-Eólico'!AD133 -> 95.599667 | H33: ='Resumen-DiarioHorario-Eólico'!AD193 -> 291.00833 | I33: ='Resumen-DiarioHorario-Eólico'!AD253 -> 0 | J33: ='Resumen-DiarioHorario-Eólico'!AD313 -> 15.530667 | K33: ='Resumen-DiarioHorario-Eólico'!AD373 -> 159.836 | L33: ='Resumen-DiarioHorario-Eólico'!AD433 -> 67.512167 | M33: ='Resumen-DiarioHorario-Eólico'!AD493 -> 273.59717 | N33: ='Resumen-DiarioHorario-Eólico'!AD553 -> 0 | O33: ='Resumen-DiarioHorario-Eólico'!AD613 -> 0 | P33: ='Resumen-DiarioHorario-Eólico'!AD673 -> 0 | Q33: ='Resumen-DiarioHorario-Eólico'!AD733 -> 155.25483 | R33: ='Resumen-DiarioHorario-Eólico'!AD793 -> 0 | S33: ='Resumen-DiarioHorario-Eólico'!AD853 -> 0 | T33: ='Resumen-DiarioHorario-Eólico'!AD913 -> 0 | U33: ='Resumen-DiarioHorario-Eólico'!AD973 -> 77.570333 | V33: ='Resumen-DiarioHorario-Eólico'!AD1033 -> 56.692667 | W33: ='Resumen-DiarioHorario-Eólico'!AD1093 -> 106.73683 | X33: ='Resumen-DiarioHorario-Eólico'!AD1153 -> 97.3405 | Y33: ='Resumen-DiarioHorario-Eólico'!AD1213 -> 100.60033 | Z33: ='Resumen-DiarioHorario-Eólico'!AD1273 -> 132.27933 | AA33: ='Resumen-DiarioHorario-Eólico'!AD1333 -> 123.74683 | AB33: ='Resumen-DiarioHorario-Eólico'!AD1393 -> 0 | AC33: ='Resumen-DiarioHorario-Eólico'!AD1453 -> 375.2045 | AD33: ='Resumen-DiarioHorario-Eólico'!AD1513 -> 312.1005 | AE33: ='Resumen-DiarioHorario-Eólico'!AD1573 -> 286.41767 | AF33: ='Resumen-DiarioHorario-Eólico'!AD1632 -> 294.23533 | AG33: ='Resumen-DiarioHorario-Eólico'!AD1691 -> 73.001 | AH33: =+'Resumen-DiarioHorario-Eólico'!AD1750 -> 13.254333 | AI33: =+'Resumen-DiarioHorario-Eólico'!AD1809 -> 141.72467 | AK33: =SUM(E33:AI33) -> 3268.7077
B34: PE-SARCO | E34: ='Resumen-DiarioHorario-Eólico'!AD14 -> 66.743667 | F34: ='Resumen-DiarioHorario-Eólico'!AD74 -> 46.5835 | G34: ='Resumen-DiarioHorario-Eólico'!AD134 -> 0.68216667 | H34: ='Resumen-DiarioHorario-Eólico'!AD194 -> 46.310333 | I34: ='Resumen-DiarioHorario-Eólico'!AD254 -> 232.152 | J34: ='Resumen-DiarioHorario-Eólico'!AD314 -> 86.190167 | K34: ='Resumen-DiarioHorario-Eólico'!AD374 -> 50.0485 | L34: ='Resumen-DiarioHorario-Eólico'!AD434 -> 59.32 | M34: ='Resumen-DiarioHorario-Eólico'!AD494 -> 57.764667 | N34: ='Resumen-DiarioHorario-Eólico'!AD554 -> 13.090167 | O34: ='Resumen-DiarioHorario-Eólico'!AD614 -> 6.4775 | P34: ='Resumen-DiarioHorario-Eólico'!AD674 -> 82.164833 | Q34: ='Resumen-DiarioHorario-Eólico'!AD734 -> 55.343 | R34: ='Resumen-DiarioHorario-Eólico'!AD794 -> 22.857333 | S34: ='Resumen-DiarioHorario-Eólico'!AD854 -> 134.64867 | T34: ='Resumen-DiarioHorario-Eólico'!AD914 -> 32.27 | U34: ='Resumen-DiarioHorario-Eólico'!AD974 -> 105.15917 | V34: ='Resumen-DiarioHorario-Eólico'!AD1034 -> 136.94183 | W34: ='Resumen-DiarioHorario-Eólico'!AD1094 -> 58.3175 | X34: ='Resumen-DiarioHorario-Eólico'!AD1154 -> 35.389167 | Y34: ='Resumen-DiarioHorario-Eólico'!AD1214 -> 50.4845 | Z34: ='Resumen-DiarioHorario-Eólico'!AD1274 -> 44.814667 | AA34: ='Resumen-DiarioHorario-Eólico'!AD1334 -> 113.94483 | AB34: ='Resumen-DiarioHorario-Eólico'!AD1394 -> 140.35333 | AC34: ='Resumen-DiarioHorario-Eólico'!AD1454 -> 80.661333 | AD34: ='Resumen-DiarioHorario-Eólico'!AD1514 -> 10.151167 | AE34: ='Resumen-DiarioHorario-Eólico'!AD1574 -> 35.672667 | AF34: ='Resumen-DiarioHorario-Eólico'!AD1633 -> 17.192167 | AG34: ='Resumen-DiarioHorario-Eólico'!AD1692 -> 58.3015 | AH34: =+'Resumen-DiarioHorario-Eólico'!AD1751 -> 90.483 | AI34: =+'Resumen-DiarioHorario-Eólico'!AD1810 -> 77.7565 | AK34: =SUM(E34:AI34) -> 2048.2698
B35: PE-CABOLEONES-1 | E35: ='Resumen-DiarioHorario-Eólico'!AD15 -> 72.535833 | F35: ='Resumen-DiarioHorario-Eólico'!AD75 -> 41.054 | G35: ='Resumen-DiarioHorario-Eólico'!AD135 -> 40.063667 | H35: ='Resumen-DiarioHorario-Eólico'!AD195 -> 87.216333 | I35: ='Resumen-DiarioHorario-Eólico'!AD255 -> 76.3055 | J35: ='Resumen-DiarioHorario-Eólico'!AD315 -> 42.870833 | K35: ='Resumen-DiarioHorario-Eólico'!AD375 -> 35.0215 | L35: ='Resumen-DiarioHorario-Eólico'!AD435 -> 69.6615 | M35: ='Resumen-DiarioHorario-Eólico'!AD495 -> 115.60667 | N35: ='Resumen-DiarioHorario-Eólico'!AD555 -> 37.598167 | O35: ='Resumen-DiarioHorario-Eólico'!AD615 -> 7.0653333 | P35: ='Resumen-DiarioHorario-Eólico'!AD675 -> 12.088667 | Q35: ='Resumen-DiarioHorario-Eólico'!AD735 -> 29.21 | R35: ='Resumen-DiarioHorario-Eólico'!AD795 -> 53.488833 | S35: ='Resumen-DiarioHorario-Eólico'!AD855 -> 101.92383 | T35: ='Resumen-DiarioHorario-Eólico'!AD915 -> 17.509 | U35: ='Resumen-DiarioHorario-Eólico'!AD975 -> 124.72667 | V35: ='Resumen-DiarioHorario-Eólico'!AD1035 -> 248.1755 | W35: ='Resumen-DiarioHorario-Eólico'!AD1095 -> 84.1955 | X35: ='Resumen-DiarioHorario-Eólico'!AD1155 -> 64.944 | Y35: ='Resumen-DiarioHorario-Eólico'!AD1215 -> 31.589333 | Z35: ='Resumen-DiarioHorario-Eólico'!AD1275 -> 36.753333 | AA35: ='Resumen-DiarioHorario-Eólico'!AD1335 -> 107.33517 | AB35: ='Resumen-DiarioHorario-Eólico'!AD1395 -> 158.04733 | AC35: ='Resumen-DiarioHorario-Eólico'!AD1455 -> 211.78533 | AD35: ='Resumen-DiarioHorario-Eólico'!AD1515 -> 11.477667 | AE35: ='Resumen-DiarioHorario-Eólico'!AD1575 -> 34.808833 | AF35: ='Resumen-DiarioHorario-Eólico'!AD1634 -> 61.777833 | AG35: ='Resumen-DiarioHorario-Eólico'!AD1693 -> 112.36167 | AH35: =+'Resumen-DiarioHorario-Eólico'!AD1752 -> 78.5115 | AI35: =+'Resumen-DiarioHorario-Eólico'!AD1811 -> 134.09117 | AK35: =SUM(E35:AI35) -> 2339.8005
B36: PE-CABOLEONES-2 | E36: ='Resumen-DiarioHorario-Eólico'!AD16 -> 301.331 | F36: ='Resumen-DiarioHorario-Eólico'!AD76 -> 198.018 | G36: ='Resumen-DiarioHorario-Eólico'!AD136 -> 90.509333 | H36: ='Resumen-DiarioHorario-Eólico'!AD196 -> 129.7195 | I36: ='Resumen-DiarioHorario-Eólico'!AD256 -> 199.2405 | J36: ='Resumen-DiarioHorario-Eólico'!AD316 -> 153.82133 | K36: ='Resumen-DiarioHorario-Eólico'!AD376 -> 180.26433 | L36: ='Resumen-DiarioHorario-Eólico'!AD436 -> 260.84033 | M36: ='Resumen-DiarioHorario-Eólico'!AD496 -> 225.44983 | N36: ='Resumen-DiarioHorario-Eólico'!AD556 -> 215.027 | O36: ='Resumen-DiarioHorario-Eólico'!AD616 -> 38.440833 | P36: ='Resumen-DiarioHorario-Eólico'!AD676 -> 173.74767 | Q36: ='Resumen-DiarioHorario-Eólico'!AD736 -> 190.58283 | R36: ='Resumen-DiarioHorario-Eólico'!AD796 -> 215.431 | S36: ='Resumen-DiarioHorario-Eólico'!AD856 -> 183.46433 | T36: ='Resumen-DiarioHorario-Eólico'!AD916 -> 194.68233 | U36: ='Resumen-DiarioHorario-Eólico'!AD976 -> 376.98033 | V36: ='Resumen-DiarioHorario-Eólico'!AD1036 -> 353.55833 | W36: ='Resumen-DiarioHorario-Eólico'!AD1096 -> 232.701 | X36: ='Resumen-DiarioHorario-Eólico'!AD1156 -> 263.32017 | Y36: ='Resumen-DiarioHorario-Eólico'!AD1216 -> 228.21817 | Z36: ='Resumen-DiarioHorario-Eólico'!AD1276 -> 232.2075 | AA36: ='Resumen-DiarioHorario-Eólico'!AD1336 -> 386.163 | AB36: ='Resumen-DiarioHorario-Eólico'!AD1396 -> 291.267 | AC36: ='Resumen-DiarioHorario-Eólico'!AD1456 -> 174.09333 | AD36: ='Resumen-DiarioHorario-Eólico'!AD1516 -> 173.21917 | AE36: ='Resumen-DiarioHorario-Eólico'!AD1576 -> 243.23883 | AF36: ='Resumen-DiarioHorario-Eólico'!AD1635 -> 189.96333 | AG36: ='Resumen-DiarioHorario-Eólico'!AD1694 -> 226.09633 | AH36: =+'Resumen-DiarioHorario-Eólico'!AD1753 -> 241.56933 | AI36: =+'Resumen-DiarioHorario-Eólico'!AD1812 -> 411.10733 | AK36: =SUM(E36:AI36) -> 6974.2733
B37: PE-CABOLEONES-3 | E37: ='Resumen-DiarioHorario-Eólico'!AD17 -> 68.393 | F37: ='Resumen-DiarioHorario-Eólico'!AD77 -> 42.594 | G37: ='Resumen-DiarioHorario-Eólico'!AD137 -> 38.069333 | H37: ='Resumen-DiarioHorario-Eólico'!AD197 -> 19.2135 | I37: ='Resumen-DiarioHorario-Eólico'!AD257 -> 362.09267 | J37: ='Resumen-DiarioHorario-Eólico'!AD317 -> 126.7225 | K37: ='Resumen-DiarioHorario-Eólico'!AD377 -> 196.5675 | L37: ='Resumen-DiarioHorario-Eólico'!AD437 -> 75.144167 | M37: ='Resumen-DiarioHorario-Eólico'!AD497 -> 71.246833 | N37: ='Resumen-DiarioHorario-Eólico'!AD557 -> 41.057 | O37: ='Resumen-DiarioHorario-Eólico'!AD617 -> 0.13566667 | P37: ='Resumen-DiarioHorario-Eólico'!AD677 -> 37.433 | Q37: ='Resumen-DiarioHorario-Eólico'!AD737 -> 62.6305 | R37: ='Resumen-DiarioHorario-Eólico'!AD797 -> 53.748667 | S37: ='Resumen-DiarioHorario-Eólico'!AD857 -> 130.6315 | T37: ='Resumen-DiarioHorario-Eólico'!AD917 -> 45.827333 | U37: ='Resumen-DiarioHorario-Eólico'!AD977 -> 104.02967 | V37: ='Resumen-DiarioHorario-Eólico'!AD1037 -> 185.91233 | W37: ='Resumen-DiarioHorario-Eólico'!AD1097 -> 91.001833 | X37: ='Resumen-DiarioHorario-Eólico'!AD1157 -> 80.485333 | Y37: ='Resumen-DiarioHorario-Eólico'!AD1217 -> 67.667 | Z37: ='Resumen-DiarioHorario-Eólico'!AD1277 -> 71.637667 | AA37: ='Resumen-DiarioHorario-Eólico'!AD1337 -> 234.871 | AB37: ='Resumen-DiarioHorario-Eólico'!AD1397 -> 221.05517 | AC37: ='Resumen-DiarioHorario-Eólico'!AD1457 -> 181.10033 | AD37: ='Resumen-DiarioHorario-Eólico'!AD1517 -> 44.367833 | AE37: ='Resumen-DiarioHorario-Eólico'!AD1577 -> 40.406 | AF37: ='Resumen-DiarioHorario-Eólico'!AD1636 -> 48.126833 | AG37: ='Resumen-DiarioHorario-Eólico'!AD1695 -> 175.57583 | AH37: =+'Resumen-DiarioHorario-Eólico'!AD1754 -> 144.12417 | AI37: =+'Resumen-DiarioHorario-Eólico'!AD1813 -> 138.97417 | AK37: =SUM(E37:AI37) -> 3200.8423
B38: PE-SANJUAN | E38: ='Resumen-DiarioHorario-Eólico'!AD18 -> 12.462333 | F38: ='Resumen-DiarioHorario-Eólico'!AD78 -> 8.0021667 | G38: ='Resumen-DiarioHorario-Eólico'!AD138 -> 0 | H38: ='Resumen-DiarioHorario-Eólico'!AD198 -> 148.95283 | I38: ='Resumen-DiarioHorario-Eólico'!AD258 -> 1146.3732 | J38: ='Resumen-DiarioHorario-Eólico'!AD318 -> 1090.181 | K38: ='Resumen-DiarioHorario-Eólico'!AD378 -> 86.148667 | L38: ='Resumen-DiarioHorario-Eólico'!AD438 -> 47.477667 | M38: ='Resumen-DiarioHorario-Eólico'!AD498 -> 10.886 | N38: ='Resumen-DiarioHorario-Eólico'!AD558 -> 22.731333 | O38: ='Resumen-DiarioHorario-Eólico'!AD618 -> 60.600833 | P38: ='Resumen-DiarioHorario-Eólico'!AD678 -> 47.395 | Q38: ='Resumen-DiarioHorario-Eólico'!AD738 -> 30.63 | R38: ='Resumen-DiarioHorario-Eólico'!AD798 -> 22.3395 | S38: ='Resumen-DiarioHorario-Eólico'!AD858 -> 371.06517 | T38: ='Resumen-DiarioHorario-Eólico'!AD918 -> 129.79667 | U38: ='Resumen-DiarioHorario-Eólico'!AD978 -> 100.69433 | V38: ='Resumen-DiarioHorario-Eólico'!AD1038 -> 67.547167 | W38: ='Resumen-DiarioHorario-Eólico'!AD1098 -> 49.878 | X38: ='Resumen-DiarioHorario-Eólico'!AD1158 -> 120.58567 | Y38: ='Resumen-DiarioHorario-Eólico'!AD1218 -> 129.07733 | Z38: ='Resumen-DiarioHorario-Eólico'!AD1278 -> 277.31 | AA38: ='Resumen-DiarioHorario-Eólico'!AD1338 -> 466.32133 | AB38: ='Resumen-DiarioHorario-Eólico'!AD1398 -> 273.54067 | AC38: ='Resumen-DiarioHorario-Eólico'!AD1458 -> 1354.472 | AD38: ='Resumen-DiarioHorario-Eólico'!AD1518 -> 1.8158333 | AE38: ='Resumen-DiarioHorario-Eólico'!AD1578 -> 113.97333 | AF38: ='Resumen-DiarioHorario-Eólico'!AD1637 -> 96.1835 | AG38: ='Resumen-DiarioHorario-Eólico'!AD1696 -> 369.521 | AH38: =+'Resumen-DiarioHorario-Eólico'!AD1755 -> 330.84183 | AI38: =+'Resumen-DiarioHorario-Eólico'!AD1814 -> 598.23983 | AK38: =SUM(E38:AI38) -> 7585.0442
B39: PE-PUNTACOLORADA | E39: ='Resumen-DiarioHorario-Eólico'!AD19 -> 0 | F39: ='Resumen-DiarioHorario-Eólico'!AD79 -> 0 | G39: ='Resumen-DiarioHorario-Eólico'!AD139 -> 0 | H39: ='Resumen-DiarioHorario-Eólico'!AD199 -> 0 | I39: ='Resumen-DiarioHorario-Eólico'!AD259 -> 0 | J39: ='Resumen-DiarioHorario-Eólico'!AD319 -> 0 | K39: ='Resumen-DiarioHorario-Eólico'!AD379 -> 0 | L39: ='Resumen-DiarioHorario-Eólico'!AD439 -> 0 | M39: ='Resumen-DiarioHorario-Eólico'!AD499 -> 0 | N39: ='Resumen-DiarioHorario-Eólico'!AD559 -> 0 | O39: ='Resumen-DiarioHorario-Eólico'!AD619 -> 0 | P39: ='Resumen-DiarioHorario-Eólico'!AD679 -> 0 | Q39: ='Resumen-DiarioHorario-Eólico'!AD739 -> 0 | R39: ='Resumen-DiarioHorario-Eólico'!AD799 -> 0 | S39: ='Resumen-DiarioHorario-Eólico'!AD859 -> 0 | T39: ='Resumen-DiarioHorario-Eólico'!AD919 -> 0 | U39: ='Resumen-DiarioHorario-Eólico'!AD979 -> 0 | V39: ='Resumen-DiarioHorario-Eólico'!AD1039 -> 0 | W39: ='Resumen-DiarioHorario-Eólico'!AD1099 -> 0 | X39: ='Resumen-DiarioHorario-Eólico'!AD1159 -> 0 | Y39: ='Resumen-DiarioHorario-Eólico'!AD1219 -> 0 | Z39: ='Resumen-DiarioHorario-Eólico'!AD1279 -> 0 | AA39: ='Resumen-DiarioHorario-Eólico'!AD1339 -> 0 | AB39: ='Resumen-DiarioHorario-Eólico'!AD1399 -> 0 | AC39: ='Resumen-DiarioHorario-Eólico'!AD1459 -> 0 | AD39: ='Resumen-DiarioHorario-Eólico'!AD1519 -> 0 | AE39: ='Resumen-DiarioHorario-Eólico'!AD1579 -> 0 | AF39: ='Resumen-DiarioHorario-Eólico'!AD1638 -> 0 | AG39: ='Resumen-DiarioHorario-Eólico'!AD1697 -> 0 | AH39: =+'Resumen-DiarioHorario-Eólico'!AD1756 -> 0 | AI39: =+'Resumen-DiarioHorario-Eólico'!AD1815 -> 0 | AK39: =SUM(E39:AI39) -> 0
... B72: PE-ATACAMA | E72: ='Resumen-DiarioHorario-Eólico'!AD52 -> 322.7185 | F72: ='Resumen-DiarioHorario-Eólico'!AD112 -> 38.787667 | G72: ='Resumen-DiarioHorario-Eólico'!AD172 -> 546.01683 | H72: ='Resumen-DiarioHorario-Eólico'!AD232 -> 190.14383 | I72: ='Resumen-DiarioHorario-Eólico'!AD292 -> 747.61717 | J72: ='Resumen-DiarioHorario-Eólico'!AD352 -> 681.15217 | K72: ='Resumen-DiarioHorario-Eólico'!AD412 -> 348.5545 | L72: ='Resumen-DiarioHorario-Eólico'!AD472 -> 167.296 | M72: ='Resumen-DiarioHorario-Eólico'!AD532 -> 90.955833 | N72: ='Resumen-DiarioHorario-Eólico'!AD592 -> 74.497333 | O72: ='Resumen-DiarioHorario-Eólico'!AD652 -> 71.693667 | P72: ='Resumen-DiarioHorario-Eólico'!AD712 -> 52.842833 | Q72: ='Resumen-DiarioHorario-Eólico'!AD772 -> 87.661333 | R72: ='Resumen-DiarioHorario-Eólico'!AD832 -> 28.011667 | S72: ='Resumen-DiarioHorario-Eólico'!AD892 -> 520.32933 | T72: ='Resumen-DiarioHorario-Eólico'!AD952 -> 197.467 | U72: ='Resumen-DiarioHorario-Eólico'!AD1012 -> 325.66683 | V72: ='Resumen-DiarioHorario-Eólico'!AD1072 -> 631.14667 | W72: ='Resumen-DiarioHorario-Eólico'!AD1132 -> 319.618 | X72: ='Resumen-DiarioHorario-Eólico'!AD1192 -> 436.13267 | Y72: ='Resumen-DiarioHorario-Eólico'!AD1252 -> 248.66467 | Z72: ='Resumen-DiarioHorario-Eólico'!AD1312 -> 126.1965 | AA72: ='Resumen-DiarioHorario-Eólico'!AD1372 -> 659.0605 | AB72: ='Resumen-DiarioHorario-Eólico'!AD1432 -> 662.94617 | AC72: ='Resumen-DiarioHorario-Eólico'!AD1492 -> 840.16417 | AD72: ='Resumen-DiarioHorario-Eólico'!AD1552 -> 266.13117 | AE72: ='Resumen-DiarioHorario-Eólico'!AD1612 -> 213.20017 | AF72: ='Resumen-DiarioHorario-Eólico'!AD1671 -> 455.90333 | AG72: ='Resumen-DiarioHorario-Eólico'!AD1730 -> 463.5625 | AH72: =+'Resumen-DiarioHorario-Eólico'!AD1789 -> 433.23417 | AI72: =+'Resumen-DiarioHorario-Eólico'!AD1848 -> 754.0355 | AK72: =SUM(E72:AI72) -> 11001.409
B73: PE-LACABANA | D73: † | E73: ='Resumen-DiarioHorario-Eólico'!AD53 -> 276.99167 | F73: ='Resumen-DiarioHorario-Eólico'!AD113 -> 0 | G73: ='Resumen-DiarioHorario-Eólico'!AD173 -> 0 | H73: ='Resumen-DiarioHorario-Eólico'!AD233 -> 0 | I73: ='Resumen-DiarioHorario-Eólico'!AD293 -> 0 | J73: ='Resumen-DiarioHorario-Eólico'!AD353 -> 0 | K73: ='Resumen-DiarioHorario-Eólico'!AD413 -> 0 | L73: ='Resumen-DiarioHorario-Eólico'!AD473 -> 0 | M73: ='Resumen-DiarioHorario-Eólico'!AD533 -> 0 | N73: ='Resumen-DiarioHorario-Eólico'!AD593 -> 0 | O73: ='Resumen-DiarioHorario-Eólico'!AD653 -> 0 | P73: ='Resumen-DiarioHorario-Eólico'!AD713 -> 0 | Q73: ='Resumen-DiarioHorario-Eólico'!AD773 -> 0 | R73: ='Resumen-DiarioHorario-Eólico'!AD833 -> 0 | S73: ='Resumen-DiarioHorario-Eólico'!AD893 -> 0 | T73: ='Resumen-DiarioHorario-Eólico'!AD953 -> 0 | U73: ='Resumen-DiarioHorario-Eólico'!AD1013 -> 0 | V73: ='Resumen-DiarioHorario-Eólico'!AD1073 -> 0 | W73: ='Resumen-DiarioHorario-Eólico'!AD1133 -> 0 | X73: ='Resumen-DiarioHorario-Eólico'!AD1193 -> 0 | Y73: ='Resumen-DiarioHorario-Eólico'!AD1253 -> 0 | Z73: ='Resumen-DiarioHorario-Eólico'!AD1313 -> 0 | AA73: ='Resumen-DiarioHorario-Eólico'!AD1373 -> 0 | AB73: ='Resumen-DiarioHorario-Eólico'!AD1433 -> 0 | AC73: ='Resumen-DiarioHorario-Eólico'!AD1493 -> 0 | AD73: ='Resumen-DiarioHorario-Eólico'!AD1553 -> 0 | AE73: ='Resumen-DiarioHorario-Eólico'!AD1613 -> 0 | AF73: ='Resumen-DiarioHorario-Eólico'!AD1672 -> 0 | AG73: ='Resumen-DiarioHorario-Eólico'!AD1731 -> 0 | AH73: =+'Resumen-DiarioHorario-Eólico'!AD1790 -> 0 | AI73: =+'Resumen-DiarioHorario-Eólico'!AD1849 -> 0 | AK73: =SUM(E73:AI73) -> 276.99167
B74: PE-SANMATIAS | E74: ='Resumen-DiarioHorario-Eólico'!AD54 -> 70.114 | F74: ='Resumen-DiarioHorario-Eólico'!AD114 -> 0.63166667 | G74: ='Resumen-DiarioHorario-Eólico'!AD174 -> 36.226 | H74: ='Resumen-DiarioHorario-Eólico'!AD234 -> 40.502333 | I74: ='Resumen-DiarioHorario-Eólico'!AD294 -> 7.0023333 | J74: ='Resumen-DiarioHorario-Eólico'!AD354 -> 140.7765 | K74: ='Resumen-DiarioHorario-Eólico'!AD414 -> 54.811833 | L74: ='Resumen-DiarioHorario-Eólico'!AD474 -> 286.7985 | M74: ='Resumen-DiarioHorario-Eólico'!AD534 -> 40.353167 | N74: ='Resumen-DiarioHorario-Eólico'!AD594 -> 19.192833 | O74: ='Resumen-DiarioHorario-Eólico'!AD654 -> 109.05667 | P74: ='Resumen-DiarioHorario-Eólico'!AD714 -> 211.53333 | Q74: ='Resumen-DiarioHorario-Eólico'!AD774 -> 6.6676667 | R74: ='Resumen-DiarioHorario-Eólico'!AD834 -> 0.61266667 | S74: ='Resumen-DiarioHorario-Eólico'!AD894 -> 0 | T74: ='Resumen-DiarioHorario-Eólico'!AD954 -> 14.756167 | U74: ='Resumen-DiarioHorario-Eólico'!AD1014 -> 125.1625 | V74: ='Resumen-DiarioHorario-Eólico'!AD1074 -> 195.40917 | W74: ='Resumen-DiarioHorario-Eólico'!AD1134 -> 2.409 | X74: ='Resumen-DiarioHorario-Eólico'!AD1194 -> 19.089 | Y74: ='Resumen-DiarioHorario-Eólico'!AD1254 -> 59.329333 | Z74: ='Resumen-DiarioHorario-Eólico'!AD1314 -> 76.224667 | AA74: ='Resumen-DiarioHorario-Eólico'!AD1374 -> 0 | AB74: ='Resumen-DiarioHorario-Eólico'!AD1434 -> 0 | AC74: ='Resumen-DiarioHorario-Eólico'!AD1494 -> 235.76267 | AD74: ='Resumen-DiarioHorario-Eólico'!AD1554 -> 122.409 | AE74: ='Resumen-DiarioHorario-Eólico'!AD1614 -> 60.692333 | AF74: ='Resumen-DiarioHorario-Eólico'!AD1673 -> 2.339 | AG74: ='Resumen-DiarioHorario-Eólico'!AD1732 -> 20.135833 | AH74: =+'Resumen-DiarioHorario-Eólico'!AD1791 -> 11.295 | AI74: =+'Resumen-DiarioHorario-Eólico'!AD1850 -> 5.257 | AK74: =SUM(E74:AI74) -> 1974.5502
B75: PE-CARDONAL | E75: ='Resumen-DiarioHorario-Eólico'!AD55 -> 37.442365 | F75: ='Resumen-DiarioHorario-Eólico'!AD115 -> 12.787433 | G75: ='Resumen-DiarioHorario-Eólico'!AD175 -> 0.62006 | H75: ='Resumen-DiarioHorario-Eólico'!AD235 -> 56.887442 | I75: ='Resumen-DiarioHorario-Eólico'!AD295 -> 23.313792 | J75: ='Resumen-DiarioHorario-Eólico'!AD355 -> 152.8605 | K75: ='Resumen-DiarioHorario-Eólico'!AD415 -> 85.574845 | L75: ='Resumen-DiarioHorario-Eólico'!AD475 -> 81.828167 | M75: ='Resumen-DiarioHorario-Eólico'!AD535 -> 30.152558 | N75: ='Resumen-DiarioHorario-Eólico'!AD595 -> 4.86891 | O75: ='Resumen-DiarioHorario-Eólico'!AD655 -> 0 | P75: ='Resumen-DiarioHorario-Eólico'!AD715 -> 26.087117 | Q75: ='Resumen-DiarioHorario-Eólico'!AD775 -> 53.901048 | R75: ='Resumen-DiarioHorario-Eólico'!AD835 -> 0.58484833 | S75: ='Resumen-DiarioHorario-Eólico'!AD895 -> 0.80560833 | T75: ='Resumen-DiarioHorario-Eólico'!AD955 -> 26.222922 | U75: ='Resumen-DiarioHorario-Eólico'!AD1015 -> 97.12704 | V75: ='Resumen-DiarioHorario-Eólico'!AD1075 -> 31.115073 | W75: ='Resumen-DiarioHorario-Eólico'!AD1135 -> 13.000378 | X75: ='Resumen-DiarioHorario-Eólico'!AD1195 -> 30.191647 | Y75: ='Resumen-DiarioHorario-Eólico'!AD1255 -> 39.643053 | Z75: ='Resumen-DiarioHorario-Eólico'!AD1315 -> 17.590207 | AA75: ='Resumen-DiarioHorario-Eólico'!AD1375 -> 0.005895 | AB75: ='Resumen-DiarioHorario-Eólico'!AD1435 -> 20.94199 | AC75: ='Resumen-DiarioHorario-Eólico'!AD1495 -> 140.81464 | AD75: ='Resumen-DiarioHorario-Eólico'!AD1555 -> 143.2544 | AE75: ='Resumen-DiarioHorario-Eólico'!AD1615 -> 46.22214 | AF75: ='Resumen-DiarioHorario-Eólico'!AD1674 -> 2.7064633 | AG75: ='Resumen-DiarioHorario-Eólico'!AD1733 -> 8.3482367 | AH75: =+'Resumen-DiarioHorario-Eólico'!AD1792 -> 40.522492 | AI75: =+'Resumen-DiarioHorario-Eólico'!AD1851 -> 12.074658 | AK75: =SUM(E75:AI75) -> 1237.4959
B76: PE-CERRILLOS | E76: ='Resumen-DiarioHorario-Eólico'!AD56 -> 3.36858 | F76: ='Resumen-DiarioHorario-Eólico'!AD116 -> 5.1213367 | G76: ='Resumen-DiarioHorario-Eólico'!AD176 -> 30.316 | H76: ='Resumen-DiarioHorario-Eólico'!AD236 -> 34.511967 | I76: ='Resumen-DiarioHorario-Eólico'!AD296 -> 22.35121 | J76: ='Resumen-DiarioHorario-Eólico'!AD356 -> 75.560023 | K76: ='Resumen-DiarioHorario-Eólico'!AD416 -> 22.6611 | L76: ='Resumen-DiarioHorario-Eólico'!AD476 -> 3.4027667 | M76: ='Resumen-DiarioHorario-Eólico'!AD536 -> 1.57008 | N76: ='Resumen-DiarioHorario-Eólico'!AD596 -> 0.083846667 | O76: ='Resumen-DiarioHorario-Eólico'!AD656 -> 0 | P76: ='Resumen-DiarioHorario-Eólico'!AD716 -> 6.1138567 | Q76: ='Resumen-DiarioHorario-Eólico'!AD776 -> 0.49688667 | R76: ='Resumen-DiarioHorario-Eólico'!AD836 -> 0.00043666667 | S76: ='Resumen-DiarioHorario-Eólico'!AD896 -> 0.75819667 | T76: ='Resumen-DiarioHorario-Eólico'!AD956 -> 2.917 | U76: ='Resumen-DiarioHorario-Eólico'!AD1016 -> 13.868377 | V76: ='Resumen-DiarioHorario-Eólico'!AD1076 -> 7.03476 | W76: ='Resumen-DiarioHorario-Eólico'!AD1136 -> 11.145297 | X76: ='Resumen-DiarioHorario-Eólico'!AD1196 -> 1.7296967 | Y76: ='Resumen-DiarioHorario-Eólico'!AD1256 -> 12.66857 | Z76: ='Resumen-DiarioHorario-Eólico'!AD1316 -> 29.933093 | AA76: ='Resumen-DiarioHorario-Eólico'!AD1376 -> 0.35902667 | AB76: ='Resumen-DiarioHorario-Eólico'!AD1436 -> 33.388497 | AC76: ='Resumen-DiarioHorario-Eólico'!AD1496 -> 83.531983 | AD76: ='Resumen-DiarioHorario-Eólico'!AD1556 -> 97.494827 | AE76: ='Resumen-DiarioHorario-Eólico'!AD1616 -> 12.506403 | AF76: ='Resumen-DiarioHorario-Eólico'!AD1675 -> 4.8003033 | AG76: ='Resumen-DiarioHorario-Eólico'!AD1734 -> 7.5413867 | AH76: =+'Resumen-DiarioHorario-Eólico'!AD1793 -> 21.586107 | AI76: =+'Resumen-DiarioHorario-Eólico'!AD1852 -> 2.1210733 | AK76: =SUM(E76:AI76) -> 548.94269
B77: PE-MANANTIALES | E77: ='Resumen-DiarioHorario-Eólico'!AD57 -> 8.844605 | F77: ='Resumen-DiarioHorario-Eólico'!AD117 -> 8.820355 | G77: ='Resumen-DiarioHorario-Eólico'!AD177 -> 50.922375 | H77: ='Resumen-DiarioHorario-Eólico'!AD237 -> 75.160137 | I77: ='Resumen-DiarioHorario-Eólico'!AD297 -> 38.665713 | J77: ='Resumen-DiarioHorario-Eólico'!AD357 -> 139.10305 | K77: ='Resumen-DiarioHorario-Eólico'!AD417 -> 47.575585 | L77: ='Resumen-DiarioHorario-Eólico'!AD477 -> 8.6427217 | M77: ='Resumen-DiarioHorario-Eólico'!AD537 -> 0.78137667 | N77: ='Resumen-DiarioHorario-Eólico'!AD597 -> 0.165775 | O77: ='Resumen-DiarioHorario-Eólico'!AD657 -> 0 | P77: ='Resumen-DiarioHorario-Eólico'!AD717 -> 13.693608 | Q77: ='Resumen-DiarioHorario-Eólico'!AD777 -> 2.3537933 | R77: ='Resumen-DiarioHorario-Eólico'!AD837 -> 0.002635 | S77: ='Resumen-DiarioHorario-Eólico'!AD897 -> 0.64717 | T77: ='Resumen-DiarioHorario-Eólico'!AD957 -> 1.4933017 | U77: ='Resumen-DiarioHorario-Eólico'!AD1017 -> 31.77231 | V77: ='Resumen-DiarioHorario-Eólico'!AD1077 -> 17.507262 | W77: ='Resumen-DiarioHorario-Eólico'!AD1137 -> 20.429537 | X77: ='Resumen-DiarioHorario-Eólico'!AD1197 -> 2.7409617 | Y77: ='Resumen-DiarioHorario-Eólico'!AD1257 -> 15.680302 | Z77: ='Resumen-DiarioHorario-Eólico'!AD1317 -> 45.944142 | AA77: ='Resumen-DiarioHorario-Eólico'!AD1377 -> 0.82431333 | AB77: ='Resumen-DiarioHorario-Eólico'!AD1437 -> 46.962428 | AC77: ='Resumen-DiarioHorario-Eólico'!AD1497 -> 142.23783 | AD77: ='Resumen-DiarioHorario-Eólico'!AD1557 -> 161.95638 | AE77: ='Resumen-DiarioHorario-Eólico'!AD1617 -> 24.329585 | AF77: ='Resumen-DiarioHorario-Eólico'!AD1676 -> 8.63789 | AG77: ='Resumen-DiarioHorario-Eólico'!AD1735 -> 11.391142 | AH77: =+'Resumen-DiarioHorario-Eólico'!AD1794 -> 31.425455 | AI77: =+'Resumen-DiarioHorario-Eólico'!AD1853 -> 0.647515 | AK77: =SUM(E77:AI77) -> 959.35924
B78: PE-KALLPA | E78: ='Resumen-DiarioHorario-Eólico'!AD58 -> 204.9025 | F78: ='Resumen-DiarioHorario-Eólico'!AD118 -> 330.40767 | G78: ='Resumen-DiarioHorario-Eólico'!AD178 -> 683.23933 | H78: ='Resumen-DiarioHorario-Eólico'!AD238 -> 76.890333 | I78: ='Resumen-DiarioHorario-Eólico'!AD298 -> 475.6995 | J78: ='Resumen-DiarioHorario-Eólico'!AD358 -> 202.802 | K78: ='Resumen-DiarioHorario-Eólico'!AD418 -> 948.24017 | L78: ='Resumen-DiarioHorario-Eólico'!AD478 -> 151.11983 | M78: ='Resumen-DiarioHorario-Eólico'!AD538 -> 387.009 | N78: ='Resumen-DiarioHorario-Eólico'!AD598 -> 102.141 | O78: ='Resumen-DiarioHorario-Eólico'!AD658 -> 317.38283 | P78: ='Resumen-DiarioHorario-Eólico'!AD718 -> 275.43433 | Q78: ='Resumen-DiarioHorario-Eólico'!AD778 -> 82.043333 | R78: ='Resumen-DiarioHorario-Eólico'!AD838 -> 336.8225 | S78: ='Resumen-DiarioHorario-Eólico'!AD898 -> 76.360667 | T78: ='Resumen-DiarioHorario-Eólico'!AD958 -> 487.56817 | U78: ='Resumen-DiarioHorario-Eólico'!AD1018 -> 296.13967 | V78: ='Resumen-DiarioHorario-Eólico'!AD1078 -> 378.27433 | W78: ='Resumen-DiarioHorario-Eólico'!AD1138 -> 536.69917 | X78: ='Resumen-DiarioHorario-Eólico'!AD1198 -> 351.34067 | Y78: ='Resumen-DiarioHorario-Eólico'!AD1258 -> 594.77817 | Z78: ='Resumen-DiarioHorario-Eólico'!AD1318 -> 345.46067 | AA78: ='Resumen-DiarioHorario-Eólico'!AD1378 -> 30.3825 | AB78: ='Resumen-DiarioHorario-Eólico'!AD1438 -> 285.37183 | AC78: ='Resumen-DiarioHorario-Eólico'!AD1498 -> 747.24183 | AD78: ='Resumen-DiarioHorario-Eólico'!AD1558 -> 1482.2348 | AE78: ='Resumen-DiarioHorario-Eólico'!AD1618 -> 1164.2833 | AF78: ='Resumen-DiarioHorario-Eólico'!AD1677 -> 392.72367 | AG78: ='Resumen-DiarioHorario-Eólico'!AD1736 -> 905.195 | AH78: =+'Resumen-DiarioHorario-Eólico'!AD1795 -> 674.1865 | AI78: =+'Resumen-DiarioHorario-Eólico'!AD1854 -> 2756.1452 | AK78: =SUM(E78:AI78) -> 16078.52
B79: PE-HORIZONTENORTE | E79: ='Resumen-DiarioHorario-Eólico'!AD59 -> 0 | F79: ='Resumen-DiarioHorario-Eólico'!AD119 -> 0 | G79: ='Resumen-DiarioHorario-Eólico'!AD179 -> 118.999 | H79: ='Resumen-DiarioHorario-Eólico'!AD239 -> 0 | I79: ='Resumen-DiarioHorario-Eólico'!AD299 -> 0 | J79: ='Resumen-DiarioHorario-Eólico'!AD359 -> 212.9075 | K79: ='Resumen-DiarioHorario-Eólico'!AD419 -> 1077.0958 | L79: ='Resumen-DiarioHorario-Eólico'!AD479 -> 277.98767 | M79: ='Resumen-DiarioHorario-Eólico'!AD539 -> 0 | N79: ='Resumen-DiarioHorario-Eólico'!AD599 -> 377.70417 | O79: ='Resumen-DiarioHorario-Eólico'!AD659 -> 167.874 | P79: ='Resumen-DiarioHorario-Eólico'!AD719 -> 226.38733 | Q79: ='Resumen-DiarioHorario-Eólico'!AD779 -> 561.941 | R79: ='Resumen-DiarioHorario-Eólico'!AD839 -> 569.123 | S79: ='Resumen-DiarioHorario-Eólico'!AD899 -> 745.30633 | T79: ='Resumen-DiarioHorario-Eólico'!AD959 -> 808.20667 | U79: ='Resumen-DiarioHorario-Eólico'!AD1019 -> 511.83117 | V79: ='Resumen-DiarioHorario-Eólico'!AD1079 -> 556.46367 | W79: ='Resumen-DiarioHorario-Eólico'!AD1139 -> 433.705 | X79: ='Resumen-DiarioHorario-Eólico'!AD1199 -> 315.89117 | Y79: ='Resumen-DiarioHorario-Eólico'!AD1259 -> 261.216 | Z79: ='Resumen-DiarioHorario-Eólico'!AD1319 -> 66.626667 | AA79: ='Resumen-DiarioHorario-Eólico'!AD1379 -> 198.116 | AB79: ='Resumen-DiarioHorario-Eólico'!AD1439 -> 809.17667 | AC79: ='Resumen-DiarioHorario-Eólico'!AD1499 -> 943.7345 | AD79: ='Resumen-DiarioHorario-Eólico'!AD1559 -> 1403.686 | AE79: ='Resumen-DiarioHorario-Eólico'!AD1619 -> 0 | AF79: ='Resumen-DiarioHorario-Eólico'!AD1678 -> 652.7665 | AG79: ='Resumen-DiarioHorario-Eólico'!AD1737 -> 0 | AH79: =+'Resumen-DiarioHorario-Eólico'!AD1796 -> 0 | AI79: =+'Resumen-DiarioHorario-Eólico'!AD1855 -> 1003.041 | AK79: =SUM(E79:AI79) -> 12299.787
B80: PE-HORIZONTESUR | E80: ='Resumen-DiarioHorario-Eólico'!AD60 -> 0 | F80: ='Resumen-DiarioHorario-Eólico'!AD120 -> 50.056 | G80: ='Resumen-DiarioHorario-Eólico'!AD180 -> 486.20867 | H80: ='Resumen-DiarioHorario-Eólico'!AD240 -> 690.8845 | I80: ='Resumen-DiarioHorario-Eólico'!AD300 -> 0 | J80: ='Resumen-DiarioHorario-Eólico'!AD360 -> 0 | K80: ='Resumen-DiarioHorario-Eólico'!AD420 -> 0 | L80: ='Resumen-DiarioHorario-Eólico'!AD480 -> 414.14883 | M80: ='Resumen-DiarioHorario-Eólico'!AD540 -> 580.80683 | N80: ='Resumen-DiarioHorario-Eólico'!AD600 -> 0 | O80: ='Resumen-DiarioHorario-Eólico'!AD660 -> 0 | P80: ='Resumen-DiarioHorario-Eólico'!AD720 -> 0 | Q80: ='Resumen-DiarioHorario-Eólico'!AD780 -> 1136.4925 | R80: ='Resumen-DiarioHorario-Eólico'!AD840 -> 0 | S80: ='Resumen-DiarioHorario-Eólico'!AD900 -> 0 | T80: ='Resumen-DiarioHorario-Eólico'!AD960 -> 0 | U80: ='Resumen-DiarioHorario-Eólico'!AD1020 -> 526.27733 | V80: ='Resumen-DiarioHorario-Eólico'!AD1080 -> 719.13467 | W80: ='Resumen-DiarioHorario-Eólico'!AD1140 -> 373.11283 | X80: ='Resumen-DiarioHorario-Eólico'!AD1200 -> 593.85367 | Y80: ='Resumen-DiarioHorario-Eólico'!AD1260 -> 308.499 | Z80: ='Resumen-DiarioHorario-Eólico'!AD1320 -> 367.868 | AA80: ='Resumen-DiarioHorario-Eólico'!AD1380 -> 188.384 | AB80: ='Resumen-DiarioHorario-Eólico'!AD1440 -> 1069.1957 | AC80: ='Resumen-DiarioHorario-Eólico'!AD1500 -> 818.78967 | AD80: ='Resumen-DiarioHorario-Eólico'!AD1560 -> 1753.1827 | AE80: ='Resumen-DiarioHorario-Eólico'!AD1620 -> 1401.6222 | AF80: ='Resumen-DiarioHorario-Eólico'!AD1679 -> 1634.2802 | AG80: ='Resumen-DiarioHorario-Eólico'!AD1738 -> 334.1845 | AH80: =+'Resumen-DiarioHorario-Eólico'!AD1797 -> 26.602833 | AI80: =+'Resumen-DiarioHorario-Eólico'!AD1856 -> 450.18983 | AK80: =SUM(E80:AI80) -> 13923.774
B81: PE-PUNTADETALCA | E81: ='Resumen-DiarioHorario-Eólico'!AD61 -> 0 | F81: ='Resumen-DiarioHorario-Eólico'!AD121 -> 0.685 | G81: ='Resumen-DiarioHorario-Eólico'!AD181 -> 99.706667 | H81: ='Resumen-DiarioHorario-Eólico'!AD241 -> 46.958 | I81: ='Resumen-DiarioHorario-Eólico'!AD301 -> 0 | J81: ='Resumen-DiarioHorario-Eólico'!AD361 -> 0 | K81: ='Resumen-DiarioHorario-Eólico'!AD421 -> 0 | L81: ='Resumen-DiarioHorario-Eólico'!AD481 -> 46.886167 | M81: ='Resumen-DiarioHorario-Eólico'!AD541 -> 26.700833 | N81: ='Resumen-DiarioHorario-Eólico'!AD601 -> 0 | O81: ='Resumen-DiarioHorario-Eólico'!AD661 -> 0 | P81: ='Resumen-DiarioHorario-Eólico'!AD721 -> 0 | Q81: ='Resumen-DiarioHorario-Eólico'!AD781 -> 21.680167 | R81: ='Resumen-DiarioHorario-Eólico'!AD841 -> 0 | S81: ='Resumen-DiarioHorario-Eólico'!AD901 -> 0 | T81: ='Resumen-DiarioHorario-Eólico'!AD961 -> 0 | U81: ='Resumen-DiarioHorario-Eólico'!AD1021 -> 110.05867 | V81: ='Resumen-DiarioHorario-Eólico'!AD1081 -> 56.021833 | W81: ='Resumen-DiarioHorario-Eólico'!AD1141 -> 44.5965 | X81: ='Resumen-DiarioHorario-Eólico'!AD1201 -> 216.44983 | Y81: ='Resumen-DiarioHorario-Eólico'!AD1261 -> 0 | Z81: ='Resumen-DiarioHorario-Eólico'!AD1321 -> 164.165 | AA81: ='Resumen-DiarioHorario-Eólico'!AD1381 -> 363.36117 | AB81: ='Resumen-DiarioHorario-Eólico'!AD1441 -> 0 | AC81: ='Resumen-DiarioHorario-Eólico'!AD1501 -> 766.43233 | AD81: ='Resumen-DiarioHorario-Eólico'!AD1561 -> 335.3695 | AE81: ='Resumen-DiarioHorario-Eólico'!AD1621 -> 64.0455 | AF81: ='Resumen-DiarioHorario-Eólico'!AD1680 -> 68.394667 | AG81: ='Resumen-DiarioHorario-Eólico'!AD1739 -> 90.506833 | AH81: =+'Resumen-DiarioHorario-Eólico'!AD1798 -> 50.6375 | AI81: =+'Resumen-DiarioHorario-Eólico'!AD1857 -> 152.43633 | AK81: =SUM(E81:AI81) -> 2725.0925
...

Sheet Resumen-DiarioHorario-Eólico
B2: CURTAILMENTS EÓLICAS POR CENTRALES EN FORMA DIARIA/HORARIA
B5: ='Resumen-Mensual'!$E$26 -> 45931
B7: Central/Hora | E7: 1 | F7: 2 | G7: 3 | H7: 4 | I7: 5 | J7: 6 | K7: 7 | L7: 8 | M7: 9 | N7: 10 | O7: 11 | P7: 12 | Q7: 13 | R7: 14 | S7: 15 | T7: 16 | U7: 17 | V7: 18 | W7: 19 | X7: 20 | Y7: 21 | Z7: 22 | AA7: 23 | AB7: 24 | AC7: Total
B8: PE-TCHAMMA | E8: 0 | F8: 0 | G8: 0 | H8: 0 | I8: 0 | J8: 0 | K8: 0 | L8: 4.5985 | M8: 36.049333 | N8: 43.1325 | O8: 11.551333 | P8: 3.8343333 | Q8: 9.3226667 | R8: 23.3755 | S8: 23.0095 | T8: 5.0933333 | U8: 10.611 | V8: 14.542667 | W8: 3.1461667 | X8: 0 | Y8: 0 | Z8: 0 | AA8: 0 | AB8: 0 | AD8: =SUM(E8:AB8) -> 188.26683
B9: PE-SIERRAGORDA | E9: 0 | F9: 0 | G9: 0 | H9: 0 | I9: 0 | J9: 0 | K9: 0 | L9: 1.7333333 | M9: 16.814833 | N9: 16.306833 | O9: 16.543333 | P9: 10.756167 | Q9: 17.009667 | R9: 17.399333 | S9: 11.826333 | T9: 19.219833 | U9: 0.12433333 | V9: 6.9048333 | W9: 11.7555 | X9: 0 | Y9: 0 | Z9: 0 | AA9: 0 | AB9: 0 | AD9: =SUM(E9:AB9) -> 146.39433
B10: PE-VALLEDELOSVIENTOS | E10: 0 | F10: 0 | G10: 0 | H10: 0 | I10: 0 | J10: 0 | K10: 0 | L10: 1.134 | M10: 8.87 | N10: 5.55 | O10: 2.35 | P10: 3.58 | Q10: 13.74 | R10: 34.83 | S10: 56.61 | T10: 29.88 | U10: 44.867833 | V10: 43.343333 | W10: 39.588833 | X10: 0 | Y10: 0 | Z10: 0 | AA10: 0 | AB10: 0 | AD10: =SUM(E10:AB10) -> 284.344
B11: PE-CERROTIGRE | E11: 0 | F11: 0 | G11: 0 | H11: 0 | I11: 0 | J11: 0 | K11: 0 | L11: 0.37333333 | M11: 1.6 | N11: 0.2 | O11: 0 | P11: 0.3 | Q11: 10.5 | R11: 52.066 | S11: 91.895333 | T11: 54.0445 | U11: 56.164167 | V11: 76.648 | W11: 42.889833 | X11: 0 | Y11: 0 | Z11: 0 | AA11: 0 | AB11: 0 | AD11: =SUM(E11:AB11) -> 386.68117
B12: PE-CALAMA | E12: 0 | F12: 0 | G12: 0 | H12: 0 | I12: 0 | J12: 0 | K12: 0 | L12: 0.25666667 | M12: 1.9095 | N12: 2.8458333 | O12: 1.6008333 | P12: 5.4536667 | Q12: 21.335833 | R12: 36.594833 | S12: 40.0275 | T12: 36.1335 | U12: 0 | V12: 31.15 | W12: 24.775833 | X12: 0 | Y12: 0 | Z12: 0 | AA12: 0 | AB12: 0 | AD12: =SUM(E12:AB12) -> 202.084
B13: PE-TALTAL | E13: 0 | F13: 0 | G13: 0 | H13: 0 | I13: 0 | J13: 0 | K13: 0 | L13: 0 | M13: 0 | N13: 0 | O13: 0 | P13: 0 | Q13: 0 | R13: 0 | S13: 0 | T13: 0 | U13: 0 | V13: 0 | W13: 0 | X13: 0 | Y13: 0 | Z13: 0 | AA13: 0 | AB13: 0 | AD13: =SUM(E13:AB13) -> 0
B14: PE-SARCO | E14: 0 | F14: 0 | G14: 0 | H14: 0 | I14: 0 | J14: 0 | K14: 0 | L14: 0.30066667 | M14: 9.4455 | N14: 9.5226667 | O14: 0.1015 | P14: 5.7505 | Q14: 11.730833 | R14: 11.418667 | S14: 7.4335 | T14: 5.7803333 | U14: 4.0815 | V14: 1.178 | W14: 0 | X14: 0 | Y14: 0 | Z14: 0 | AA14: 0 | AB14: 0 | AD14: =SUM(E14:AB14) -> 66.743667
B15: PE-CABOLEONES-1 | E15: 0 | F15: 0 | G15: 0 | H15: 0 | I15: 0 | J15: 0 | K15: 0 | L15: 0.34433333 | M15: 7.0398333 | N15: 12.021167 | O15: 11.257 | P15: 7.1201667 | Q15: 11.319333 | R15: 11.582167 | S15: 7.1755 | T15: 4.2868333 | U15: 0.3895 | V15: 0 | W15: 0 | X15: 0 | Y15: 0 | Z15: 0 | AA15: 0 | AB15: 0 | AD15: =SUM(E15:AB15) -> 72.535833
B16: PE-CABOLEONES-2 | E16: 0 | F16: 0 | G16: 0 | H16: 0 | I16: 0 | J16: 0 | K16: 0 | L16: 0.868 | M16: 13.64 | N16: 29.087 | O16: 39.093333 | P16: 30.352 | Q16: 34.520167 | R16: 37.725833 | S16: 36.3 | T16: 30.5115 | U16: 20.069333 | V16: 15.901167 | W16: 13.262667 | X16: 0 | Y16: 0 | Z16: 0 | AA16: 0 | AB16: 0 | AD16: =SUM(E16:AB16) -> 301.331
B17: PE-CABOLEONES-3 | E17: 0 | F17: 0 | G17: 0 | H17: 0 | I17: 0 | J17: 0 | K17: 0 | L17: 0.381 | M17: 8.5285 | N17: 10.713333 | O17: 10.5285 | P17: 6.6706667 | Q17: 8.6306667 | R17: 8.0063333 | S17: 3.8093333 | T17: 1.8876667 | U17: 2.082 | V17: 6.523 | W17: 0.632 | X17: 0 | Y17: 0 | Z17: 0 | AA17: 0 | AB17: 0 | AD17: =SUM(E17:AB17) -> 68.393
B18: PE-SANJUAN | E18: 0 | F18: 0 | G18: 0 | H18: 0 | I18: 0 | J18: 0 | K18: 0 | L18: 0.28233333 | M18: 1.001 | N18: 0.2765 | O18: 0 | P18: 0.21983333 | Q18: 0.96633333 | R18: 0.88983333 | S18: 2.9353333 | T18: 4.371 | U18: 0.80183333 | V18: 0.687 | W18: 0.031333333 | X18: 0 | Y18: 0 | Z18: 0 | AA18: 0 | AB18: 0 | AD18: =SUM(E18:AB18) -> 12.462333
B19: PE-PUNTACOLORADA | E19: 0 | F19: 0 | G19: 0 | H19: 0 | I19: 0 | J19: 0 | K19: 0 | L19: 0 | M19: 0 | N19: 0 | O19: 0 | P19: 0 | Q19: 0 | R19: 0 | S19: 0 | T19: 0 | U19: 0 | V19: 0 | W19: 0 | X19: 0 | Y19: 0 | Z19: 0 | AA19: 0 | AB19: 0 | AD19: =SUM(E19:AB19) -> 0
... B61: PE-PUNTADETALCA | E61: 0 | F61: 0 | G61: 0 | H61: 0 | I61: 0 | J61: 0 | K61: 0 | L61: 0 | M61: 0 | N61: 0 | O61: 0 | P61: 0 | Q61: 0 | R61: 0 | S61: 0 | T61: 0 | U61: 0 | V61: 0 | W61: 0 | X61: 0 | Y61: 0 | Z61: 0 | AA61: 0 | AB61: 0 | AD61: =SUM(E61:AB61) -> 0
B62: Total | E62: =SUM(E8:E61) -> 335.68667 | F62: =SUM(F8:F61) -> 174.34067 | G62: =SUM(G8:G61) -> 158.719 | H62: =SUM(H8:H61) -> 157.55117 | I62: =SUM(I8:I61) -> 147.524 | J62: =SUM(J8:J61) -> 131.85833 | K62: =SUM(K8:K61) -> 163.97467 | L62: =SUM(L8:L61) -> 159.81828 | ... AB62: =SUM(AB8:AB61) -> 0 | AC62: =SUM(AC8:AE61) -> 5511.0457
B65: ='Resumen-Mensual'!$F$26 -> 45932
B67: Central/Hora | E67: 1 | F67: 2 | G67: 3 | H67: 4 | I67: 5 | J67: 6 | K67: 7 | L67: 8 | M67: 9 | N67: 10 | O67: 11 | P67: 12 | Q67: 13 | R67: 14 | S67: 15 | T67: 16 | U67: 17 | V67: 18 | W67: 19 | X67: 20 | Y67: 21 | Z67: 22 | AA67: 23 | AB67: 24 | AC67: Total
B68: PE-TCHAMMA | E68: 0 | F68: 0 | G68: 0 | H68: 0 | I68: 0 | J68: 0 | K68: 0 | L68: 0 | M68: 12.757667 | N68: 0.38883333 | O68: 1.62 | P68: 3.283 | Q68: 7.2723333 | R68: 14.023667 | S68: 5.3796667 | T68: 0.056666667 | U68: 6.2025 | V68: 6.009 | W68: 3.781 | X68: 0 | Y68: 0 | Z68: 0 | AA68: 0 | AB68: 0 | AD68: =SUM(E68:AB68) -> 60.774333
B69: PE-SIERRAGORDA | E69: 0 | F69: 0 | G69: 0 | H69: 0 | I69: 0 | J69: 0 | K69: 0 | L69: 1.8323333 | M69: 31.762 | N69: 15.535333 | O69: 5.6715 | P69: 6.7073333 | Q69: 10.031167 | R69: 11.920667 | S69: 14.889333 | T69: 5.5721667 | U69: 0.566 | V69: 6.724 | W69: 2.268 | X69: 0 | Y69: 0 | Z69: 0 | AA69: 0 | AB69: 0 | AD69: =SUM(E69:AB69) -> 113.47983
B70: PE-VALLEDELOSVIENTOS | E70: 0 | F70: 0 | G70: 0 | H70: 0 | I70: 0 | J70: 0 | K70: 0 | L70: 0 | M70: 2.7165 | N70: 9.2158333 | O70: 2.155 | P70: 1.915 | Q70: 4.4393333 | R70: 12.346667 | S70: 23.345 | T70: 32.32 | U70: 23.1495 | V70: 34.153333 | W70: 21.839667 | X70: 0 | Y70: 0 | Z70: 0 | AA70: 0 | AB70: 0 | AD70: =SUM(E70:AB70) -> 167.59583
B71: PE-CERROTIGRE | E71: 0 | F71: 0 | G71: 0 | H71: 0 | I71: 0 | J71: 0 | K71: 0 | L71: 0.36 | M71: 1.9555 | N71: 0.9895 | O71: 0.1 | P71: 0.41116667 | Q71: 5.8 | R71: 45.8515 | S71: 50.303333 | T71: 20.381167 | U71: 23.610167 | V71: 68.586667 | W71: 17.951167 | X71: 0 | Y71: 0 | Z71: 0 | AA71: 0 | AB71: 0 | AD71: =SUM(E71:AB71) -> 236.30017
B72: PE-CALAMA | E72: 0 | F72: 0 | G72: 0 | H72: 0 | I72: 0 | J72: 0 | K72: 0 | L72: 0.5955 | M72: 16.985 | N72: 21.532 | O72: 3.4003333 | P72: 1.6705 | Q72: 9.5928333 | R72: 31.631333 | S72: 60.626167 | T72: 74.889167 | U72: 37.653333 | V72: 6.6493333 | W72: 0.699 | X72: 0 | Y72: 0 | Z72: 0 | AA72: 0 | AB72: 0 | AD72: =SUM(E72:AB72) -> 265.9245
B73: PE-TALTAL | E73: 0 | F73: 0 | G73: 0 | H73: 0 | I73: 0 | J73: 0 | K73: 0 | L73: 0 | M73: 0 | N73: 0 | O73: 0 | P73: 0 | Q73: 0 | R73: 0 | S73: 0 | T73: 0 | U73: 0 | V73: 10.098833 | W73: 9.3651667 | X73: 0 | Y73: 0 | Z73: 0 | AA73: 0 | AB73: 0 | AD73: =SUM(E73:AB73) -> 19.464
B74: PE-SARCO | E74: 0 | F74: 0 | G74: 0 | H74: 0 | I74: 0 | J74: 0 | K74: 0 | L74: 0.049333333 | M74: 1.728 | N74: 4.4851667 | O74: 8.5605 | P74: 5.2675 | Q74: 9.4871667 | R74: 8.9558333 | S74: 3.4541667 | T74: 3.2668333 | U74: 1.329 | V74: 0 | W74: 0 | X74: 0 | Y74: 0 | Z74: 0 | AA74: 0 | AB74: 0 | AD74: =SUM(E74:AB74) -> 46.5835
B75: PE-CABOLEONES-1 | E75: 0 | F75: 0 | G75: 0 | H75: 0 | I75: 0 | J75: 0 | K75: 0 | L75: 0.094166667 | M75: 1.7068333 | N75: 3.5396667 | O75: 5.583 | P75: 4.9281667 | Q75: 9.1081667 | R75: 7.9961667 | S75: 4.73 | T75: 2.8806667 | U75: 0.48716667 | V75: 0 | W75: 0 | X75: 0 | Y75: 0 | Z75: 0 | AA75: 0 | AB75: 0 | AD75: =SUM(E75:AB75) -> 41.054
B76: PE-CABOLEONES-2 | E76: 0 | F76: 0 | G76: 0 | H76: 0 | I76: 0 | J76: 0 | K76: 0 | L76: 0.488 | M76: 7.88 | N76: 9.18 | O76: 19.8045 | P76: 24.734 | Q76: 28.509 | R76: 26.241333 | S76: 24.187833 | T76: 20.190833 | U76: 16.001167 | V76: 8.7693333 | W76: 12.032 | X76: 0 | Y76: 0 | Z76: 0 | AA76: 0 | AB76: 0 | AD76: =SUM(E76:AB76) -> 198.018
B77: PE-CABOLEONES-3 | E77: 0 | F77: 0 | G77: 0 | H77: 0 | I77: 0 | J77: 0 | K77: 0 | L77: 0.25983333 | M77: 3.1751667 | N77: 4.2041667 | O77: 6.5683333 | P77: 7.1705 | Q77: 7.566 | R77: 6.6866667 | S77: 3.7978333 | T77: 2.4385 | U77: 0.19483333 | V77: 0 | W77: 0.53216667 | X77: 0 | Y77: 0 | Z77: 0 | AA77: 0 | AB77: 0 | AD77: =SUM(E77:AB77) -> 42.594
B78: PE-SANJUAN | E78: 0 | F78: 0 | G78: 0 | H78: 0 | I78: 0 | J78: 0 | K78: 0 | L78: 0 | M78: 0.0405 | N78: 0 | O78: 0.15 | P78: 0.00083333333 | Q78: 0.29216667 | R78: 0.5345 | S78: 2.272 | T78: 4.4333333 | U78: 0.27883333 | V78: 0 | W78: 0 | X78: 0 | Y78: 0 | Z78: 0 | AA78: 0 | AB78: 0 | AD78: =SUM(E78:AB78) -> 8.0021667
B79: PE-PUNTACOLORADA | E79: 0 | F79: 0 | G79: 0 | H79: 0 | I79: 0 | J79: 0 | K79: 0 | L79: 0 | M79: 0 | N79: 0 | O79: 0 | P79: 0 | Q79: 0 | R79: 0 | S79: 0 | T79: 0 | U79: 0 | V79: 0 | W79: 0 | X79: 0 | Y79: 0 | Z79: 0 | AA79: 0 | AB79: 0 | AD79: =SUM(E79:AB79) -> 0
... B121: PE-PUNTADETALCA | E121: 0 | F121: 0 | G121: 0 | H121: 0 | I121: 0 | J121: 0 | K121: 0 | L121: 0 | M121: 0 | N121: 0 | O121: 0 | P121: 0 | Q121: 0 | R121: 0 | S121: 0 | T121: 0 | U121: 0.47433333 | V121: 0.20966667 | W121: 0 | X121: 0.001 | Y121: 0 | Z121: 0 | AA121: 0 | AB121: 0 | AD121: =SUM(E121:AB121) -> 0.685
B122: Total | E122: =SUM(E68:E121) -> 0 | F122: =SUM(F68:F121) -> 0 | G122: =SUM(G68:G121) -> 0 | H122: =SUM(H68:H121) -> 0 | I122: =SUM(I68:I121) -> 0 | J122: =SUM(J68:J121) -> 0 | K122: =SUM(K68:K121) -> 0 | L122: =SUM(L68:L121) -> 15.236887 | ... AB122: =SUM(AB68:AB121) -> 0 | AC122: =SUM(AC68:AE121) -> 2682.814
B125: ='Resumen-Mensual'!$G$26 -> 45933
B127: Central/Hora | E127: 1 | F127: 2 | G127: 3 | H127: 4 | I127: 5 | J127: 6 | K127: 7 | L127: 8 | M127: 9 | N127: 10 | O127: 11 | P127: 12 | Q127: 13 | R127: 14 | S127: 15 | T127: 16 | U127: 17 | V127: 18 | W127: 19 | X127: 20 | Y127: 21 | Z127: 22 | AA127: 23 | AB127: 24 | AC127: Total
B128: PE-TCHAMMA | E128: 0 | F128: 0 | G128: 0 | H128: 0 | I128: 0 | J128: 0 | K128: 0 | L128: 0 | M128: 0 | N128: 3.883 | O128: 0.57433333 | P128: 3.7008333 | Q128: 9.6306667 | R128: 3.8606667 | S128: 8.908 | T128: 11.294167 | U128: 18.005333 | V128: 24.644167 | W128: 12.659 | X128: 0 | Y128: 0 | Z128: 0 | AA128: 0 | AB128: 0 | AD128: =SUM(E128:AB128) -> 97.160167
B129: PE-SIERRAGORDA | E129: 0 | F129: 0 | G129: 0 | H129: 0 | I129: 0 | J129: 0 | K129: 0 | L129: 0 | M129: 0 | N129: 9.0003333 | O129: 8.0171667 | P129: 11.586167 | Q129: 17.784667 | R129: 7.913 | S129: 4.0535 | T129: 25.137167 | U129: 33.207667 | V129: 25.789833 | W129: 1.413 | X129: 0 | Y129: 0 | Z129: 0 | AA129: 0 | AB129: 0 | AD129: =SUM(E129:AB129) -> 143.9025
B130: PE-VALLEDELOSVIENTOS | E130: 0 | F130: 0 | G130: 0 | H130: 0 | I130: 0 | J130: 0 | K130: 0 | L130: 0 | M130: 0 | N130: 0.298 | O130: 1.1033333 | P130: 5.1396667 | Q130: 12.760667 | R130: 19.5085 | S130: 25.287667 | T130: 31.211333 | U130: 34.485667 | V130: 35.177667 | W130: 24.516167 | X130: 0 | Y130: 0 | Z130: 0 | AA130: 0 | AB130: 0 | AD130: =SUM(E130:AB130) -> 189.48867
B131: PE-CERROTIGRE | E131: 0 | F131: 0 | G131: 0 | H131: 0 | I131: 0 | J131: 0 | K131: 0 | L131: 0 | M131: 0.67783333 | N131: 0.23916667 | O131: 1.2955 | P131: 3.1 | Q131: 20.854833 | R131: 42.606333 | S131: 35.890333 | T131: 61.618333 | U131: 35.896 | V131: 75.2075 | W131: 53.103167 | X131: 0 | Y131: 0 | Z131: 0 | AA131: 0 | AB131: 0 | AD131: =SUM(E131:AB131) -> 330.489
B132: PE-CALAMA | E132: 0 | F132: 0 | G132: 0 | H132: 0 | I132: 0 | J132: 0 | K132: 0 | L132: 0 | M132: 0 | N132: 0.19616667 | O132: 0.9255 | P132: 8.8518333 | Q132: 27.945333 | R132: 51.937167 | S132: 52.098833 | T132: 48.919667 | U132: 2.8523333 | V132: 4.6216667 | W132: 47.791333 | X132: 0 | Y132: 0 | Z132: 0 | AA132: 0 | AB132: 0 | AD132: =SUM(E132:AB132) -> 246.13983
...

Sheet Resumen-DiarioHorario-Solar
B2: CURTAILMENTS SOLAR POR CENTRALES EN FORMA DIARIA/HORARIA
B5: ='Resumen-Mensual'!$E$26 -> 45931
B7: Central/Hora | E7: 1 | F7: 2 | G7: 3 | H7: 4 | I7: 5 | J7: 6 | K7: 7 | L7: 8 | M7: 9 | N7: 10 | O7: 11 | P7: 12 | Q7: 13 | R7: 14 | S7: 15 | T7: 16 | U7: 17 | V7: 18 | W7: 19 | X7: 20 | Y7: 21 | Z7: 22 | AA7: 23 | AB7: 24 | AC7: Total
B8: PFV-POZOALMONTE-2 | E8: 0 | F8: 0 | G8: 0 | H8: 0 | I8: 0 | J8: 0 | K8: 0 | L8: 0.035 | M8: 4.2 | N8: 1.77 | O8: 1.98 | P8: 1.79 | Q8: 1.61 | R8: 1.67 | S8: 1.54 | T8: 1.54 | U8: 1.16 | V8: 1.28 | W8: 3.0333333 | X8: 0 | Y8: 0 | Z8: 0 | AA8: 0 | AB8: 0 | AD8: =SUM(E8:AB8) -> 21.608333
