Workbook

Sheet Resumen-Mensual
B2: RESUMEN DE CURTAILMENTS ACUMULADO DE CENTRALES EÓLICAS, SOLARES HIDRÁULICAS DE PASADA, EMBALSES Y SERIES HÍDRICAS AÑO 2025
C4: Resumen Anual / Mensual (GWh)
C6: Acumulado 2025
B7: Eólica | C7: =SUM(C14,F14,I14,L14,O14,R14,U14,X14,AA14,AD14,AG14,AJ14) -> 477.84286 | E7: =IF($C$11=0,"-",+C7/$C$11) -> 0.22222398
B8: Solar | C8: =SUM(C15,F15,I15,L15,O15,R15,U15,X15,AA15,AD15,AG15,AJ15) -> 1629.8657 | E8: =IF($C$11=0,"-",+C8/$C$11) -> 0.75797983 | Y8: =+AJ84/1000-X15 -> 142.0184
B9: Hidro Pasada | C9: =SUM(C16,F16,I16,L16,O16,R16,U16,X16,AA16,AD16,AG16,AJ16) -> 40.576434 | E9: =IF($C$11=0,"-",+C9/$C$11) -> 0.018870338
B10: Hidro Embalse | C10: =SUM(C17,F17,I17,L17,O17,R17,U17,X17,AA17,AD17,AG17,AJ17) -> 1.9908386 | E10: =IF($C$11=0,"-",+C10/$C$11) -> 0.00092585266
B11: Total | C11: =SUM(C7:C10) -> 2150.2759 | E11: =SUM(E7:E10) -> 1
C13: 45658 | F13: 45689 | I13: 45717 | L13: 45748 | O13: 45778 | R13: 45809 | U13: 45839 | X13: 45870 | AA13: 45901 | AD13: 45931 | AG13: 45962 | AJ13: 45992
B14: Eólica | C14: ='Acumulado-Anual-Eólico'!AJ10/1000 -> 147.02888 | E14: =IF($C$18=0,"-",+C14/$C$18) -> 0.22184096 | F14: ='Acumulado-Anual-Eólico'!AJ65/1000 -> 100.28563 | H14: =IF($F$18=0,"-",+F14/$F$18) -> 0.23812007 | I14: ='Acumulado-Anual-Eólico'!$AJ$120/1000 -> 121.00713 | K14: =IF($I$18=0,"-",+I14/$I$18) -> 0.2223667 | L14: ='Acumulado-Anual-Eólico'!AJ175/1000 -> 65.27924 | N14: =IF($L$18=0,"-",+L14/$L$18) -> 0.19569124 | O14: =+'Acumulado-Anual-Eólico'!AJ231/1000 -> 44.241988 | Q14: =IF($O$18=0,"-",+O14/$O$18) -> 0.23459099 | R14: 0 | T14: =IF($R$18=0,"-",+R14/$R$18) -> - | U14: 0 | W14: =IF($U$18=0,"-",+U14/$U$18) -> - | X14: 0 | Z14: =IF($X$18=0,"-",+X14/$X$18) -> - | AA14: 0 | AC14: =IF($AA$18=0,"-",+AA14/$AA$18) -> - | AD14: 0 | AF14: =IF($AD$18=0,"-",+AD14/$AD$18) -> - | AG14: 0 | AI14: =IF($AG$18=0,"-",+AG14/$AG$18) -> - | AJ14: 0 | AL14: =IF($AJ$18=0,"-",+AJ14/$AJ$18) -> -
B15: Solar | C15: ='Acumulado-Anual-Solar'!AJ10/1000 -> 494.3341 | E15: =IF($C$18=0,"-",+C15/$C$18) -> 0.74586401 | F15: ='Acumulado-Anual-Solar'!AJ84/1000 -> 311.23959 | H15: =IF($F$18=0,"-",+F15/$F$18) -> 0.73901313 | I15: ='Acumulado-Anual-Solar'!$AJ$158/1000 -> 415.98783 | K15: =IF($I$18=0,"-",+I15/$I$18) -> 0.76443301 | L15: ='Acumulado-Anual-Solar'!AJ232/1000 -> 266.28583 | N15: =IF($L$18=0,"-",+L15/$L$18) -> 0.79825998 | O15: =+'Acumulado-Anual-Solar'!AJ308/1000 -> 142.0184 | Q15: =IF($O$18=0,"-",+O15/$O$18) -> 0.75304566 | R15: 0 | T15: =IF($R$18=0,"-",+R15/$R$18) -> - | U15: 0 | W15: =IF($U$18=0,"-",+U15/$U$18) -> - | X15: 0 | Z15: =IF($X$18=0,"-",+X15/$X$18) -> - | AA15: 0 | AC15: =IF($AA$18=0,"-",+AA15/$AA$18) -> - | AD15: 0 | AF15: =IF($AD$18=0,"-",+AD15/$AD$18) -> - | AG15: 0 | AI15: =IF($AG$18=0,"-",+AG15/$AG$18) -> - | AJ15: 0 | AL15: =IF($AJ$18=0,"-",+AJ15/$AJ$18) -> -
B16: Hidro Pasada | C16: =+'Acumulado-Anual-HP'!AJ11/1000 -> 20.43018 | E16: =IF($C$18=0,"-",+C16/$C$18) -> 0.030825581 | F16: =+'Acumulado-Anual-HP'!AJ152/1000 -> 8.6135453 | H16: =IF($F$18=0,"-",+F16/$F$18) -> 0.020452164 | I16: ='Acumulado-Anual-HP'!AJ293/1000 -> 7.18331 | K16: =IF($I$18=0,"-",+I16/$I$18) -> 0.013200288 | L16: ='Acumulado-Anual-HP'!AJ434/1000 -> 2.0177691 | N16: =IF($L$18=0,"-",+L16/$L$18) -> 0.0060487797 | O16: =+'Acumulado-Anual-HP'!AJ575/1000 -> 2.3316291 | Q16: =IF($O$18=0,"-",+O16/$O$18) -> 0.01236335 | R16: 0 | T16: =IF($R$18=0,"-",+R16/$R$18) -> - | U16: 0 | W16: =IF($U$18=0,"-",+U16/$U$18) -> - | X16: 0 | Z16: =IF($X$18=0,"-",+X16/$X$18) -> - | AA16: 0 | AC16: =IF($AA$18=0,"-",+AA16/$AA$18) -> - | AD16: 0 | AF16: =IF($AD$18=0,"-",+AD16/$AD$18) -> - | AG16: 0 | AI16: =IF($AG$18=0,"-",+AG16/$AG$18) -> - | AJ16: 0 | AL16: =IF($AJ$18=0,"-",+AJ16/$AJ$18) -> -
B17: Hidro Embalse | C17: ='Acumulado-Anual-HE'!AJ10/1000 -> 0.97390005 | E17: =IF($C$18=0,"-",+C17/$C$18) -> 0.0014694455 | F17: =+'Acumulado-Anual-HE'!AJ44/1000 -> 1.0169386 | H17: =IF($F$18=0,"-",+F17/$F$18) -> 0.0024146381 | I17: ='Acumulado-Anual-HE'!AJ78 -> 0 | K17: =IF($I$18=0,"-",+I17/$I$18) -> 0 | L17: ='Acumulado-Anual-HE'!AJ112 -> 0 | N17: =IF($L$18=0,"-",+L17/$L$18) -> 0 | O17: =+'Acumulado-Anual-HE'!AJ146/1000 -> 0 | Q17: =IF($O$18=0,"-",+O17/$O$18) -> 0 | R17: 0 | T17: =IF($R$18=0,"-",+R17/$R$18) -> - | U17: 0 | W17: =IF($U$18=0,"-",+U17/$U$18) -> - | X17: 0 | Z17: =IF($X$18=0,"-",+X17/$X$18) -> - | AA17: 0 | AC17: =IF($AA$18=0,"-",+AA17/$AA$18) -> - | AD17: 0 | AF17: =IF($AD$18=0,"-",+AD17/$AD$18) -> - | AG17: 0 | AI17: =IF($AG$18=0,"-",+AG17/$AG$18) -> - | AJ17: 0 | AL17: =IF($AJ$18=0,"-",+AJ17/$AJ$18) -> -
B18: Total | C18: =SUM(C14:D17) -> 662.76706 | E18: =SUM(E14:E17) -> 1 | F18: =SUM(F14:G17) -> 421.1557 | H18: =SUM(H14:H17) -> 1 | I18: =SUM(I14:I17) -> 544.17827 | K18: =SUM(K14:K17) -> 1 | L18: =SUM(L14:L17) -> 333.58284 | N18: =SUM(N14:N17) -> 1 | O18: =SUM(O14:O17) -> 188.59202 | Q18: =SUM(Q14:Q17) -> 1 | R18: =SUM(R14:R17) -> 0 | T18: =SUM(T14:T17) -> 0 | U18: =SUM(U14:U17) -> 0 | W18: =SUM(W14:W17) -> 0 | X18: =SUM(X14:X17) -> 0 | Z18: =SUM(Z14:Z17) -> 0 | AA18: =SUM(AA14:AA17) -> 0 | AC18: =SUM(AC14:AC17) -> 0 | AD18: =SUM(AD14:AD17) -> 0 | AF18: =SUM(AF14:AF17) -> 0 | AG18: =SUM(AG14:AG17) -> 0 | AI18: =SUM(AI14:AI17) -> 0 | AJ18: =SUM(AJ14:AJ17) -> 0 | AL18: =SUM(AL14:AL17) -> 0
B21: RESUMEN DE CURTAILMENTS CENTRALES EÓLICAS, SOLARES, HIDRÁULICAS DE PASADA, EMBALSES Y SERIES HÍDRICAS CORRESPONDIENTE A MAYO 2025 (MWh)
B24: DESGLOSE DIARIO DE CURTAILMENTS DE ENERGÍA EÓLICA
B26: Central / Día | E26: 45778 | F26: =+E26+1 -> 45779 | G26: =+F26+1 -> 45780 | H26: =+G26+1 -> 45781 | I26: =+H26+1 -> 45782 | J26: =+I26+1 -> 45783 | K26: =+J26+1 -> 45784 | L26: =+K26+1 -> 45785 | M26: =+L26+1 -> 45786 | ... AI26: =+AH26+1 -> 45808 | AJ26: Total
B27: Total | E27: =SUM(E28:E78) -> 2789.0277 | F27: =SUM(F28:F78) -> 964.86658 | G27: =SUM(G28:G78) -> 1713.2131 | H27: =SUM(H28:H78) -> 1831.6015 | I27: =SUM(I28:I78) -> 2.642 | J27: =SUM(J28:J78) -> 1135.2818 | K27: =SUM(K28:K78) -> 1186.6352 | L27: =SUM(L28:L78) -> 3819.4398 | ... AI27: =SUM(AI28:AI78) -> 1729.9761 | AK27: =SUM(AK28:AK78) -> 44241.988
B28: PE-TCHAMMA | E28: ='Resumen-DiarioHorario-Eólico'!AD8 -> 61.751833 | F28: ='Resumen-DiarioHorario-Eólico'!AD65 -> 97.882 | G28: ='Resumen-DiarioHorario-Eólico'!AD122 -> 66.386667 | H28: ='Resumen-DiarioHorario-Eólico'!AD179 -> 62.0005 | I28: ='Resumen-DiarioHorario-Eólico'!AD236 -> 0 | J28: ='Resumen-DiarioHorario-Eólico'!AD293 -> 72.008833 | K28: ='Resumen-DiarioHorario-Eólico'!AD350 -> 76.082 | L28: ='Resumen-DiarioHorario-Eólico'!AD407 -> 131.8685 | M28: ='Resumen-DiarioHorario-Eólico'!AD464 -> 330.3535 | N28: ='Resumen-DiarioHorario-Eólico'!AD521 -> 259.8585 | O28: ='Resumen-DiarioHorario-Eólico'!AD578 -> 108.86867 | P28: ='Resumen-DiarioHorario-Eólico'!AD635 -> 19.503333 | Q28: ='Resumen-DiarioHorario-Eólico'!AD692 -> 25.5965 | R28: ='Resumen-DiarioHorario-Eólico'!AD749 -> 7.3023333 | S28: ='Resumen-DiarioHorario-Eólico'!AD806 -> 0 | T28: ='Resumen-DiarioHorario-Eólico'!AD863 -> 0 | U28: ='Resumen-DiarioHorario-Eólico'!AD920 -> 0.012 | V28: ='Resumen-DiarioHorario-Eólico'!AD977 -> 147.7045 | W28: ='Resumen-DiarioHorario-Eólico'!AD1034 -> 0 | X28: ='Resumen-DiarioHorario-Eólico'!AD1091 -> 47.376 | Y28: ='Resumen-DiarioHorario-Eólico'!AD1148 -> 59.341167 | Z28: ='Resumen-DiarioHorario-Eólico'!AD1205 -> 14.452167 | AA28: ='Resumen-DiarioHorario-Eólico'!AD1262 -> 0 | AB28: ='Resumen-DiarioHorario-Eólico'!AD1319 -> 0 | AC28: ='Resumen-DiarioHorario-Eólico'!AD1376 -> 6.6286667 | AD28: ='Resumen-DiarioHorario-Eólico'!AD1433 -> 0.098333333 | AE28: ='Resumen-DiarioHorario-Eólico'!AD1490 -> 158.43733 | AF28: ='Resumen-DiarioHorario-Eólico'!AD1546 -> 120.41933 | AG28: ='Resumen-DiarioHorario-Eólico'!AD1602 -> 0 | AH28: =+'Resumen-DiarioHorario-Eólico'!AD1658 -> 108.62117 | AI28: =+'Resumen-DiarioHorario-Eólico'!AD1714 -> 63.872 | AK28: =SUM(E28:AI28) -> 2046.4258
B29: PE-SIERRAGORDA | E29: ='Resumen-DiarioHorario-Eólico'!AD9 -> 55.617167 | F29: ='Resumen-DiarioHorario-Eólico'!AD66 -> 43.571833 | G29: ='Resumen-DiarioHorario-Eólico'!AD123 -> 25.913333 | H29: ='Resumen-DiarioHorario-Eólico'!AD180 -> 56.336333 | I29: ='Resumen-DiarioHorario-Eólico'!AD237 -> 0 | J29: ='Resumen-DiarioHorario-Eólico'!AD294 -> 65.170333 | K29: ='Resumen-DiarioHorario-Eólico'!AD351 -> 1.72 | L29: ='Resumen-DiarioHorario-Eólico'!AD408 -> 249.51867 | M29: ='Resumen-DiarioHorario-Eólico'!AD465 -> 113.67017 | N29: ='Resumen-DiarioHorario-Eólico'!AD522 -> 81.292333 | O29: ='Resumen-DiarioHorario-Eólico'!AD579 -> 71.254 | P29: ='Resumen-DiarioHorario-Eólico'!AD636 -> 20.217667 | Q29: ='Resumen-DiarioHorario-Eólico'!AD693 -> 90.8365 | R29: ='Resumen-DiarioHorario-Eólico'!AD750 -> 2.1655 | S29: ='Resumen-DiarioHorario-Eólico'!AD807 -> 0 | T29: ='Resumen-DiarioHorario-Eólico'!AD864 -> 0 | U29: ='Resumen-DiarioHorario-Eólico'!AD921 -> 0 | V29: ='Resumen-DiarioHorario-Eólico'!AD978 -> 184.61467 | W29: ='Resumen-DiarioHorario-Eólico'!AD1035 -> 0 | X29: ='Resumen-DiarioHorario-Eólico'!AD1092 -> 9.6161667 | Y29: ='Resumen-DiarioHorario-Eólico'!AD1149 -> 44.264833 | Z29: ='Resumen-DiarioHorario-Eólico'!AD1206 -> 16.289 | AA29: ='Resumen-DiarioHorario-Eólico'!AD1263 -> 0 | AB29: ='Resumen-DiarioHorario-Eólico'!AD1320 -> 0 | AC29: ='Resumen-DiarioHorario-Eólico'!AD1377 -> 12.57 | AD29: ='Resumen-DiarioHorario-Eólico'!AD1434 -> 0.020833333 | AE29: ='Resumen-DiarioHorario-Eólico'!AD1491 -> 49.729 | AF29: ='Resumen-DiarioHorario-Eólico'!AD1547 -> 130.48183 | AG29: ='Resumen-DiarioHorario-Eólico'!AD1603 -> 0 | AH29: =+'Resumen-DiarioHorario-Eólico'!AD1659 -> 42.786833 | AI29: =+'Resumen-DiarioHorario-Eólico'!AD1715 -> 17.148667 | AK29: =SUM(E29:AI29) -> 1384.8057
B30: PE-VALLEDELOSVIENTOS | E30: ='Resumen-DiarioHorario-Eólico'!AD10 -> 59.441667 | F30: ='Resumen-DiarioHorario-Eólico'!AD67 -> 51.809833 | G30: ='Resumen-DiarioHorario-Eólico'!AD124 -> 25.855333 | H30: ='Resumen-DiarioHorario-Eólico'!AD181 -> 4.9963333 | I30: ='Resumen-DiarioHorario-Eólico'!AD238 -> 0 | J30: ='Resumen-DiarioHorario-Eólico'!AD295 -> 119.70083 | K30: ='Resumen-DiarioHorario-Eólico'!AD352 -> 53.9915 | L30: ='Resumen-DiarioHorario-Eólico'!AD409 -> 309.85017 | M30: ='Resumen-DiarioHorario-Eólico'!AD466 -> 138.70567 | N30: ='Resumen-DiarioHorario-Eólico'!AD523 -> 150.97783 | O30: ='Resumen-DiarioHorario-Eólico'!AD580 -> 113.79117 | P30: ='Resumen-DiarioHorario-Eólico'!AD637 -> 26.581667 | Q30: ='Resumen-DiarioHorario-Eólico'!AD694 -> 144.40767 | R30: ='Resumen-DiarioHorario-Eólico'!AD751 -> 24.9085 | S30: ='Resumen-DiarioHorario-Eólico'!AD808 -> 16.278167 | T30: ='Resumen-DiarioHorario-Eólico'!AD865 -> 42.261667 | U30: ='Resumen-DiarioHorario-Eólico'!AD922 -> 2.2038333 | V30: ='Resumen-DiarioHorario-Eólico'!AD979 -> 106.2745 | W30: ='Resumen-DiarioHorario-Eólico'!AD1036 -> 0 | X30: ='Resumen-DiarioHorario-Eólico'!AD1093 -> 5.9088333 | Y30: ='Resumen-DiarioHorario-Eólico'!AD1150 -> 19.266833 | Z30: ='Resumen-DiarioHorario-Eólico'!AD1207 -> 33.153333 | AA30: ='Resumen-DiarioHorario-Eólico'!AD1264 -> 0 | AB30: ='Resumen-DiarioHorario-Eólico'!AD1321 -> 0 | AC30: ='Resumen-DiarioHorario-Eólico'!AD1378 -> 0 | AD30: ='Resumen-DiarioHorario-Eólico'!AD1435 -> 7.5053333 | AE30: ='Resumen-DiarioHorario-Eólico'!AD1492 -> 66.988333 | AF30: ='Resumen-DiarioHorario-Eólico'!AD1548 -> 99.521 | AG30: ='Resumen-DiarioHorario-Eólico'!AD1604 -> 0 | AH30: =+'Resumen-DiarioHorario-Eólico'!AD1660 -> 80.569333 | AI30: =+'Resumen-DiarioHorario-Eólico'!AD1716 -> 44.618667 | AK30: =SUM(E30:AI30) -> 1749.568
B31: PE-CERROTIGRE | E31: ='Resumen-DiarioHorario-Eólico'!AD11 -> 258.4755 | F31: ='Resumen-DiarioHorario-Eólico'!AD68 -> 49.548667 | G31: ='Resumen-DiarioHorario-Eólico'!AD125 -> 38.147167 | H31: ='Resumen-DiarioHorario-Eólico'!AD182 -> 26.778333 | I31: ='Resumen-DiarioHorario-Eólico'!AD239 -> 0 | J31: ='Resumen-DiarioHorario-Eólico'!AD296 -> 61.191833 | K31: ='Resumen-DiarioHorario-Eólico'!AD353 -> 73.938 | L31: ='Resumen-DiarioHorario-Eólico'!AD410 -> 436.78833 | M31: ='Resumen-DiarioHorario-Eólico'!AD467 -> 322.34567 | N31: ='Resumen-DiarioHorario-Eólico'!AD524 -> 449.25017 | O31: ='Resumen-DiarioHorario-Eólico'!AD581 -> 433.4465 | P31: ='Resumen-DiarioHorario-Eólico'!AD638 -> 172.47033 | Q31: ='Resumen-DiarioHorario-Eólico'!AD695 -> 234.4995 | R31: ='Resumen-DiarioHorario-Eólico'!AD752 -> 5.5841667 | S31: ='Resumen-DiarioHorario-Eólico'!AD809 -> 0 | T31: ='Resumen-DiarioHorario-Eólico'!AD866 -> 0 | U31: ='Resumen-DiarioHorario-Eólico'!AD923 -> 0.15616667 | V31: ='Resumen-DiarioHorario-Eólico'!AD980 -> 351.03533 | W31: ='Resumen-DiarioHorario-Eólico'!AD1037 -> 0 | X31: ='Resumen-DiarioHorario-Eólico'!AD1094 -> 0.18766667 | Y31: ='Resumen-DiarioHorario-Eólico'!AD1151 -> 13.9845 | Z31: ='Resumen-DiarioHorario-Eólico'!AD1208 -> 53.8485 | AA31: ='Resumen-DiarioHorario-Eólico'!AD1265 -> 0 | AB31: ='Resumen-DiarioHorario-Eólico'!AD1322 -> 0 | AC31: ='Resumen-DiarioHorario-Eólico'!AD1379 -> 0.097333333 | AD31: ='Resumen-DiarioHorario-Eólico'!AD1436 -> 15.5605 | AE31: ='Resumen-DiarioHorario-Eólico'!AD1493 -> 115.314 | AF31: ='Resumen-DiarioHorario-Eólico'!AD1549 -> 106.74417 | AG31: ='Resumen-DiarioHorario-Eólico'!AD1605 -> 0 | AH31: =+'Resumen-DiarioHorario-Eólico'!AD1661 -> 178.71267 | AI31: =+'Resumen-DiarioHorario-Eólico'!AD1717 -> 157.551 | AK31: =SUM(E31:AI31) -> 3555.656
B32: PE-CALAMA | E32: ='Resumen-DiarioHorario-Eólico'!AD12 -> 88.9755 | F32: ='Resumen-DiarioHorario-Eólico'!AD69 -> 163.5875 | G32: ='Resumen-DiarioHorario-Eólico'!AD126 -> 146.49767 | H32: ='Resumen-DiarioHorario-Eólico'!AD183 -> 51.232333 | I32: ='Resumen-DiarioHorario-Eólico'!AD240 -> 0 | J32: ='Resumen-DiarioHorario-Eólico'!AD297 -> 278.4155 | K32: ='Resumen-DiarioHorario-Eólico'!AD354 -> 91.612167 | L32: ='Resumen-DiarioHorario-Eólico'!AD411 -> 310.39233 | M32: ='Resumen-DiarioHorario-Eólico'!AD468 -> 314.37283 | N32: ='Resumen-DiarioHorario-Eólico'!AD525 -> 206.36533 | O32: ='Resumen-DiarioHorario-Eólico'!AD582 -> 174.17683 | P32: ='Resumen-DiarioHorario-Eólico'!AD639 -> 106.47633 | Q32: ='Resumen-DiarioHorario-Eólico'!AD696 -> 237.79767 | R32: ='Resumen-DiarioHorario-Eólico'!AD753 -> 3.322 | S32: ='Resumen-DiarioHorario-Eólico'!AD810 -> 0 | T32: ='Resumen-DiarioHorario-Eólico'!AD867 -> 0 | U32: ='Resumen-DiarioHorario-Eólico'!AD924 -> 1.0423333 | V32: ='Resumen-DiarioHorario-Eólico'!AD981 -> 278.00183 | W32: ='Resumen-DiarioHorario-Eólico'!AD1038 -> 0 | X32: ='Resumen-DiarioHorario-Eólico'!AD1095 -> 1.7508333 | Y32: ='Resumen-DiarioHorario-Eólico'!AD1152 -> 38.7495 | Z32: ='Resumen-DiarioHorario-Eólico'!AD1209 -> 16.211833 | AA32: ='Resumen-DiarioHorario-Eólico'!AD1266 -> 0 | AB32: ='Resumen-DiarioHorario-Eólico'!AD1323 -> 0 | AC32: ='Resumen-DiarioHorario-Eólico'!AD1380 -> 0 | AD32: ='Resumen-DiarioHorario-Eólico'!AD1437 -> 20.327333 | AE32: ='Resumen-DiarioHorario-Eólico'!AD1494 -> 176.61367 | AF32: ='Resumen-DiarioHorario-Eólico'!AD1550 -> 178.85017 | AG32: ='Resumen-DiarioHorario-Eólico'!AD1606 -> 0 | AH32: =+'Resumen-DiarioHorario-Eólico'!AD1662 -> 193.8025 | AI32: =+'Resumen-DiarioHorario-Eólico'!AD1718 -> 99.420833 | AK32: =SUM(E32:AI32) -> 3177.9948
B33: PE-TALTAL | E33: ='Resumen-DiarioHorario-Eólico'!AD13 -> 209.56717 | F33: ='Resumen-DiarioHorario-Eólico'!AD70 -> 30.497667 | G33: ='Resumen-DiarioHorario-Eólico'!AD127 -> 43.8385 | H33: ='Resumen-DiarioHorario-Eólico'!AD184 -> 30.897333 | I33: ='Resumen-DiarioHorario-Eólico'!AD241 -> 2.642 | J33: ='Resumen-DiarioHorario-Eólico'!AD298 -> 36.556333 | K33: ='Resumen-DiarioHorario-Eólico'!AD355 -> 498.74117 | L33: ='Resumen-DiarioHorario-Eólico'!AD412 -> 717.38517 | M33: ='Resumen-DiarioHorario-Eólico'!AD469 -> 585.66317 | N33: ='Resumen-DiarioHorario-Eólico'!AD526 -> 5.2156667 | O33: ='Resumen-DiarioHorario-Eólico'!AD583 -> 160.0205 | P33: ='Resumen-DiarioHorario-Eólico'!AD640 -> 14.972 | Q33: ='Resumen-DiarioHorario-Eólico'!AD697 -> 16.969167 | R33: ='Resumen-DiarioHorario-Eólico'!AD754 -> 2.1153333 | S33: ='Resumen-DiarioHorario-Eólico'!AD811 -> 0 | T33: ='Resumen-DiarioHorario-Eólico'!AD868 -> 223.035 | U33: ='Resumen-DiarioHorario-Eólico'!AD925 -> 594.34 | V33: ='Resumen-DiarioHorario-Eólico'!AD982 -> 178.0705 | W33: ='Resumen-DiarioHorario-Eólico'!AD1039 -> 0 | X33: ='Resumen-DiarioHorario-Eólico'!AD1096 -> 0 | Y33: ='Resumen-DiarioHorario-Eólico'!AD1153 -> 11.948333 | Z33: ='Resumen-DiarioHorario-Eólico'!AD1210 -> 21.907667 | AA33: ='Resumen-DiarioHorario-Eólico'!AD1267 -> 83.233333 | AB33: ='Resumen-DiarioHorario-Eólico'!AD1324 -> 0 | AC33: ='Resumen-DiarioHorario-Eólico'!AD1381 -> 47.6035 | AD33: ='Resumen-DiarioHorario-Eólico'!AD1438 -> 0.726 | AE33: ='Resumen-DiarioHorario-Eólico'!AD1495 -> 69.1965 | AF33: ='Resumen-DiarioHorario-Eólico'!AD1551 -> 51.322167 | AG33: ='Resumen-DiarioHorario-Eólico'!AD1607 -> 0 | AH33: =+'Resumen-DiarioHorario-Eólico'!AD1663 -> 9.6518333 | AI33: =+'Resumen-DiarioHorario-Eólico'!AD1719 -> 44.007 | AK33: =SUM(E33:AI33) -> 3690.123
B34: PE-SARCO | E34: ='Resumen-DiarioHorario-Eólico'!AD14 -> 40.6215 | F34: ='Resumen-DiarioHorario-Eólico'!AD71 -> 15.956167 | G34: ='Resumen-DiarioHorario-Eólico'!AD128 -> 17.118667 | H34: ='Resumen-DiarioHorario-Eólico'!AD185 -> 17.047833 | I34: ='Resumen-DiarioHorario-Eólico'!AD242 -> 0 | J34: ='Resumen-DiarioHorario-Eólico'!AD299 -> 0.65633333 | K34: ='Resumen-DiarioHorario-Eólico'!AD356 -> 26.533167 | L34: ='Resumen-DiarioHorario-Eólico'!AD413 -> 145.825 | M34: ='Resumen-DiarioHorario-Eólico'!AD470 -> 142.79233 | N34: ='Resumen-DiarioHorario-Eólico'!AD527 -> 19.281833 | O34: ='Resumen-DiarioHorario-Eólico'!AD584 -> 92.648333 | P34: ='Resumen-DiarioHorario-Eólico'!AD641 -> 14.800667 | Q34: ='Resumen-DiarioHorario-Eólico'!AD698 -> 69.8085 | R34: ='Resumen-DiarioHorario-Eólico'!AD755 -> 0 | S34: ='Resumen-DiarioHorario-Eólico'!AD812 -> 0 | T34: ='Resumen-DiarioHorario-Eólico'!AD869 -> 0 | U34: ='Resumen-DiarioHorario-Eólico'!AD926 -> 6.8923333 | V34: ='Resumen-DiarioHorario-Eólico'!AD983 -> 73.832667 | W34: ='Resumen-DiarioHorario-Eólico'!AD1040 -> 0 | X34: ='Resumen-DiarioHorario-Eólico'!AD1097 -> 24.493167 | Y34: ='Resumen-DiarioHorario-Eólico'!AD1154 -> 19.163333 | Z34: ='Resumen-DiarioHorario-Eólico'!AD1211 -> 13.421333 | AA34: ='Resumen-DiarioHorario-Eólico'!AD1268 -> 0 | AB34: ='Resumen-DiarioHorario-Eólico'!AD1325 -> 0 | AC34: ='Resumen-DiarioHorario-Eólico'!AD1382 -> 0.5875 | AD34: ='Resumen-DiarioHorario-Eólico'!AD1439 -> 0 | AE34: ='Resumen-DiarioHorario-Eólico'!AD1496 -> 312.88467 | AF34: ='Resumen-DiarioHorario-Eólico'!AD1552 -> 570.35867 | AG34: ='Resumen-DiarioHorario-Eólico'!AD1608 -> 0 | AH34: =+'Resumen-DiarioHorario-Eólico'!AD1664 -> 38.413333 | AI34: =+'Resumen-DiarioHorario-Eólico'!AD1720 -> 66.938667 | AK34: =SUM(E34:AI34) -> 1730.076
B35: PE-CABOLEONES-1 | E35: ='Resumen-DiarioHorario-Eólico'!AD15 -> 8.864 | F35: ='Resumen-DiarioHorario-Eólico'!AD72 -> 15.712667 | G35: ='Resumen-DiarioHorario-Eólico'!AD129 -> 5.0603333 | H35: ='Resumen-DiarioHorario-Eólico'!AD186 -> 6.1173333 | I35: ='Resumen-DiarioHorario-Eólico'!AD243 -> 0 | J35: ='Resumen-DiarioHorario-Eólico'!AD300 -> 0 | K35: ='Resumen-DiarioHorario-Eólico'!AD357 -> 19.535833 | L35: ='Resumen-DiarioHorario-Eólico'!AD414 -> 185.66517 | M35: ='Resumen-DiarioHorario-Eólico'!AD471 -> 236.00567 | N35: ='Resumen-DiarioHorario-Eólico'!AD528 -> 14.677333 | O35: ='Resumen-DiarioHorario-Eólico'!AD585 -> 154.82733 | P35: ='Resumen-DiarioHorario-Eólico'!AD642 -> 0 | Q35: ='Resumen-DiarioHorario-Eólico'!AD699 -> 67.194 | R35: ='Resumen-DiarioHorario-Eólico'!AD756 -> 0 | S35: ='Resumen-DiarioHorario-Eólico'!AD813 -> 0 | T35: ='Resumen-DiarioHorario-Eólico'!AD870 -> 0 | U35: ='Resumen-DiarioHorario-Eólico'!AD927 -> 0.010833333 | V35: ='Resumen-DiarioHorario-Eólico'!AD984 -> 74.645167 | W35: ='Resumen-DiarioHorario-Eólico'!AD1041 -> 0 | X35: ='Resumen-DiarioHorario-Eólico'!AD1098 -> 17.369333 | Y35: ='Resumen-DiarioHorario-Eólico'!AD1155 -> 23.5295 | Z35: ='Resumen-DiarioHorario-Eólico'!AD1212 -> 15.637833 | AA35: ='Resumen-DiarioHorario-Eólico'!AD1269 -> 0 | AB35: ='Resumen-DiarioHorario-Eólico'!AD1326 -> 0 | AC35: ='Resumen-DiarioHorario-Eólico'!AD1383 -> 2.0283333 | AD35: ='Resumen-DiarioHorario-Eólico'!AD1440 -> 0 | AE35: ='Resumen-DiarioHorario-Eólico'!AD1497 -> 199.32567 | AF35: ='Resumen-DiarioHorario-Eólico'!AD1553 -> 33.812167 | AG35: ='Resumen-DiarioHorario-Eólico'!AD1609 -> 0 | AH35: =+'Resumen-DiarioHorario-Eólico'!AD1665 -> 0.7885 | AI35: =+'Resumen-DiarioHorario-Eólico'!AD1721 -> 36.9225 | AK35: =SUM(E35:AI35) -> 1117.7295
B36: PE-CABOLEONES-2 | E36: ='Resumen-DiarioHorario-Eólico'!AD16 -> 8.3943333 | F36: ='Resumen-DiarioHorario-Eólico'!AD73 -> 21.38 | G36: ='Resumen-DiarioHorario-Eólico'!AD130 -> 8.5265 | H36: ='Resumen-DiarioHorario-Eólico'!AD187 -> 0.87416667 | I36: ='Resumen-DiarioHorario-Eólico'!AD244 -> 0 | J36: ='Resumen-DiarioHorario-Eólico'!AD301 -> 0 | K36: ='Resumen-DiarioHorario-Eólico'!AD358 -> 0.48483333 | L36: ='Resumen-DiarioHorario-Eólico'!AD415 -> 94.8225 | M36: ='Resumen-DiarioHorario-Eólico'!AD472 -> 203.1 | N36: ='Resumen-DiarioHorario-Eólico'!AD529 -> 15.086833 | O36: ='Resumen-DiarioHorario-Eólico'!AD586 -> 177.69317 | P36: ='Resumen-DiarioHorario-Eólico'!AD643 -> 0 | Q36: ='Resumen-DiarioHorario-Eólico'!AD700 -> 54.962667 | R36: ='Resumen-DiarioHorario-Eólico'!AD757 -> 0 | S36: ='Resumen-DiarioHorario-Eólico'!AD814 -> 0 | T36: ='Resumen-DiarioHorario-Eólico'!AD871 -> 0 | U36: ='Resumen-DiarioHorario-Eólico'!AD928 -> 0 | V36: ='Resumen-DiarioHorario-Eólico'!AD985 -> 78.384 | W36: ='Resumen-DiarioHorario-Eólico'!AD1042 -> 0 | X36: ='Resumen-DiarioHorario-Eólico'!AD1099 -> 14.837833 | Y36: ='Resumen-DiarioHorario-Eólico'!AD1156 -> 28.958167 | Z36: ='Resumen-DiarioHorario-Eólico'!AD1213 -> 14.383833 | AA36: ='Resumen-DiarioHorario-Eólico'!AD1270 -> 0 | AB36: ='Resumen-DiarioHorario-Eólico'!AD1327 -> 0 | AC36: ='Resumen-DiarioHorario-Eólico'!AD1384 -> 3.8313333 | AD36: ='Resumen-DiarioHorario-Eólico'!AD1441 -> 0 | AE36: ='Resumen-DiarioHorario-Eólico'!AD1498 -> 51.241667 | AF36: ='Resumen-DiarioHorario-Eólico'!AD1554 -> 38.668 | AG36: ='Resumen-DiarioHorario-Eólico'!AD1610 -> 0 | AH36: =+'Resumen-DiarioHorario-Eólico'!AD1666 -> 0.20433333 | AI36: =+'Resumen-DiarioHorario-Eólico'!AD1722 -> 20.645 | AK36: =SUM(E36:AI36) -> 836.47917
B37: PE-CABOLEONES-3 | E37: ='Resumen-DiarioHorario-Eólico'!AD17 -> 31.6655 | F37: ='Resumen-DiarioHorario-Eólico'!AD74 -> 8.4481667 | G37: ='Resumen-DiarioHorario-Eólico'!AD131 -> 25.196167 | H37: ='Resumen-DiarioHorario-Eólico'!AD188 -> 26.119833 | I37: ='Resumen-DiarioHorario-Eólico'!AD245 -> 0 | J37: ='Resumen-DiarioHorario-Eólico'!AD302 -> 0 | K37: ='Resumen-DiarioHorario-Eólico'!AD359 -> 52.300167 | L37: ='Resumen-DiarioHorario-Eólico'!AD416 -> 199.21483 | M37: ='Resumen-DiarioHorario-Eólico'!AD473 -> 224.962 | N37: ='Resumen-DiarioHorario-Eólico'!AD530 -> 20.390833 | O37: ='Resumen-DiarioHorario-Eólico'!AD587 -> 51.7845 | P37: ='Resumen-DiarioHorario-Eólico'!AD644 -> 0 | Q37: ='Resumen-DiarioHorario-Eólico'!AD701 -> 99.358167 | R37: ='Resumen-DiarioHorario-Eólico'!AD758 -> 0 | S37: ='Resumen-DiarioHorario-Eólico'!AD815 -> 0 | T37: ='Resumen-DiarioHorario-Eólico'!AD872 -> 0 | U37: ='Resumen-DiarioHorario-Eólico'!AD929 -> 1.3881667 | V37: ='Resumen-DiarioHorario-Eólico'!AD986 -> 51.002667 | W37: ='Resumen-DiarioHorario-Eólico'!AD1043 -> 0 | X37: ='Resumen-DiarioHorario-Eólico'!AD1100 -> 37.996333 | Y37: ='Resumen-DiarioHorario-Eólico'!AD1157 -> 25.277167 | Z37: ='Resumen-DiarioHorario-Eólico'!AD1214 -> 8.9698333 | AA37: ='Resumen-DiarioHorario-Eólico'!AD1271 -> 0 | AB37: ='Resumen-DiarioHorario-Eólico'!AD1328 -> 0 | AC37: ='Resumen-DiarioHorario-Eólico'!AD1385 -> 3.1663333 | AD37: ='Resumen-DiarioHorario-Eólico'!AD1442 -> 2.595 | AE37: ='Resumen-DiarioHorario-Eólico'!AD1499 -> 145.74117 | AF37: ='Resumen-DiarioHorario-Eólico'!AD1555 -> 38.201167 | AG37: ='Resumen-DiarioHorario-Eólico'!AD1611 -> 0 | AH37: =+'Resumen-DiarioHorario-Eólico'!AD1667 -> 1.0105 | AI37: =+'Resumen-DiarioHorario-Eólico'!AD1723 -> 44.225 | AK37: =SUM(E37:AI37) -> 1099.0135
B38: PE-SANJUAN | E38: ='Resumen-DiarioHorario-Eólico'!AD18 -> 35.153667 | F38: ='Resumen-DiarioHorario-Eólico'!AD75 -> 15.095667 | G38: ='Resumen-DiarioHorario-Eólico'!AD132 -> 0.014333333 | H38: ='Resumen-DiarioHorario-Eólico'!AD189 -> 20.388167 | I38: ='Resumen-DiarioHorario-Eólico'!AD246 -> 0 | J38: ='Resumen-DiarioHorario-Eólico'!AD303 -> 1.9763333 | K38: ='Resumen-DiarioHorario-Eólico'!AD360 -> 13.510667 | L38: ='Resumen-DiarioHorario-Eólico'!AD417 -> 38.204333 | M38: ='Resumen-DiarioHorario-Eólico'!AD474 -> 274.41133 | N38: ='Resumen-DiarioHorario-Eólico'!AD531 -> 0.50783333 | O38: ='Resumen-DiarioHorario-Eólico'!AD588 -> 7.0186667 | P38: ='Resumen-DiarioHorario-Eólico'!AD645 -> 0 | Q38: ='Resumen-DiarioHorario-Eólico'!AD702 -> 0 | R38: ='Resumen-DiarioHorario-Eólico'!AD759 -> 0 | S38: ='Resumen-DiarioHorario-Eólico'!AD816 -> 0 | T38: ='Resumen-DiarioHorario-Eólico'!AD873 -> 0 | U38: ='Resumen-DiarioHorario-Eólico'!AD930 -> 38.287 | V38: ='Resumen-DiarioHorario-Eólico'!AD987 -> 97.370333 | W38: ='Resumen-DiarioHorario-Eólico'!AD1044 -> 0 | X38: ='Resumen-DiarioHorario-Eólico'!AD1101 -> 29.648667 | Y38: ='Resumen-DiarioHorario-Eólico'!AD1158 -> 7.1071667 | Z38: ='Resumen-DiarioHorario-Eólico'!AD1215 -> 0.31033333 | AA38: ='Resumen-DiarioHorario-Eólico'!AD1272 -> 0 | AB38: ='Resumen-DiarioHorario-Eólico'!AD1329 -> 0 | AC38: ='Resumen-DiarioHorario-Eólico'!AD1386 -> 0.073333333 | AD38: ='Resumen-DiarioHorario-Eólico'!AD1443 -> 0.035 | AE38: ='Resumen-DiarioHorario-Eólico'!AD1500 -> 119.8405 | AF38: ='Resumen-DiarioHorario-Eólico'!AD1556 -> 80.240667 | AG38: ='Resumen-DiarioHorario-Eólico'!AD1612 -> 0 | AH38: =+'Resumen-DiarioHorario-Eólico'!AD1668 -> 22.576 | AI38: =+'Resumen-DiarioHorario-Eólico'!AD1724 -> 4.5353333 | AK38: =SUM(E38:AI38) -> 806.30533
B39: PE-PUNTACOLORADA | E39: ='Resumen-DiarioHorario-Eólico'!AD19 -> 0 | F39: ='Resumen-DiarioHorario-Eólico'!AD76 -> 0 | G39: ='Resumen-DiarioHorario-Eólico'!AD133 -> 0 | H39: ='Resumen-DiarioHorario-Eólico'!AD190 -> 0 | I39: ='Resumen-DiarioHorario-Eólico'!AD247 -> 0 | J39: ='Resumen-DiarioHorario-Eólico'!AD304 -> 0 | K39: ='Resumen-DiarioHorario-Eólico'!AD361 -> 0 | L39: ='Resumen-DiarioHorario-Eólico'!AD418 -> 0 | M39: ='Resumen-DiarioHorario-Eólico'!AD475 -> 0 | N39: ='Resumen-DiarioHorario-Eólico'!AD532 -> 0 | O39: ='Resumen-DiarioHorario-Eólico'!AD589 -> 0 | P39: ='Resumen-DiarioHorario-Eólico'!AD646 -> 0 | Q39: ='Resumen-DiarioHorario-Eólico'!AD703 -> 0 | R39: ='Resumen-DiarioHorario-Eólico'!AD760 -> 0 | S39: ='Resumen-DiarioHorario-Eólico'!AD817 -> 0 | T39: ='Resumen-DiarioHorario-Eólico'!AD874 -> 0 | U39: ='Resumen-DiarioHorario-Eólico'!AD931 -> 0 | V39: ='Resumen-DiarioHorario-Eólico'!AD988 -> 0 | W39: ='Resumen-DiarioHorario-Eólico'!AD1045 -> 0 | X39: ='Resumen-DiarioHorario-Eólico'!AD1102 -> 0 | Y39: ='Resumen-DiarioHorario-Eólico'!AD1159 -> 0 | Z39: ='Resumen-DiarioHorario-Eólico'!AD1216 -> 0 | AA39: ='Resumen-DiarioHorario-Eólico'!AD1273 -> 0 | AB39: ='Resumen-DiarioHorario-Eólico'!AD1330 -> 0 | AC39: ='Resumen-DiarioHorario-Eólico'!AD1387 -> 0 | AD39: ='Resumen-DiarioHorario-Eólico'!AD1444 -> 0 | AE39: ='Resumen-DiarioHorario-Eólico'!AD1501 -> 0 | AF39: ='Resumen-DiarioHorario-Eólico'!AD1557 -> 0 | AG39: ='Resumen-DiarioHorario-Eólico'!AD1613 -> 0 | AH39: =+'Resumen-DiarioHorario-Eólico'!AD1669 -> 0 | AI39: =+'Resumen-DiarioHorario-Eólico'!AD1725 -> 0 | AK39: =SUM(E39:AI39) -> 0
... B72: PE-ATACAMA | E72: ='Resumen-DiarioHorario-Eólico'!AD52 -> 225.82817 | F72: ='Resumen-DiarioHorario-Eólico'!AD109 -> 79.8435 | G72: ='Resumen-DiarioHorario-Eólico'!AD166 -> 93.4345 | H72: ='Resumen-DiarioHorario-Eólico'!AD223 -> 8.761 | I72: ='Resumen-DiarioHorario-Eólico'!AD280 -> 0 | J72: ='Resumen-DiarioHorario-Eólico'!AD337 -> 181.0645 | K72: ='Resumen-DiarioHorario-Eólico'!AD394 -> 132.84233 | L72: ='Resumen-DiarioHorario-Eólico'!AD451 -> 460.26667 | M72: ='Resumen-DiarioHorario-Eólico'!AD508 -> 727.26567 | N72: ='Resumen-DiarioHorario-Eólico'!AD565 -> 0 | O72: ='Resumen-DiarioHorario-Eólico'!AD622 -> 267.71433 | P72: ='Resumen-DiarioHorario-Eólico'!AD679 -> 108.453 | Q72: ='Resumen-DiarioHorario-Eólico'!AD736 -> 318.72917 | R72: ='Resumen-DiarioHorario-Eólico'!AD793 -> 1.3356667 | S72: ='Resumen-DiarioHorario-Eólico'!AD850 -> 0 | T72: ='Resumen-DiarioHorario-Eólico'!AD907 -> 0 | U72: ='Resumen-DiarioHorario-Eólico'!AD964 -> 141.31 | V72: ='Resumen-DiarioHorario-Eólico'!AD1021 -> 276.58783 | W72: ='Resumen-DiarioHorario-Eólico'!AD1078 -> 0 | X72: ='Resumen-DiarioHorario-Eólico'!AD1135 -> 0.40116667 | Y72: ='Resumen-DiarioHorario-Eólico'!AD1192 -> 31.047667 | Z72: ='Resumen-DiarioHorario-Eólico'!AD1249 -> 55.091833 | AA72: ='Resumen-DiarioHorario-Eólico'!AD1306 -> 0 | AB72: ='Resumen-DiarioHorario-Eólico'!AD1363 -> 0 | AC72: ='Resumen-DiarioHorario-Eólico'!AD1420 -> 5.1501667 | AD72: ='Resumen-DiarioHorario-Eólico'!AD1477 -> 27.602833 | AE72: ='Resumen-DiarioHorario-Eólico'!AD1534 -> 341.6825 | AF72: ='Resumen-DiarioHorario-Eólico'!AD1590 -> 157.43267 | AG72: ='Resumen-DiarioHorario-Eólico'!AD1646 -> 0 | AH72: =+'Resumen-DiarioHorario-Eólico'!AD1702 -> 172.399 | AI72: =+'Resumen-DiarioHorario-Eólico'!AD1758 -> 147.02133 | AK72: =SUM(E72:AI72) -> 3961.2655
B73: PE-LACABANA | D73: † | E73: ='Resumen-DiarioHorario-Eólico'!AD53 -> 0 | F73: ='Resumen-DiarioHorario-Eólico'!AD110 -> 0.86116667 | G73: ='Resumen-DiarioHorario-Eólico'!AD167 -> 10.442333 | H73: ='Resumen-DiarioHorario-Eólico'!AD224 -> 103.55067 | I73: ='Resumen-DiarioHorario-Eólico'!AD281 -> 0 | J73: ='Resumen-DiarioHorario-Eólico'!AD338 -> 0 | K73: ='Resumen-DiarioHorario-Eólico'!AD395 -> 0 | L73: ='Resumen-DiarioHorario-Eólico'!AD452 -> 0 | M73: ='Resumen-DiarioHorario-Eólico'!AD509 -> 0 | N73: ='Resumen-DiarioHorario-Eólico'!AD566 -> 0 | O73: ='Resumen-DiarioHorario-Eólico'!AD623 -> 0 | P73: ='Resumen-DiarioHorario-Eólico'!AD680 -> 0 | Q73: ='Resumen-DiarioHorario-Eólico'!AD737 -> 0 | R73: ='Resumen-DiarioHorario-Eólico'!AD794 -> 0 | S73: ='Resumen-DiarioHorario-Eólico'!AD851 -> 0 | T73: ='Resumen-DiarioHorario-Eólico'!AD908 -> 0 | U73: ='Resumen-DiarioHorario-Eólico'!AD965 -> 0 | V73: ='Resumen-DiarioHorario-Eólico'!AD1022 -> 0 | W73: ='Resumen-DiarioHorario-Eólico'!AD1079 -> 0 | X73: ='Resumen-DiarioHorario-Eólico'!AD1136 -> 11.247667 | Y73: ='Resumen-DiarioHorario-Eólico'!AD1193 -> 1.4416667 | Z73: ='Resumen-DiarioHorario-Eólico'!AD1250 -> 17.566 | AA73: ='Resumen-DiarioHorario-Eólico'!AD1307 -> 0 | AB73: ='Resumen-DiarioHorario-Eólico'!AD1364 -> 0 | AC73: ='Resumen-DiarioHorario-Eólico'!AD1421 -> 18.311 | AD73: ='Resumen-DiarioHorario-Eólico'!AD1478 -> 0 | AE73: ='Resumen-DiarioHorario-Eólico'!AD1535 -> 0 | AF73: ='Resumen-DiarioHorario-Eólico'!AD1591 -> 0 | AG73: ='Resumen-DiarioHorario-Eólico'!AD1647 -> 0 | AH73: =+'Resumen-DiarioHorario-Eólico'!AD1703 -> 0 | AI73: =+'Resumen-DiarioHorario-Eólico'!AD1759 -> 0 | AK73: =SUM(E73:AI73) -> 163.4205
B74: PE-SANMATIAS | E74: ='Resumen-DiarioHorario-Eólico'!AD54 -> 7.5183333 | F74: ='Resumen-DiarioHorario-Eólico'!AD111 -> 0.4115 | G74: ='Resumen-DiarioHorario-Eólico'!AD168 -> 2.923 | H74: ='Resumen-DiarioHorario-Eólico'!AD225 -> 31.763 | I74: ='Resumen-DiarioHorario-Eólico'!AD282 -> 0 | J74: ='Resumen-DiarioHorario-Eólico'!AD339 -> 0 | K74: ='Resumen-DiarioHorario-Eólico'!AD396 -> 65.205167 | L74: ='Resumen-DiarioHorario-Eólico'!AD453 -> 72.546333 | M74: ='Resumen-DiarioHorario-Eólico'!AD510 -> 2.9021667 | N74: ='Resumen-DiarioHorario-Eólico'!AD567 -> 206.24583 | O74: ='Resumen-DiarioHorario-Eólico'!AD624 -> 69.386667 | P74: ='Resumen-DiarioHorario-Eólico'!AD681 -> 27.590167 | Q74: ='Resumen-DiarioHorario-Eólico'!AD738 -> 9.8903333 | R74: ='Resumen-DiarioHorario-Eólico'!AD795 -> 3.6421667 | S74: ='Resumen-DiarioHorario-Eólico'!AD852 -> 0 | T74: ='Resumen-DiarioHorario-Eólico'!AD909 -> 88.4765 | U74: ='Resumen-DiarioHorario-Eólico'!AD966 -> 100.59483 | V74: ='Resumen-DiarioHorario-Eólico'!AD1023 -> 34.386 | W74: ='Resumen-DiarioHorario-Eólico'!AD1080 -> 0 | X74: ='Resumen-DiarioHorario-Eólico'!AD1137 -> 0.93433333 | Y74: ='Resumen-DiarioHorario-Eólico'!AD1194 -> 14.48 | Z74: ='Resumen-DiarioHorario-Eólico'!AD1251 -> 53.237333 | AA74: ='Resumen-DiarioHorario-Eólico'!AD1308 -> 0 | AB74: ='Resumen-DiarioHorario-Eólico'!AD1365 -> 0 | AC74: ='Resumen-DiarioHorario-Eólico'!AD1422 -> 28.1735 | AD74: ='Resumen-DiarioHorario-Eólico'!AD1479 -> 0 | AE74: ='Resumen-DiarioHorario-Eólico'!AD1536 -> 114.19 | AF74: ='Resumen-DiarioHorario-Eólico'!AD1592 -> 37.9935 | AG74: ='Resumen-DiarioHorario-Eólico'!AD1648 -> 2.4716667 | AH74: =+'Resumen-DiarioHorario-Eólico'!AD1704 -> 36.717333 | AI74: =+'Resumen-DiarioHorario-Eólico'!AD1760 -> 9.9346667 | AK74: =SUM(E74:AI74) -> 1021.6143
B75: PE-CARDONAL | E75: ='Resumen-DiarioHorario-Eólico'!AD55 -> 24.53875 | F75: ='Resumen-DiarioHorario-Eólico'!AD112 -> 0.235335 | G75: ='Resumen-DiarioHorario-Eólico'!AD169 -> 16.846333 | H75: ='Resumen-DiarioHorario-Eólico'!AD226 -> 0.31460167 | I75: ='Resumen-DiarioHorario-Eólico'!AD283 -> 0 | J75: ='Resumen-DiarioHorario-Eólico'!AD340 -> 0 | K75: ='Resumen-DiarioHorario-Eólico'!AD397 -> 0 | L75: ='Resumen-DiarioHorario-Eólico'!AD454 -> 0 | M75: ='Resumen-DiarioHorario-Eólico'!AD511 -> 0 | N75: ='Resumen-DiarioHorario-Eólico'!AD568 -> 0.003405 | O75: ='Resumen-DiarioHorario-Eólico'!AD625 -> 0 | P75: ='Resumen-DiarioHorario-Eólico'!AD682 -> 1.0236817 | Q75: ='Resumen-DiarioHorario-Eólico'!AD739 -> 0 | R75: ='Resumen-DiarioHorario-Eólico'!AD796 -> 0.88258333 | S75: ='Resumen-DiarioHorario-Eólico'!AD853 -> 0 | T75: ='Resumen-DiarioHorario-Eólico'!AD910 -> 2.3357467 | U75: ='Resumen-DiarioHorario-Eólico'!AD967 -> 0.39192167 | V75: ='Resumen-DiarioHorario-Eólico'!AD1024 -> 0 | W75: ='Resumen-DiarioHorario-Eólico'!AD1081 -> 0 | X75: ='Resumen-DiarioHorario-Eólico'!AD1138 -> 0 | Y75: ='Resumen-DiarioHorario-Eólico'!AD1195 -> 0.46969833 | Z75: ='Resumen-DiarioHorario-Eólico'!AD1252 -> 0 | AA75: ='Resumen-DiarioHorario-Eólico'!AD1309 -> 0 | AB75: ='Resumen-DiarioHorario-Eólico'!AD1366 -> 0 | AC75: ='Resumen-DiarioHorario-Eólico'!AD1423 -> 0 | AD75: ='Resumen-DiarioHorario-Eólico'!AD1480 -> 0 | AE75: ='Resumen-DiarioHorario-Eólico'!AD1537 -> 0 | AF75: ='Resumen-DiarioHorario-Eólico'!AD1593 -> 0 | AG75: ='Resumen-DiarioHorario-Eólico'!AD1649 -> 0 | AH75: =+'Resumen-DiarioHorario-Eólico'!AD1705 -> 1.6183733 | AI75: =+'Resumen-DiarioHorario-Eólico'!AD1761 -> 14.065512 | AK75: =SUM(E75:AI75) -> 62.725942
B76: PE-CERRILLOS | E76: ='Resumen-DiarioHorario-Eólico'!AD56 -> 24.5525 | F76: ='Resumen-DiarioHorario-Eólico'!AD113 -> 2.4885067 | G76: ='Resumen-DiarioHorario-Eólico'!AD170 -> 19.648487 | H76: ='Resumen-DiarioHorario-Eólico'!AD227 -> 1.4892733 | I76: ='Resumen-DiarioHorario-Eólico'!AD284 -> 0 | J76: ='Resumen-DiarioHorario-Eólico'!AD341 -> 0 | K76: ='Resumen-DiarioHorario-Eólico'!AD398 -> 0 | L76: ='Resumen-DiarioHorario-Eólico'!AD455 -> 0 | M76: ='Resumen-DiarioHorario-Eólico'!AD512 -> 0 | N76: ='Resumen-DiarioHorario-Eólico'!AD569 -> 0.16597667 | O76: ='Resumen-DiarioHorario-Eólico'!AD626 -> 0 | P76: ='Resumen-DiarioHorario-Eólico'!AD683 -> 0.77035667 | Q76: ='Resumen-DiarioHorario-Eólico'!AD740 -> 0 | R76: ='Resumen-DiarioHorario-Eólico'!AD797 -> 0.91666667 | S76: ='Resumen-DiarioHorario-Eólico'!AD854 -> 0 | T76: ='Resumen-DiarioHorario-Eólico'!AD911 -> 0 | U76: ='Resumen-DiarioHorario-Eólico'!AD968 -> 0 | V76: ='Resumen-DiarioHorario-Eólico'!AD1025 -> 0 | W76: ='Resumen-DiarioHorario-Eólico'!AD1082 -> 0 | X76: ='Resumen-DiarioHorario-Eólico'!AD1139 -> 0 | Y76: ='Resumen-DiarioHorario-Eólico'!AD1196 -> 1.6385333 | Z76: ='Resumen-DiarioHorario-Eólico'!AD1253 -> 0 | AA76: ='Resumen-DiarioHorario-Eólico'!AD1310 -> 0 | AB76: ='Resumen-DiarioHorario-Eólico'!AD1367 -> 0 | AC76: ='Resumen-DiarioHorario-Eólico'!AD1424 -> 0 | AD76: ='Resumen-DiarioHorario-Eólico'!AD1481 -> 0 | AE76: ='Resumen-DiarioHorario-Eólico'!AD1538 -> 28.219763 | AF76: ='Resumen-DiarioHorario-Eólico'!AD1594 -> 0.70783333 | AG76: ='Resumen-DiarioHorario-Eólico'!AD1650 -> 0 | AH76: =+'Resumen-DiarioHorario-Eólico'!AD1706 -> 0.93550667 | AI76: =+'Resumen-DiarioHorario-Eólico'!AD1762 -> 21.0763 | AK76: =SUM(E76:AI76) -> 102.6097
B77: PE-MANANTIALES | E77: ='Resumen-DiarioHorario-Eólico'!AD57 -> 28.846417 | F77: ='Resumen-DiarioHorario-Eólico'!AD114 -> 1.2637433 | G77: ='Resumen-DiarioHorario-Eólico'!AD171 -> 24.560403 | H77: ='Resumen-DiarioHorario-Eólico'!AD228 -> 1.0241283 | I77: ='Resumen-DiarioHorario-Eólico'!AD285 -> 0 | J77: ='Resumen-DiarioHorario-Eólico'!AD342 -> 0 | K77: ='Resumen-DiarioHorario-Eólico'!AD399 -> 0 | L77: ='Resumen-DiarioHorario-Eólico'!AD456 -> 0 | M77: ='Resumen-DiarioHorario-Eólico'!AD513 -> 0 | N77: ='Resumen-DiarioHorario-Eólico'!AD570 -> 0.051991667 | O77: ='Resumen-DiarioHorario-Eólico'!AD627 -> 0 | P77: ='Resumen-DiarioHorario-Eólico'!AD684 -> 1.1141283 | Q77: ='Resumen-DiarioHorario-Eólico'!AD741 -> 0 | R77: ='Resumen-DiarioHorario-Eólico'!AD798 -> 0.91341667 | S77: ='Resumen-DiarioHorario-Eólico'!AD855 -> 0 | T77: ='Resumen-DiarioHorario-Eólico'!AD912 -> 0 | U77: ='Resumen-DiarioHorario-Eólico'!AD969 -> 0 | V77: ='Resumen-DiarioHorario-Eólico'!AD1026 -> 0 | W77: ='Resumen-DiarioHorario-Eólico'!AD1083 -> 0 | X77: ='Resumen-DiarioHorario-Eólico'!AD1140 -> 0 | Y77: ='Resumen-DiarioHorario-Eólico'!AD1197 -> 0.80613 | Z77: ='Resumen-DiarioHorario-Eólico'!AD1254 -> 0 | AA77: ='Resumen-DiarioHorario-Eólico'!AD1311 -> 0 | AB77: ='Resumen-DiarioHorario-Eólico'!AD1368 -> 0 | AC77: ='Resumen-DiarioHorario-Eólico'!AD1425 -> 0 | AD77: ='Resumen-DiarioHorario-Eólico'!AD1482 -> 0 | AE77: ='Resumen-DiarioHorario-Eólico'!AD1539 -> 34.419448 | AF77: ='Resumen-DiarioHorario-Eólico'!AD1595 -> 0.54814667 | AG77: ='Resumen-DiarioHorario-Eólico'!AD1651 -> 0 | AH77: =+'Resumen-DiarioHorario-Eólico'!AD1707 -> 1.4484533 | AI77: =+'Resumen-DiarioHorario-Eólico'!AD1763 -> 24.55065 | AK77: =SUM(E77:AI77) -> 119.54706
B78: PE-KALLPA | E78: ='Resumen-DiarioHorario-Eólico'!AD58 -> 371.05117 | F78: ='Resumen-DiarioHorario-Eólico'!AD115 -> 23.403833 | G78: ='Resumen-DiarioHorario-Eólico'!AD172 -> 318.2335 | H78: ='Resumen-DiarioHorario-Eólico'!AD229 -> 233.02883 | I78: ='Resumen-DiarioHorario-Eólico'!AD286 -> 0 | J78: ='Resumen-DiarioHorario-Eólico'!AD343 -> 0 | K78: ='Resumen-DiarioHorario-Eólico'!AD400 -> 0 | L78: ='Resumen-DiarioHorario-Eólico'!AD457 -> 0 | M78: ='Resumen-DiarioHorario-Eólico'!AD514 -> 0 | N78: ='Resumen-DiarioHorario-Eólico'!AD571 -> 193.34117 | O78: ='Resumen-DiarioHorario-Eólico'!AD628 -> 223.2475 | P78: ='Resumen-DiarioHorario-Eólico'!AD685 -> 75.6765 | Q78: ='Resumen-DiarioHorario-Eólico'!AD742 -> 0 | R78: ='Resumen-DiarioHorario-Eólico'!AD799 -> 15.139 | S78: ='Resumen-DiarioHorario-Eólico'!AD856 -> 0 | T78: ='Resumen-DiarioHorario-Eólico'!AD913 -> 0 | U78: ='Resumen-DiarioHorario-Eólico'!AD970 -> 0 | V78: ='Resumen-DiarioHorario-Eólico'!AD1027 -> 0 | W78: ='Resumen-DiarioHorario-Eólico'!AD1084 -> 0 | X78: ='Resumen-DiarioHorario-Eólico'!AD1141 -> 0 | Y78: ='Resumen-DiarioHorario-Eólico'!AD1198 -> 93.835167 | Z78: ='Resumen-DiarioHorario-Eólico'!AD1255 -> 0 | AA78: ='Resumen-DiarioHorario-Eólico'!AD1312 -> 0 | AB78: ='Resumen-DiarioHorario-Eólico'!AD1369 -> 0 | AC78: ='Resumen-DiarioHorario-Eólico'!AD1426 -> 7.5841667 | AD78: ='Resumen-DiarioHorario-Eólico'!AD1483 -> 0 | AE78: ='Resumen-DiarioHorario-Eólico'!AD1540 -> 173.64317 | AF78: ='Resumen-DiarioHorario-Eólico'!AD1596 -> 407.12667 | AG78: ='Resumen-DiarioHorario-Eólico'!AD1652 -> 0 | AH78: =+'Resumen-DiarioHorario-Eólico'!AD1708 -> 0.0025 | AI78: =+'Resumen-DiarioHorario-Eólico'!AD1764 -> 285.86333 | AK78: =SUM(E78:AI78) -> 2421.1765
B81: DESGLOSE DIARIO DE CURTAILMENTS DE ENERGÍA SOLAR
B83: Central / Día | E83: =E26 -> 45778 | F83: =F26 -> 45779 | G83: =G26 -> 45780 | H83: =H26 -> 45781 | I83: =I26 -> 45782 | J83: =J26 -> 45783 | K83: =K26 -> 45784 | L83: =L26 -> 45785 | ... AI83: =AI26 -> 45808 | AJ83: Total
B84: Total | E84: =SUM(E85:E155) -> 10604.201 | F84: =SUM(F85:F155) -> 3462.8627 | G84: =SUM(G85:G155) -> 4099.3972 | H84: =SUM(H85:H155) -> 2637.8337 | I84: =SUM(I85:I155) -> 387.75183 | J84: =SUM(J85:J155) -> 2559.1083 | K84: =SUM(K85:K155) -> 3271.1069 | L84: =SUM(L85:L155) -> 11652.61 | ... AI84: =SUM(AI85:AI155) -> 3718.9705 | AJ84: =SUM(AK85:AK155) -> 142018.4
...

Sheet Resumen-DiarioHorario-Eólico
B2: CURTAILMENTS EÓLICAS POR CENTRALES EN FORMA DIARIA/HORARIA
B5: ='Resumen-Mensual'!$E$26 -> 45778
B7: Central/Hora | E7: 1 | F7: 2 | G7: 3 | H7: 4 | I7: 5 | J7: 6 | K7: 7 | L7: 8 | M7: 9 | N7: 10 | O7: 11 | P7: 12 | Q7: 13 | R7: 14 | S7: 15 | T7: 16 | U7: 17 | V7: 18 | W7: 19 | X7: 20 | Y7: 21 | Z7: 22 | AA7: 23 | AB7: 24 | AC7: Total
B8: PE-TCHAMMA | E8: 0 | F8: 0 | G8: 0 | H8: 0 | I8: 0 | J8: 0 | K8: 0 | L8: 0 | M8: 7.3685 | N8: 0 | O8: 0 | P8: 1.5455 | Q8: 0.91716667 | R8: 16.6015 | S8: 21.232167 | T8: 13.809 | U8: 0.278 | V8: 0 | W8: 0 | X8: 0 | Y8: 0 | Z8: 0 | AA8: 0 | AB8: 0 | AD8: =SUM(E8:AB8) -> 61.751833
B9: PE-SIERRAGORDA | E9: 0 | F9: 0 | G9: 0 | H9: 0 | I9: 0 | J9: 0 | K9: 0 | L9: 0 | M9: 0.3535 | N9: 3.1781667 | O9: 1.6293333 | P9: 9.717 | Q9: 0 | R9: 0.70033333 | S9: 18.381667 | T9: 19.398167 | U9: 2.259 | V9: 0 | W9: 0 | X9: 0 | Y9: 0 | Z9: 0 | AA9: 0 | AB9: 0 | AD9: =SUM(E9:AB9) -> 55.617167
B10: PE-VALLEDELOSVIENTOS | E10: 0 | F10: 0 | G10: 0 | H10: 0 | I10: 0 | J10: 0 | K10: 0 | L10: 0 | M10: 3.6333333 | N10: 3.8551667 | O10: 1.3486667 | P10: 6.1821667 | Q10: 7.7065 | R10: 2.3793333 | S10: 11.745 | T10: 21.015333 | U10: 1.5761667 | V10: 0 | W10: 0 | X10: 0 | Y10: 0 | Z10: 0 | AA10: 0 | AB10: 0 | AD10: =SUM(E10:AB10) -> 59.441667
B11: PE-CERROTIGRE | E11: 0 | F11: 0 | G11: 0 | H11: 0 | I11: 0 | J11: 0 | K11: 0 | L11: 0 | M11: 0.0255 | N11: 0.147 | O11: 0.132 | P11: 4.628 | Q11: 18.231167 | R11: 69.328333 | S11: 93.9075 | T11: 65.843 | U11: 6.233 | V11: 0 | W11: 0 | X11: 0 | Y11: 0 | Z11: 0 | AA11: 0 | AB11: 0 | AD11: =SUM(E11:AB11) -> 258.4755
B12: PE-CALAMA | E12: 0 | F12: 0 | G12: 0 | H12: 0 | I12: 0 | J12: 0 | K12: 0 | L12: 0 | M12: 6.8191667 | N12: 5.8216667 | O12: 0.568 | P12: 8.4375 | Q12: 23.7385 | R12: 14.101 | S12: 4.7521667 | T12: 23.5975 | U12: 1.14 | V12: 0 | W12: 0 | X12: 0 | Y12: 0 | Z12: 0 | AA12: 0 | AB12: 0 | AD12: =SUM(E12:AB12) -> 88.9755
B13: PE-TALTAL | E13: 0 | F13: 0 | G13: 0 | H13: 0 | I13: 0 | J13: 0 | K13: 0 | L13: 0 | M13: 27.958167 | N13: 60.041667 | O13: 8.7341667 | P13: 29.658167 | Q13: 15.2 | R13: 35.972333 | S13: 19.086 | T13: 12.096333 | U13: 0.82033333 | V13: 0 | W13: 0 | X13: 0 | Y13: 0 | Z13: 0 | AA13: 0 | AB13: 0 | AD13: =SUM(E13:AB13) -> 209.56717
B14: PE-SARCO | E14: 0 | F14: 0 | G14: 0 | H14: 0 | I14: 0 | J14: 0 | K14: 0 | L14: 0 | M14: 8.3303333 | N14: 6.3368333 | O14: 2.5951667 | P14: 8.272 | Q14: 9.725 | R14: 0 | S14: 0 | T14: 4.0601667 | U14: 1.302 | V14: 0 | W14: 0 | X14: 0 | Y14: 0 | Z14: 0 | AA14: 0 | AB14: 0 | AD14: =SUM(E14:AB14) -> 40.6215
B15: PE-CABOLEONES-1 | E15: 0 | F15: 0 | G15: 0 | H15: 0 | I15: 0 | J15: 0 | K15: 0 | L15: 0 | M15: 3.4618333 | N15: 4.991 | O15: 0.41116667 | P15: 0 | Q15: 0 | R15: 0 | S15: 0 | T15: 0 | U15: 0 | V15: 0 | W15: 0 | X15: 0 | Y15: 0 | Z15: 0 | AA15: 0 | AB15: 0 | AD15: =SUM(E15:AB15) -> 8.864
B16: PE-CABOLEONES-2 | E16: 0 | F16: 0 | G16: 0 | H16: 0 | I16: 0 | J16: 0 | K16: 0 | L16: 0 | M16: 4.2683333 | N16: 3.7023333 | O16: 0.42366667 | P16: 0 | Q16: 0 | R16: 0 | S16: 0 | T16: 0 | U16: 0 | V16: 0 | W16: 0 | X16: 0 | Y16: 0 | Z16: 0 | AA16: 0 | AB16: 0 | AD16: =SUM(E16:AB16) -> 8.3943333
B17: PE-CABOLEONES-3 | E17: 0 | F17: 0 | G17: 0 | H17: 0 | I17: 0 | J17: 0 | K17: 0 | L17: 0 | M17: 8.7688333 | N17: 12.221167 | O17: 5.2726667 | P17: 5.4028333 | Q17: 0 | R17: 0 | S17: 0 | T17: 0 | U17: 0 | V17: 0 | W17: 0 | X17: 0 | Y17: 0 | Z17: 0 | AA17: 0 | AB17: 0 | AD17: =SUM(E17:AB17) -> 31.6655
B18: PE-SANJUAN | E18: 0 | F18: 0 | G18: 0 | H18: 0 | I18: 0 | J18: 0 | K18: 0 | L18: 0 | M18: 5.349 | N18: 7.0565 | O18: 0.302 | P18: 0.73866667 | Q18: 1.1425 | R18: 0 | S18: 11.8215 | T18: 8.7435 | U18: 0 | V18: 0 | W18: 0 | X18: 0 | Y18: 0 | Z18: 0 | AA18: 0 | AB18: 0 | AD18: =SUM(E18:AB18) -> 35.153667
B19: PE-PUNTACOLORADA | E19: 0 | F19: 0 | G19: 0 | H19: 0 | I19: 0 | J19: 0 | K19: 0 | L19: 0 | M19: 0 | N19: 0 | O19: 0 | P19: 0 | Q19: 0 | R19: 0 | S19: 0 | T19: 0 | U19: 0 | V19: 0 | W19: 0 | X19: 0 | Y19: 0 | Z19: 0 | AA19: 0 | AB19: 0 | AD19: =SUM(E19:AB19) -> 0
... B58: PE-KALLPA | E58: 0 | F58: 0 | G58: 0 | H58: 0 | I58: 0 | J58: 0 | K58: 0 | L58: 0 | M58: 23.235167 | N58: 62.105167 | O58: 55.110833 | P58: 53.773167 | Q58: 39.520333 | R58: 39.606667 | S58: 50.077 | T58: 44.532167 | U58: 3.0906667 | V58: 0 | W58: 0 | X58: 0 | Y58: 0 | Z58: 0 | AA58: 0 | AB58: 0 | AD58: =SUM(E58:AB58) -> 371.05117
B59: Total | E59: =SUM(E8:E58) -> 0 | F59: =SUM(F8:F58) -> 0 | G59: =SUM(G8:G58) -> 0 | H59: =SUM(H8:H58) -> 0 | I59: =SUM(I8:I58) -> 0 | J59: =SUM(J8:J58) -> 0 | K59: =SUM(K8:K58) -> 0 | L59: =SUM(L8:L58) -> 0 | ... AB59: =SUM(AB8:AB58) -> 0 | AC59: =SUM(AC8:AE58) -> 2789.0277
B62: ='Resumen-Mensual'!$F$26 -> 45779
B64: Central/Hora | E64: 1 | F64: 2 | G64: 3 | H64: 4 | I64: 5 | J64: 6 | K64: 7 | L64: 8 | M64: 9 | N64: 10 | O64: 11 | P64: 12 | Q64: 13 | R64: 14 | S64: 15 | T64: 16 | U64: 17 | V64: 18 | W64: 19 | X64: 20 | Y64: 21 | Z64: 22 | AA64: 23 | AB64: 24 | AC64: Total
B65: PE-TCHAMMA | E65: 0 | F65: 0 | G65: 0 | H65: 0 | I65: 0 | J65: 0 | K65: 0 | L65: 0 | M65: 10.145833 | N65: 26.471167 | O65: 0 | P65: 0 | Q65: 0 | R65: 0 | S65: 6.2641667 | T65: 30.610833 | U65: 24.39 | V65: 0 | W65: 0 | X65: 0 | Y65: 0 | Z65: 0 | AA65: 0 | AB65: 0 | AD65: =SUM(E65:AB65) -> 97.882
B66: PE-SIERRAGORDA | E66: 0 | F66: 0 | G66: 0 | H66: 0 | I66: 0 | J66: 0 | K66: 0 | L66: 0 | M66: 1.8908333 | N66: 8.9411667 | O66: 8.3151667 | P66: 0 | Q66: 0 | R66: 0 | S66: 3.1638333 | T66: 16.287833 | U66: 4.973 | V66: 0 | W66: 0 | X66: 0 | Y66: 0 | Z66: 0 | AA66: 0 | AB66: 0 | AD66: =SUM(E66:AB66) -> 43.571833
B67: PE-VALLEDELOSVIENTOS | E67: 0 | F67: 0 | G67: 0 | H67: 0 | I67: 0 | J67: 0 | K67: 0 | L67: 0 | M67: 1.9756667 | N67: 7.0293333 | O67: 2.6031667 | P67: 0 | Q67: 0 | R67: 0 | S67: 1.5683333 | T67: 23.0985 | U67: 15.534833 | V67: 0 | W67: 0 | X67: 0 | Y67: 0 | Z67: 0 | AA67: 0 | AB67: 0 | AD67: =SUM(E67:AB67) -> 51.809833
B68: PE-CERROTIGRE | E68: 0 | F68: 0 | G68: 0 | H68: 0 | I68: 0 | J68: 0 | K68: 0 | L68: 0 | M68: 0.07 | N68: 0.18 | O68: 0.075 | P68: 0 | Q68: 0 | R68: 0 | S68: 0 | T68: 24.876333 | U68: 24.347333 | V68: 0 | W68: 0 | X68: 0 | Y68: 0 | Z68: 0 | AA68: 0 | AB68: 0 | AD68: =SUM(E68:AB68) -> 49.548667
B69: PE-CALAMA | E69: 0 | F69: 0 | G69: 0 | H69: 0 | I69: 0 | J69: 0 | K69: 0 | L69: 0 | M69: 0.40033333 | N69: 4.6205 | O69: 0.003 | P69: 0 | Q69: 0 | R69: 0 | S69: 12.8315 | T69: 89.052833 | U69: 56.679333 | V69: 0 | W69: 0 | X69: 0 | Y69: 0 | Z69: 0 | AA69: 0 | AB69: 0 | AD69: =SUM(E69:AB69) -> 163.5875
B70: PE-TALTAL | E70: 0 | F70: 0 | G70: 0 | H70: 0 | I70: 0 | J70: 0 | K70: 0 | L70: 0 | M70: 0.82366667 | N70: 6.9965 | O70: 4.4653333 | P70: 0 | Q70: 0 | R70: 0 | S70: 0.672 | T70: 9.5358333 | U70: 8.0043333 | V70: 0 | W70: 0 | X70: 0 | Y70: 0 | Z70: 0 | AA70: 0 | AB70: 0 | AD70: =SUM(E70:AB70) -> 30.497667
B71: PE-SARCO | E71: 0 | F71: 0 | G71: 0 | H71: 0 | I71: 0 | J71: 0 | K71: 0 | L71: 0 | M71: 4.123 | N71: 3.4695 | O71: 1.096 | P71: 0 | Q71: 0 | R71: 0 | S71: 0.60066667 | T71: 6.667 | U71: 0 | V71: 0 | W71: 0 | X71: 0 | Y71: 0 | Z71: 0 | AA71: 0 | AB71: 0 | AD71: =SUM(E71:AB71) -> 15.956167
B72: PE-CABOLEONES-1 | E72: 0 | F72: 0 | G72: 0 | H72: 0 | I72: 0 | J72: 0 | K72: 0 | L72: 0 | M72: 5.5438333 | N72: 3.8113333 | O72: 0 | P72: 0 | Q72: 0 | R72: 0 | S72: 0 | T72: 6.3575 | U72: 0 | V72: 0 | W72: 0 | X72: 0 | Y72: 0 | Z72: 0 | AA72: 0 | AB72: 0 | AD72: =SUM(E72:AB72) -> 15.712667
B73: PE-CABOLEONES-2 | E73: 0 | F73: 0 | G73: 0 | H73: 0 | I73: 0 | J73: 0 | K73: 0 | L73: 0 | M73: 4.9046667 | N73: 8.5671667 | O73: 2.34 | P73: 0 | Q73: 0 | R73: 0 | S73: 0 | T73: 5.5681667 | U73: 0 | V73: 0 | W73: 0 | X73: 0 | Y73: 0 | Z73: 0 | AA73: 0 | AB73: 0 | AD73: =SUM(E73:AB73) -> 21.38
B74: PE-CABOLEONES-3 | E74: 0 | F74: 0 | G74: 0 | H74: 0 | I74: 0 | J74: 0 | K74: 0 | L74: 0 | M74: 2.2271667 | N74: 0.0071666667 | O74: 0 | P74: 0 | Q74: 0 | R74: 0 | S74: 0.22866667 | T74: 5.9851667 | U74: 0 | V74: 0 | W74: 0 | X74: 0 | Y74: 0 | Z74: 0 | AA74: 0 | AB74: 0 | AD74: =SUM(E74:AB74) -> 8.4481667
B75: PE-SANJUAN | E75: 0 | F75: 0 | G75: 0 | H75: 0 | I75: 0 | J75: 0 | K75: 0 | L75: 0 | M75: 4.0045 | N75: 0 | O75: 0 | P75: 0 | Q75: 0 | R75: 0 | S75: 2.0596667 | T75: 8.4686667 | U75: 0.56283333 | V75: 0 | W75: 0 | X75: 0 | Y75: 0 | Z75: 0 | AA75: 0 | AB75: 0 | AD75: =SUM(E75:AB75) -> 15.095667
B76: PE-PUNTACOLORADA | E76: 0 | F76: 0 | G76: 0 | H76: 0 | I76: 0 | J76: 0 | K76: 0 | L76: 0 | M76: 0 | N76: 0 | O76: 0 | P76: 0 | Q76: 0 | R76: 0 | S76: 0 | T76: 0 | U76: 0 | V76: 0 | W76: 0 | X76: 0 | Y76: 0 | Z76: 0 | AA76: 0 | AB76: 0 | AD76: =SUM(E76:AB76) -> 0
... B115: PE-KALLPA | E115: 0 | F115: 0 | G115: 0 | H115: 0 | I115: 0 | J115: 0 | K115: 0 | L115: 0 | M115: 9.0788333 | N115: 0 | O115: 0 | P115: 0 | Q115: 0 | R115: 0 | S115: 0 | T115: 2.9736667 | U115: 11.351333 | V115: 0 | W115: 0 | X115: 0 | Y115: 0 | Z115: 0 | AA115: 0 | AB115: 0 | AD115: =SUM(E115:AB115) -> 23.403833
B116: Total | E116: =SUM(E65:E115) -> 0 | F116: =SUM(F65:F115) -> 0 | G116: =SUM(G65:G115) -> 0 | H116: =SUM(H65:H115) -> 0 | I116: =SUM(I65:I115) -> 0 | J116: =SUM(J65:J115) -> 0 | K116: =SUM(K65:K115) -> 0 | L116: =SUM(L65:L115) -> 0 | ... AB116: =SUM(AB65:AB115) -> 0 | AC116: =SUM(AC65:AE115) -> 964.86658
B119: ='Resumen-Mensual'!$G$26 -> 45780
B121: Central/Hora | E121: 1 | F121: 2 | G121: 3 | H121: 4 | I121: 5 | J121: 6 | K121: 7 | L121: 8 | M121: 9 | N121: 10 | O121: 11 | P121: 12 | Q121: 13 | R121: 14 | S121: 15 | T121: 16 | U121: 17 | V121: 18 | W121: 19 | X121: 20 | Y121: 21 | Z121: 22 | AA121: 23 | AB121: 24 | AC121: Total
B122: PE-TCHAMMA | E122: 0 | F122: 0 | G122: 0 | H122: 0 | I122: 0 | J122: 0 | K122: 0 | L122: 0 | M122: 28.262167 | N122: 20.574667 | O122: 0.9485 | P122: 0 | Q122: 0 | R122: 0 | S122: 1.1615 | T122: 8.9341667 | U122: 6.5056667 | V122: 0 | W122: 0 | X122: 0 | Y122: 0 | Z122: 0 | AA122: 0 | AB122: 0 | AD122: =SUM(E122:AB122) -> 66.386667
B123: PE-SIERRAGORDA | E123: 0 | F123: 0 | G123: 0 | H123: 0 | I123: 0 | J123: 0 | K123: 0 | L123: 0 | M123: 0 | N123: 0.47016667 | O123: 0.0915 | P123: 0 | Q123: 0 | R123: 0 | S123: 2.7906667 | T123: 12.837167 | U123: 9.7238333 | V123: 0 | W123: 0 | X123: 0 | Y123: 0 | Z123: 0 | AA123: 0 | AB123: 0 | AD123: =SUM(E123:AB123) -> 25.913333
B124: PE-VALLEDELOSVIENTOS | E124: 0 | F124: 0 | G124: 0 | H124: 0 | I124: 0 | J124: 0 | K124: 0 | L124: 0 | M124: 0 | N124: 0.274 | O124: 0.75116667 | P124: 0 | Q124: 0 | R124: 0 | S124: 4.8176667 | T124: 11.766 | U124: 8.2465 | V124: 0 | W124: 0 | X124: 0 | Y124: 0 | Z124: 0 | AA124: 0 | AB124: 0 | AD124: =SUM(E124:AB124) -> 25.855333
B125: PE-CERROTIGRE | E125: 0 | F125: 0 | G125: 0 | H125: 0 | I125: 0 | J125: 0 | K125: 0 | L125: 0 | M125: 0.68233333 | N125: 0.09 | O125: 0.024 | P125: 0 | Q125: 0 | R125: 0 | S125: 4.2415 | T125: 19.363833 | U125: 13.7455 | V125: 0 | W125: 0 | X125: 0 | Y125: 0 | Z125: 0 | AA125: 0 | AB125: 0 | AD125: =SUM(E125:AB125) -> 38.147167
B126: PE-CALAMA | E126: 0 | F126: 0 | G126: 0 | H126: 0 | I126: 0 | J126: 0 | K126: 0 | L126: 0 | M126: 0 | N126: 0.766 | O126: 0.022166667 | P126: 0 | Q126: 0 | R126: 10.031833 | S126: 73.227167 | T126: 37.008833 | U126: 25.441667 | V126: 0 | W126: 0 | X126: 0 | Y126: 0 | Z126: 0 | AA126: 0 | AB126: 0 | AD126: =SUM(E126:AB126) -> 146.49767
...

Sheet Resumen-DiarioHorario-Solar
B2: CURTAILMENTS SOLAR POR CENTRALES EN FORMA DIARIA/HORARIA
B5: ='Resumen-Mensual'!$E$26 -> 45778
B7: Central/Hora | E7: 1 | F7: 2 | G7: 3 | H7: 4 | I7: 5 | J7: 6 | K7: 7 | L7: 8 | M7: 9 | N7: 10 | O7: 11 | P7: 12 | Q7: 13 | R7: 14 | S7: 15 | T7: 16 | U7: 17 | V7: 18 | W7: 19 | X7: 20 | Y7: 21 | Z7: 22 | AA7: 23 | AB7: 24 | AC7: Total
B8: PFV-POZOALMONTE-2 | E8: 0 | F8: 0 | G8: 0 | H8: 0 | I8: 0 | J8: 0 | K8: 0 | L8: 0 | M8: 0.37166667 | N8: 0.39633333 | O8: 0.43283333 | P8: 0.44116667 | Q8: 0.6075 | R8: 0.435 | S8: 0.473 | T8: 0.95083333 | U8: 0 | V8: 0 | W8: 0 | X8: 0 | Y8: 0 | Z8: 0 | AA8: 0 | AB8: 0 | AD8: =SUM(E8:AB8) -> 4.1083333
B9: PFV-POZOALMONTE-3 | E9: 0 | F9: 0 | G9: 0 | H9: 0 | I9: 0 | J9: 0 | K9: 0 | L9: 0 | M9: 0.033833333 | N9: 0 | O9: 0 | P9: 0 | Q9: 0 | R9: 0 | S9: 0 | T9: 0 | U9: 0 | V9: 0 | W9: 0 | X9: 0 | Y9: 0 | Z9: 0 | AA9: 0 | AB9: 0 | AD9: =SUM(E9:AB9) -> 0.033833333
B10: PFV-LAHUAYCA-2 | E10: 0 | F10: 0 | G10: 0 | H10: 0 | I10: 0 | J10: 0 | K10: 0 | L10: 0 | M10: 3.2011667 | N10: 5.124 | O10: 4.68 | P10: 5.99 | Q10: 7.1641667 | R10: 7.0446667 | S10: 7.3068333 | T10: 7.468 | U10: 0.274 | V10: 0 | W10: 0 | X10: 0 | Y10: 0 | Z10: 0 | AA10: 0 | AB10: 0 | AD10: =SUM(E10:AB10) -> 48.252833
B11: PFV-SANTAISABEL | E11: 0 | F11: 0 | G11: 0 | H11: 0 | I11: 0 | J11: 0 | K11: 0 | L11: 0 | M11: 24.026667 | N11: 42.0605 | O11: 29.066333 | P11: 31.641333 | Q11: 39.778333 | R11: 40.031833 | S11: 28.343167 | T11: 24.747 | U11: 4.1035 | V11: 0 | W11: 0 | X11: 0 | Y11: 0 | Z11: 0 | AA11: 0 | AB11: 0 | AD11: =SUM(E11:AB11) -> 263.79867
B12: PFV-HUATACONDO | E12: 0 | F12: 0 | G12: 0 | H12: 0 | I12: 0 | J12: 0 | K12: 0 | L12: 0 | M12: 0 | N12: 0 | O12: 0 | P12: 0 | Q12: 0 | R12: 0 | S12: 0 | T12: 0 | U12: 0 | V12: 0 | W12: 0 | X12: 0 | Y12: 0 | Z12: 0 | AA12: 0 | AB12: 0 | AD12: =SUM(E12:AB12) -> 0
B13: PFV-ATACAMASOLAR-2 | E13: 0 | F13: 0 | G13: 0 | H13: 0 | I13: 0 | J13: 0 | K13: 0 | L13: 0 | M13: 3.6351667 | N13: 4.3651667 | O13: 7.412 | P13: 1.8991667 | Q13: 19.221333 | R13: 20.2675 | S13: 9.1738333 | T13: 7.6576667 | U13: 0.043333333 | V13: 0 | W13: 0 | X13: 0 | Y13: 0 | Z13: 0 | AA13: 0 | AB13: 0 | AD13: =SUM(E13:AB13) -> 73.675167
B14: PFV-NUEVOQUILLAGUA | E14: 0 | F14: 0 | G14: 0 | H14: 0 | I14: 0 | J14: 0 | K14: 0 | L14: 0 | M14: 39.6795 | N14: 38.16 | O14: 18.25 | P14: 13.81 | Q14: 7.94 | R14: 8.35 | S14: 0 | T14: 7.74 | U14: 6.06 | V14: 0 | W14: 0 | X14: 0 | Y14: 0 | Z14: 0 | AA14: 0 | AB14: 0 | AD14: =SUM(E14:AB14) -> 139.9895
B15: PFV-GRANJA | E15: 0 | F15: 0 | G15: 0 | H15: 0 | I15: 0 | J15: 0 | K15: 0 | L15: 0 | M15: 0.001 | N15: 0 | O15: 0 | P15: 0 | Q15: 0.0585 | R15: 0 | S15: 0 | T15: 0.59816667 | U15: 0 | V15: 0 | W15: 0 | X15: 0 | Y15: 0 | Z15: 0 | AA15: 0 | AB15: 0 | AD15: =SUM(E15:AB15) -> 0.65766667
B16: PFV-USYA | E16: 0 | F16: 0 | G16: 0 | H16: 0 | I16: 0 | J16: 0 | K16: 0 | L16: 0 | M16: 0.0295 | N16: 0 | O16: 0 | P16: 0 | Q16: 0 | R16: 0 | S16: 0 | T16: 0 | U16: 0 | V16: 0 | W16: 0 | X16: 0 | Y16: 0 | Z16: 0 | AA16: 0 | AB16: 0 | AD16: =SUM(E16:AB16) -> 0.0295
B17: PFV-SANPEDRO-GPG | E17: 0 | F17: 0 | G17: 0 | H17: 0 | I17: 0 | J17: 0 | K17: 0 | L17: 0 | M17: 22.331833 | N17: 28.385167 | O17: 22.202833 | P17: 30.285833 | Q17: 23.431 | R17: 13.0655 | S17: 12.683167 | T17: 17.392167 | U17: 1.45 | V17: 0 | W17: 0 | X17: 0 | Y17: 0 | Z17: 0 | AA17: 0 | AB17: 0 | AD17: =SUM(E17:AB17) -> 171.2275
B18: PFV-JAMA-1 | E18: 0 | F18: 0 | G18: 0 | H18: 0 | I18: 0 | J18: 0 | K18: 0 | L18: 0 | M18: 0 | N18: 0 | O18: 0 | P18: 0 | Q18: 0 | R18: 0 | S18: 0 | T18: 0 | U18: 0 | V18: 0 | W18: 0 | X18: 0 | Y18: 0 | Z18: 0 | AA18: 0 | AB18: 0 | AD18: =SUM(E18:AB18) -> 0
B19: PFV-JAMA-2 | E19: 0 | F19: 0 | G19: 0 | H19: 0 | I19: 0 | J19: 0 | K19: 0 | L19: 0 | M19: 2.0483333 | N19: 4.5641667 | O19: 3.0928333 | P19: 4.9978333 | Q19: 3.2965 | R19: 2.395 | S19: 1.6528333 | T19: 2.1663333 | U19: 0.13483333 | V19: 0 | W19: 0 | X19: 0 | Y19: 0 | Z19: 0 | AA19: 0 | AB19: 0 | AD19: =SUM(E19:AB19) -> 24.348667
... B78: PFV-TAIRA | E78: 0 | F78: 0 | G78: 0 | H78: 0 | I78: 0 | J78: 0 | K78: 0 | L78: 0 | M78: 0 | N78: 0 | O78: 0 | P78: 0 | Q78: 0 | R78: 0 | S78: 0 | T78: 0 | U78: 0 | V78: 0 | W78: 0 | X78: 0 | Y78: 0 | Z78: 0 | AA78: 0 | AB78: 0 | AD78: =SUM(E78:AB78) -> 0
B79: Total | E79: =SUM(E8:E78) -> 0 | F79: =SUM(F8:F78) -> 0 | G79: =SUM(G8:G78) -> 0 | H79: =SUM(H8:H78) -> 0 | I79: =SUM(I8:I78) -> 0 | J79: =SUM(J8:J78) -> 0 | K79: =SUM(K8:K78) -> 0 | L79: =SUM(L8:L78) -> 0 | ... AB79: =SUM(AB8:AB78) -> 0 | AC79: =SUM(AC8:AE78) -> 10604.201
B82: ='Resumen-Mensual'!$F$26 -> 45779
B84: Central/Hora | E84: 1 | F84: 2 | G84: 3 | H84: 4 | I84: 5 | J84: 6 | K84: 7 | L84: 8 | M84: 9 | N84: 10 | O84: 11 | P84: 12 | Q84: 13 | R84: 14 | S84: 15 | T84: 16 | U84: 17 | V84: 18 | W84: 19 | X84: 20 | Y84: 21 | Z84: 22 | AA84: 23 | AB84: 24 | AC84: Total
B85: PFV-POZOALMONTE-2 | E85: 0 | F85: 0 | G85: 0 | H85: 0 | I85: 0 | J85: 0 | K85: 0 | L85: 0 | M85: 0.6095 | N85: 1.3456667 | O85: 0.9085 | P85: 0 | Q85: 0 | R85: 0 | S85: 0.28466667 | T85: 1.1881667 | U85: 0.0115 | V85: 0 | W85: 0 | X85: 0 | Y85: 0 | Z85: 0 | AA85: 0 | AB85: 0 | AD85: =SUM(E85:AB85) -> 4.348
B86: PFV-POZOALMONTE-3 | E86: 0 | F86: 0 | G86: 0 | H86: 0 | I86: 0 | J86: 0 | K86: 0 | L86: 0 | M86: 0.249 | N86: 0.028166667 | O86: 0.00033333333 | P86: 0 | Q86: 0 | R86: 0 | S86: 0 | T86: 0 | U86: 0 | V86: 0 | W86: 0 | X86: 0 | Y86: 0 | Z86: 0 | AA86: 0 | AB86: 0 | AD86: =SUM(E86:AB86) -> 0.2775
B87: PFV-LAHUAYCA-2 | E87: 0 | F87: 0 | G87: 0 | H87: 0 | I87: 0 | J87: 0 | K87: 0 | L87: 0 | M87: 1.4656667 | N87: 7.1431667 | O87: 4.2518333 | P87: 0 | Q87: 0 | R87: 0 | S87: 2.0415 | T87: 9.6331667 | U87: 3.9345 | V87: 0 | W87: 0 | X87: 0 | Y87: 0 | Z87: 0 | AA87: 0 | AB87: 0 | AD87: =SUM(E87:AB87) -> 28.469833
B88: PFV-SANTAISABEL | E88: 0 | F88: 0 | G88: 0 | H88: 0 | I88: 0 | J88: 0 | K88: 0 | L88: 0 | M88: 16.7235 | N88: 41.005167 | O88: 6.467 | P88: 0 | Q88: 0 | R88: 0 | S88: 5.5346667 | T88: 17.987333 | U88: 17.840833 | V88: 0 | W88: 0 | X88: 0 | Y88: 0 | Z88: 0 | AA88: 0 | AB88: 0 | AD88: =SUM(E88:AB88) -> 105.5585
B89: PFV-HUATACONDO | E89: 0 | F89: 0 | G89: 0 | H89: 0 | I89: 0 | J89: 0 | K89: 0 | L89: 0 | M89: 1.5498333 | N89: 15.933833 | O89: 21.204333 | P89: 23.036167 | Q89: 22.947167 | R89: 19.984167 | S89: 18.795333 | T89: 16.047 | U89: 0.0675 | V89: 0 | W89: 0 | X89: 0 | Y89: 0 | Z89: 0 | AA89: 0 | AB89: 0 | AD89: =SUM(E89:AB89) -> 139.56533
B90: PFV-ATACAMASOLAR-2 | E90: 0 | F90: 0 | G90: 0 | H90: 0 | I90: 0 | J90: 0 | K90: 0 | L90: 0 | M90: 8.3333333 | N90: 36.9355 | O90: 2.1926667 | P90: 0 | Q90: 0 | R90: 0 | S90: 8.521 | T90: 41.489833 | U90: 33.031333 | V90: 0 | W90: 0 | X90: 0 | Y90: 0 | Z90: 0 | AA90: 0 | AB90: 0 | AD90: =SUM(E90:AB90) -> 130.50367
B91: PFV-NUEVOQUILLAGUA | E91: 0 | F91: 0 | G91: 0 | H91: 0 | I91: 0 | J91: 0 | K91: 0 | L91: 0 | M91: 22.036667 | N91: 38.45 | O91: 20.06 | P91: 0 | Q91: 0 | R91: 0 | S91: 16.076667 | T91: 25.4 | U91: 10.42 | V91: 0 | W91: 0 | X91: 0 | Y91: 0 | Z91: 0 | AA91: 0 | AB91: 0 | AD91: =SUM(E91:AB91) -> 132.44333
B92: PFV-GRANJA | E92: 0 | F92: 0 | G92: 0 | H92: 0 | I92: 0 | J92: 0 | K92: 0 | L92: 0 | M92: 0 | N92: 0 | O92: 0 | P92: 0 | Q92: 0 | R92: 0 | S92: 0 | T92: 0 | U92: 0 | V92: 0 | W92: 0 | X92: 0 | Y92: 0 | Z92: 0 | AA92: 0 | AB92: 0 | AD92: =SUM(E92:AB92) -> 0
B93: PFV-USYA | E93: 0 | F93: 0 | G93: 0 | H93: 0 | I93: 0 | J93: 0 | K93: 0 | L93: 0 | M93: 0 | N93: 0 | O93: 2.396 | P93: 0 | Q93: 0 | R93: 0 | S93: 0 | T93: 4.0726667 | U93: 1.6636667 | V93: 0 | W93: 0 | X93: 0 | Y93: 0 | Z93: 0 | AA93: 0 | AB93: 0 | AD93: =SUM(E93:AB93) -> 8.1323333
B94: PFV-SANPEDRO-GPG | E94: 0 | F94: 0 | G94: 0 | H94: 0 | I94: 0 | J94: 0 | K94: 0 | L94: 0 | M94: 6.4618333 | N94: 16.890833 | O94: 7.1585 | P94: 0 | Q94: 0 | R94: 0 | S94: 0.0395 | T94: 22.64 | U94: 7.4798333 | V94: 0 | W94: 0 | X94: 0 | Y94: 0 | Z94: 0 | AA94: 0 | AB94: 0 | AD94: =SUM(E94:AB94) -> 60.6705
B95: PFV-JAMA-1 | E95: 0 | F95: 0 | G95: 0 | H95: 0 | I95: 0 | J95: 0 | K95: 0 | L95: 0 | M95: 4.3156667 | N95: 0 | O95: 10.99 | P95: 0 | Q95: 0 | R95: 0 | S95: 5.0266667 | T95: 9.56 | U95: 9.6463333 | V95: 0 | W95: 0 | X95: 0 | Y95: 0 | Z95: 0 | AA95: 0 | AB95: 0 | AD95: =SUM(E95:AB95) -> 39.538667
